Workbook

Sheet COEM_Package_20200302
B2: No | C2: Package | D2: Type | E2: Project | F2: ComponentName | G2: TaskID | H2: ItemName | I2: Type of Comment | J2: BB | K2: Database | L2: ItemRevision | M2: Owner Contact | N2: Task Jira | O2: TaskGroup | P2: Tester | Q2: PeerReviewer | R2: Status Review | S2: ELOC Assigned | T2: ELOC Recheck With Tool | U2: LOC Complete | V2: Estimation base TOOL | W2: Actual hour | X2: Status | Y2: Planned Start | Z2: Planned End | AA2: Start | AB2: End | AC2: Status Result | AD2: C0 | AE2: C1 | AF2: MCDC | AG2: Reason | AH2: Remark
B3: 1 | C3: 20200302 | D3: PSW | E3: GAC_220680_Carbon_A18_ESPHevx_FPA/RPA_BL03 | F3: rb\as\gaig\prj\dsmpr\src\RBVoltageHandler\src | G3: 1348323 | H3: RBVoltageHandler_Suppression.c | I3: Auto | J3: - | K3: GAC_ESPHevX_HADHAP_Int | L3: =IF(D3="ASW","PUT_VERSION","-") -> - | M3: CHEN Xiaomin (CC-AS/EVA-SW31-CN) | O3: T01 | P3: duong.nguyen | Q3: hieu.nguyen-trung | R3: Yes | S3: 113 | T3: 113 | U3: 113 | V3: 3 | W3: 4 | X3: Ready for review | Y3: 43892 | Z3: 43894 | AA3: 43892 | AB3: 43893 | AC3: OK | AD3: 100 | AE3: 100 | AF3: 100
B4: =B3+1 -> 2 | C4: 20200302 | D4: PSW | E4: MC_227282_SGMW_E200_Plus_ESPCPiGen9.3_BSS04_SP02 | F4: rb\as\sgmw\CN210S\app\net\RBScl\RBScl_SGMW\src | G4: 1345876 | H4: SGMW_RBA_NDS_HBCRequest_Callout.c | I4: Auto | J4: bb99885 | K4: SGMW_ESP93_Carbon_Int | L4: =IF(D4="ASW","PUT_VERSION","-") -> - | M4: WANG Yang (CC-AS/EVA-SW32-CN) | O4: T01 | P4: loc.do-phu | Q4: hieu.nguyen-trung | R4: Yes | S4: 148 | T4: 357 | U4: 357 | V4: 10 | W4: 6 | X4: Ready for review | Y4: 43893 | Z4: 43894 | AA4: 43892 | AB4: 43892 | AC4: OK | AD4: 100 | AE4: 100 | AF4: 100 | AG4: Tool collect 148 ELOC, but the real is 357
B5: =B4+1 -> 3 | C5: 20200302 | D5: PSW | E5: 241595_GAC_A27_ESP9.3CP_BL04 | F5: rb\as\gaig\A10\dsmpr\src\RBHMI\src | G5: 1350941 | H5: RBHMI_LDMLamp_CNMS.c | I5: Auto | J5: BB81650 & BB81651 | K5: Gac_ESP93CP_A26HD_Int | L5: =IF(D5="ASW","PUT_VERSION","-") -> - | M5: MIAO Huafeng (CC-AS/EVA-SW32-CN) | O5: T01 | P5: duong.nguyen | Q5: hieu.nguyen-trung | R5: Yes | S5: 291 | T5: 291 | U5: 291 | V5: 8 | W5: 10 | X5: Ready for review | Y5: 43892 | Z5: 43894 | AA5: 43892 | AB5: 43893 | AC5: OK | AD5: 100 | AE5: 100 | AF5: 100 | AG5: Wrong extension C "RBHMI_LDMLamp_CNMS.C" | AH5: Got 1 findings
B6: =B5+1 -> 4 | C6: 20200302 | D6: PSW | E6: 223331_GAC_A39_Carbon_ESP9.3HD_OBD_BL07 | F6: rb\as\cnms_core\app\obd\ObdCyclesHandler\src | G6: 1351929 | H6: ObdCyclesHandler.c | I6: Auto | J6: bb99735 | K6: GAC_ESP93CP_Carbon_Int | L6: =IF(D6="ASW","PUT_VERSION","-") -> - | M6: CHEN Xiaomin (CC-AS/EVA-SW31-CN) | O6: T01 | P6: chung.ly | Q6: hieu.nguyen-trung | R6: Yes | S6: 254 | T6: 254 | U6: 254 | V6: =ROUNDDOWN(T6/HLOOKUP(D6,Table!$C$3:$D$4,2,0)*8,2) -> 4.51 | W6: 4 | X6: Pending for OPL | Y6: 43892 | Z6: 43893 | AA6: 43892 | AB6: 43893 | AC6: NG | AD6: 100 | AE6: 100 | AF6: 95 | AG6: Bug (Condition is always TRUE) so can not cover MCDC. | AH6: Got 1 defect Reason: not send to internal team
B7: =B6+1 -> 5 | C7: 20200302 | D7: ASW | E7: DFN_ESP_Gen9.3_532EC_244112_BSS01 | F7: - | G7: 1352219 | H7: PAP_Odometry | I7: Auto | J7: - | K7: 1352219 | L7: V4.2.104.1 | M7: QIAN Li (CC-AS/EVA-SW2-CN) | O7: T01 | P7: thanh.nguyen-kim | Q7: hieu.nguyen-trung | R7: Yes | S7: 19 | T7: 19 | U7: 19 | V7: =ROUNDDOWN(T7/HLOOKUP(D7,Table!$C$3:$D$4,2,0)*8,2) -> 1.16 | W7: 4 | X7: Pending for OPL | Y7: 43892 | Z7: 43893 | AA7: 43893 | AB7: 43893 | AC7: NG | AD7: 95.6 | AE7: 96 | AF7: - | AG7: Bug (Condition is always TRUE) | AH7: Got 1 findings
B8: =B7+1 -> 6 | C8: 20200302 | D8: PSW | E8: MC_232534_SGMW_CN202C_ESP9.3CPi_ACC_BSS04_SP02 | F8: rb\as\cnms_core\app\dcom\RBAPLCust\src\ESP | G8: 1351848 | H8: RBAPLCUST_EOLDelayCtrlOrAPBMi.c | I8: Auto | J8: 80504 | K8: SGMW_ESP93_Carbon_Int | L8: =IF(D8="ASW","PUT_VERSION","-") -> - | M8: SUN Yun (CC-AS/EVA-SW31-CN) | O8: T02 | P8: thanh.nguyen-kim | Q8: hieu.nguyen-trung | R8: Yes | S8: 478 | T8: 478 | U8: 478 | V8: =ROUNDDOWN(T8/HLOOKUP(D8,Table!$C$3:$D$4,2,0)*8,2) -> 8.49 | W8: 14 | X8: Ready for PLC | Y8: 43892 | Z8: 43894 | AA8: 43892 | AB8: 43894 | AC8: NG | AD8: 99 | AE8: 99 | AF8: 100 | AG8: Bug (Condition not occur) | AH8: Got 1 findings
B9: =B8+1 -> 7 | C9: 20200302 | D9: PSW | E9: MC_232534_SGMW_CN202C_ESP9.3CPi_ACC_BSS04_SP02 | F9: rb\as\sgmw\core\app\dcom\RBAPLCust\src\ESP | G9: 1351848 | H9: RBAPLCUST_RDBI_TPMS.c | I9: Auto | J9: 80504 | K9: SGMW_ESP93_Carbon_Int | L9: =IF(D9="ASW","PUT_VERSION","-") -> - | M9: SUN Yun (CC-AS/EVA-SW31-CN) | O9: T02 | P9: loc.do-phu | Q9: hieu.nguyen-trung | R9: Yes | S9: 286 | T9: 59 | U9: 59 | V9: =ROUNDDOWN(T9/HLOOKUP(D9,Table!$C$3:$D$4,2,0)*8,2) -> 1.04 | W9: 1 | X9: Ready for review | Y9: 43892 | Z9: 43894 | AA9: 43893 | AB9: 43892 | AC9: OK | AD9: 100 | AE9: 100 | AF9: 100 | AG9: Tool collect 286 ELOC, but the real is 59
B10: =B9+1 -> 8 | C10: 20200302 | D10: PSW | E10: MC_232534_SGMW_CN202C_ESP9.3CPi_ACC_BSS04_SP02 | F10: rb\as\sgmw\core\app\dcom\RBAPLCust\src\ESP | G10: 1351848 | H10: RBAPLCUST_RoutineControl_TPMSReset.c | I10: Auto | J10: 80504 | K10: SGMW_ESP93_Carbon_Int | L10: =IF(D10="ASW","PUT_VERSION","-") -> - | M10: SUN Yun (CC-AS/EVA-SW31-CN) | O10: T02 | P10: chung.ly | Q10: hieu.nguyen-trung | R10: Yes | S10: 110 | T10: 110 | U10: 110 | V10: =ROUNDDOWN(T10/HLOOKUP(D10,Table!$C$3:$D$4,2,0)*8,2) -> 1.95 | W10: 1.9 | X10: Ready for review | Y10: 43892 | Z10: 43894 | AA10: 43894 | AB10: 43894 | AC10: OK | AD10: 100 | AE10: 100 | AF10: 100
B11: =B10+1 -> 9 | C11: 20200302 | D11: PSW | E11: GAC_Beryllium_GEN93_ESP_Mainpath_BL05 | F11: rb\as\gaig\A10\app\net\RBScl\RBSclGAC\src | G11: 1278532 | H11: RB_SCL_GAC_RX.c | I11: Auto | J11: BB81261 | K11: GAC_ESP93CP_Int | L11: =IF(D11="ASW","PUT_VERSION","-") -> - | M11: ZHANG Yu (CC-AS/EVA-SW31-CN) | O11: T03 | P11: loc.do-phu | Q11: hieu.nguyen-trung | R11: Yes | S11: 251 | T11: 294 | U11: 294 | V11: =ROUNDDOWN(T11/HLOOKUP(D11,Table!$C$3:$D$4,2,0)*8,2) -> 5.22 | W11: 6.5 | X11: Ready for review | Y11: 43892 | Z11: 43894 | AA11: 43893 | AB11: 43893 | AC11: OK | AD11: 100 | AE11: 100 | AF11: 100 | AG11: Actually ELOC = 294
B12: =B11+1 -> 10 | C12: 20200302 | D12: PSW | E12: GAC_Beryllium_GEN93_ESP_Mainpath_BL05 | F12: rb\as\gaig\A10\app\net\RBScl\RBSclGAC\src | G12: 1278532 | H12: RB_SCL_GAC_TX.c | I12: Auto | J12: BB81261 | K12: GAC_ESP93CP_Int | L12: =IF(D12="ASW","PUT_VERSION","-") -> - | M12: ZHANG Yu (CC-AS/EVA-SW31-CN) | O12: T03 | P12: loc.do-phu | Q12: hieu.nguyen-trung | R12: Yes | S12: 101 | T12: 101 | U12: 101 | V12: =ROUNDDOWN(T12/HLOOKUP(D12,Table!$C$3:$D$4,2,0)*8,2) -> 1.79 | W12: 1.5 | X12: Ready for review | Y12: 43892 | Z12: 43894 | AA12: 43894 | AB12: 43894 | AC12: OK | AD12: 100 | AE12: 100 | AF12: 100
B13: =B12+1 -> 11 | C13: 20200302 | D13: PSW | E13: GAC_Beryllium_GEN93_ESP_Mainpath_BL05 | F13: rb\as\cnms_core\app\net\scl\LDMFunctions\ACC\src | G13: 1278532 | H13: NET_SCL_Tx_AEB.c | I13: Auto | J13: BB81261 | K13: GAC_ESP93CP_Int | L13: =IF(D13="ASW","PUT_VERSION","-") -> - | M13: ZHANG Yu (CC-AS/EVA-SW31-CN) | O13: T03 | P13: duong.nguyen | S13: 90 | T13: 90 | U13: 90 | V13: =ROUNDDOWN(T13/HLOOKUP(D13,Table!$C$3:$D$4,2,0)*8,2) -> 1.6 | W13: 2 | X13: Ready for review | Y13: 43892 | Z13: 43894 | AA13: 43894 | AB13: 43894 | AC13: NG | AD13: 86 | AE13: 83 | AF13: 100
B14: =B13+1 -> 12 | C14: 20200302 | D14: PSW | E14: GAC_Beryllium_GEN93_ESP_Mainpath_BL05 | F14: rb\as\cnms_core\app\net\scl\LDMFunctions\APA\src | G14: 1278532 | H14: NET_SCL_Tx_APAInformSts.c | I14: Auto | J14: BB81261 | K14: GAC_ESP93CP_Int | L14: =IF(D14="ASW","PUT_VERSION","-") -> - | M14: ZHANG Yu (CC-AS/EVA-SW31-CN) | O14: T03 | P14: loc.do-phu | Q14: hieu.nguyen-trung | R14: Yes | S14: 101 | T14: 183 | U14: 183 | V14: =ROUNDDOWN(T14/HLOOKUP(D14,Table!$C$3:$D$4,2,0)*8,2) -> 3.25 | W14: 3 | X14: Ready for review | Y14: 43892 | Z14: 43894 | AA14: 43894 | AB14: 43894 | AC14: OK | AD14: 100 | AE14: 100 | AF14: 100 | AG14: Actually ELOC = 183
B15: =B14+1 -> 13 | C15: 20200303 | D15: PSW | E15: BYD_IPB_SW_Mainstream_BL05 | F15: rb\as\BYD\ipb\app\net\RBScl\Scl_Callout\src | G15: 1352115 | H15: RBA_NDS_Complex_Callout.c | I15: Auto | J15: none | K15: BYD_IPB_BL05_Int | L15: =IF(D15="ASW","PUT_VERSION","-") -> - | M15: GUO Sasa (CC-AS/EVA-SW3-CN) | O15: T01 | P15: chung.ly | S15: 828 | T15: 828 | V15: =ROUNDDOWN(T15/HLOOKUP(D15,Table!$C$3:$D$4,2,0)*8,2) -> 14.72 | W15: 14 | X15: Ready for review | Y15: 43892 | Z15: 43899 | AA15: 43894 | AB15: 43896 | AC15: NG | AD15: 100 | AE15: 100 | AF15: 98 | AG15: Bug (Condition is always TRUE)
B16: =B15+1 -> 14 | C16: 20200303 | D16: PSW | E16: GWM_ESP9.3CP_RBVH_Stream_BSS04 | F16: rb\as\gwm\core\app\dcom\RBAPLCust\src | G16: 1353313 | H16: RBAPLCUST_RBDI_NVMData.c | I16: Auto | J16: none | K16: GWM_CP_RBVH_Stream_Int | L16: =IF(D16="ASW","PUT_VERSION","-") -> - | M16: Ngo Nhat Tan (RBVH/EAS12) | O16: T01 | P16: loc.do-phu | S16: 371 | T16: 371 | V16: =ROUNDDOWN(T16/HLOOKUP(D16,Table!$C$3:$D$4,2,0)*8,2) -> 6.59 | W16: 3 | X16: Ready for review | Y16: 43892 | Z16: 43899 | AA16: 43895 | AB16: 43895 | AC16: OK | AD16: 100 | AE16: 100 | AF16: 100 | AG16: OPL It does not impact to SW functionality.
B17: =B16+1 -> 15 | C17: 20200303 | D17: PSW | E17: GWM_ESP9.3CP_RBVH_Stream_BSS04 | F17: rb\as\gwm\core\app\dcom\RBAPLCust\src | G17: 1353313 | H17: RBAPLCUST_RDBI_PBCData.c | I17: Auto | J17: none | K17: GWM_CP_RBVH_Stream_Int | L17: =IF(D17="ASW","PUT_VERSION","-") -> - | M17: Ngo Nhat Tan (RBVH/EAS12) | O17: T01 | P17: loc.do-phu | S17: 254 | T17: 254 | U17: 254 | V17: =ROUNDDOWN(T17/HLOOKUP(D17,Table!$C$3:$D$4,2,0)*8,2) -> 4.51 | W17: 2 | X17: Ready for review | Y17: 43892 | Z17: 43899 | AA17: 43895 | AB17: 43895 | AC17: OK | AD17: 100 | AE17: 100 | AF17: 100
B18: =B17+1 -> 16 | C18: 20200303 | D18: PSW | E18: GWM_ESP9.3CP_RBVH_Stream_BSS04 | F18: rb\as\gwm\core\app\net\scl\Callout\src\ATMwithoutSportPlus | G18: 1353313 | H18: NET_ATM_Callout_GWM.c | I18: Auto | J18: none | K18: GWM_CP_RBVH_Stream_Int | L18: =IF(D18="ASW","PUT_VERSION","-") -> - | M18: Ngo Nhat Tan (RBVH/EAS12) | O18: T01 | P18: thanh.nguyen-kim | S18: 395 | T18: 395 | U18: 395 | V18: =ROUNDDOWN(T18/HLOOKUP(D18,Table!$C$3:$D$4,2,0)*8,2) -> 7.02 | W18: 2 | X18: Ready for review | Y18: 43892 | Z18: 43899 | AA18: 43895 | AB18: 43895 | AC18: OK | AD18: 100 | AE18: 100 | AF18: 100
B19: =B18+1 -> 17 | C19: 20200303 | D19: PSW | E19: GWM_ESP9.3CP_RBVH_Stream_BSS04 | F19: rb\as\gwm\core\app\net\scl\Callout\src\ATMwithSportPlus | G19: 1353313 | H19: NET_ATM_Callout_GWM.c | I19: Auto | J19: none | K19: GWM_CP_RBVH_Stream_Int | L19: =IF(D19="ASW","PUT_VERSION","-") -> - | M19: Ngo Nhat Tan (RBVH/EAS12) | O19: T01 | P19: thanh.nguyen-kim | S19: 395 | T19: 395 | U19: 395 | V19: =ROUNDDOWN(T19/HLOOKUP(D19,Table!$C$3:$D$4,2,0)*8,2) -> 7.02 | W19: 3 | X19: Ready for review | Y19: 43892 | Z19: 43899 | AA19: 43895 | AB19: 43895 | AC19: OK | AD19: 100 | AE19: 100 | AF19: 100
B20: =B19+1 -> 18 | C20: 20200303 | D20: ASW | E20: - | F20: - | G20: 1353762 | H20: HDC_InvalidThrPos | I20: Auto | J20: - | K20: 1353762 | L20: V3.3.147305.2 | M20: Nguyen Quang Vinh (RBVH/EAS15) | O20: T01 | P20: duong.nguyen | S20: 50 | T20: 50 | U20: 50 | V20: =ROUNDDOWN(T20/HLOOKUP(D20,Table!$C$3:$D$4,2,0)*8,2) -> 3.07 | W20: 3 | X20: Ready for review | Y20: 43892 | Z20: 43899 | AA20: 43895 | AB20: 43896 | AG20: Have issues with database, complexity of code
B21: =B20+1 -> 19 | C21: 20200303 | D21: PSW | E21: CNMS Super Deuterium BSS01 | F21: rb\as\rbcn\core\app\dcom\RBAPLCust\src\iBooster | G21: 1341660 | H21: RBAPLCUST_RDBI_AnalogData.c | I21: Manual | J21: - | K21: CNMS_Deuterium_Int | L21: =IF(D21="ASW","PUT_VERSION","-") -> - | M21: LU Martin (CC-AS/ESW2-CN) | O21: T02 | P21: duong.nguyen | S21: 77 | T21: 77 | V21: =ROUNDDOWN(T21/HLOOKUP(D21,Table!$C$3:$D$4,2,0)*8,2) -> 1.36 | X21: N/A | Z21: 43901
B22: =B21+1 -> 20 | C22: 20200303 | D22: PSW | E22: CNMS Super Deuterium BSS01 | F22: rb\as\rbcn\core\app\dcom\RBAPLCust\src\iBooster | G22: 1341660 | H22: RBAPLCUST_RDBI_StatusInformation.c | I22: Manual | J22: - | K22: CNMS_Deuterium_Int | L22: =IF(D22="ASW","PUT_VERSION","-") -> - | M22: LU Martin (CC-AS/ESW2-CN) | O22: T02 | P22: duong.nguyen | S22: 44 | T22: 44 | V22: =ROUNDDOWN(T22/HLOOKUP(D22,Table!$C$3:$D$4,2,0)*8,2) -> 0.78 | X22: N/A | Z22: 43901
B23: =B22+1 -> 21 | C23: 20200303 | D23: PSW | E23: CNMS Super Deuterium BSS01 | F23: rb\as\rbcn\core\app\dcom\RBAPLCust\src\iBooster | G23: 1341660 | H23: RBAPLCUST_RoutineControl_iBoosterActuatorTest.c | I23: Manual | J23: - | K23: CNMS_Deuterium_Int | L23: =IF(D23="ASW","PUT_VERSION","-") -> - | M23: LU Martin (CC-AS/ESW2-CN) | O23: T02 | P23: duong.nguyen | S23: 210 | T23: 210 | V23: =ROUNDDOWN(T23/HLOOKUP(D23,Table!$C$3:$D$4,2,0)*8,2) -> 3.73 | X23: N/A | Z23: 43901
B24: =B23+1 -> 22 | C24: 20200303 | D24: PSW | E24: CNMS Super Deuterium BSS01 | F24: rb\as\rbcn\core\app\dcom\RBAPLCust\src\IPB | G24: 1341660 | H24: RBAPLCUST_InputOutputControl.c | I24: Manual | J24: - | K24: CNMS_Deuterium_Int | L24: =IF(D24="ASW","PUT_VERSION","-") -> - | M24: LU Martin (CC-AS/ESW2-CN) | O24: T03 | P24: duong.nguyen | S24: 622 | T24: 622 | V24: =ROUNDDOWN(T24/HLOOKUP(D24,Table!$C$3:$D$4,2,0)*8,2) -> 11.05 | X24: N/A | Z24: 43901
B25: =B24+1 -> 23 | C25: 20200303 | D25: PSW | E25: CNMS Super Deuterium BSS01 | F25: rb\as\rbcn\core\app\dcom\RBAPLCust\src\IPB | G25: 1341660 | H25: RBAPLCUST_InputOutputControl_GeneralFunctions.c | I25: Manual | J25: - | K25: CNMS_Deuterium_Int | L25: =IF(D25="ASW","PUT_VERSION","-") -> - | M25: LU Martin (CC-AS/ESW2-CN) | O25: T03 | S25: 97 | T25: 97 | V25: =ROUNDDOWN(T25/HLOOKUP(D25,Table!$C$3:$D$4,2,0)*8,2) -> 1.72 | X25: N/A | Z25: 43901
B26: =B25+1 -> 24 | C26: 20200303 | D26: PSW | E26: CNMS Super Deuterium BSS01 | F26: rb\as\rbcn\core\app\dcom\RBAPLCust\src\IPB | G26: 1341660 | H26: RBAPLCUST_RDBI_ActuationState.c | I26: Manual | J26: - | K26: CNMS_Deuterium_Int | L26: =IF(D26="ASW","PUT_VERSION","-") -> - | M26: LU Martin (CC-AS/ESW2-CN) | O26: T03 | S26: 100 | T26: 100 | V26: =ROUNDDOWN(T26/HLOOKUP(D26,Table!$C$3:$D$4,2,0)*8,2) -> 1.77 | X26: N/A | Z26: 43901
B27: =B26+1 -> 25 | C27: 20200303 | D27: PSW | E27: CNMS Super Deuterium BSS01 | F27: rb\as\rbcn\core\app\dcom\RBAPLCust\src\IPB | G27: 1341660 | H27: RBAPLCUST_RDBI_CBDS.c | I27: Manual | J27: - | K27: CNMS_Deuterium_Int | L27: =IF(D27="ASW","PUT_VERSION","-") -> - | M27: LU Martin (CC-AS/ESW2-CN) | O27: T03 | S27: 8 | T27: 8 | V27: =ROUNDDOWN(T27/HLOOKUP(D27,Table!$C$3:$D$4,2,0)*8,2) -> 0.14 | X27: N/A | Z27: 43901
B28: =B27+1 -> 26 | C28: 20200303 | D28: PSW | E28: CNMS Super Deuterium BSS01 | F28: rb\as\rbcn\core\app\dcom\RBAPLCust\src\IPB | G28: 1341660 | H28: RBAPLCUST_RDBI_IOCtrlState.c | I28: Manual | J28: - | K28: CNMS_Deuterium_Int | L28: =IF(D28="ASW","PUT_VERSION","-") -> - | M28: LU Martin (CC-AS/ESW2-CN) | O28: T03 | S28: 148 | T28: 148 | V28: =ROUNDDOWN(T28/HLOOKUP(D28,Table!$C$3:$D$4,2,0)*8,2) -> 2.63 | X28: N/A | Z28: 43901
B29: =B28+1 -> 27 | C29: 20200303 | D29: PSW | E29: CNMS Super Deuterium BSS01 | F29: rb\as\rbcn\core\app\dcom\RBAPLCust\src\IPB | G29: 1341660 | H29: RBAPLCUST_RDBI_IPBAssemblyMode.c | I29: Manual | J29: - | K29: CNMS_Deuterium_Int | L29: =IF(D29="ASW","PUT_VERSION","-") -> - | M29: LU Martin (CC-AS/ESW2-CN) | O29: T03 | S29: 17 | T29: 17 | V29: =ROUNDDOWN(T29/HLOOKUP(D29,Table!$C$3:$D$4,2,0)*8,2) -> 0.3 | X29: N/A | Z29: 43901
B30: =B29+1 -> 28 | C30: 20200303 | D30: PSW | E30: CNMS Super Deuterium BSS01 | F30: rb\as\rbcn\core\app\dcom\RBAPLCust\src\IPB | G30: 1341660 | H30: RBAPLCUST_RDBI_PBC.c | I30: Manual | J30: - | K30: CNMS_Deuterium_Int | L30: =IF(D30="ASW","PUT_VERSION","-") -> - | M30: LU Martin (CC-AS/ESW2-CN) | O30: T03 | S30: 18 | T30: 18 | V30: =ROUNDDOWN(T30/HLOOKUP(D30,Table!$C$3:$D$4,2,0)*8,2) -> 0.32 | X30: N/A | Z30: 43901
B31: =B30+1 -> 29 | C31: 20200303 | D31: PSW | E31: CNMS Super Deuterium BSS01 | F31: rb\as\rbcn\core\app\dcom\RBAPLCust\src\IPB | G31: 1341660 | H31: RBAPLCUST_RDBI_SystemData.c | I31: Manual | J31: - | K31: CNMS_Deuterium_Int | L31: =IF(D31="ASW","PUT_VERSION","-") -> - | M31: LU Martin (CC-AS/ESW2-CN) | O31: T03 | P31: loc.do-phu | S31: 129 | T31: 129 | U31: 129 | V31: =ROUNDDOWN(T31/HLOOKUP(D31,Table!$C$3:$D$4,2,0)*8,2) -> 2.29 | W31: 3 | X31: Ready for review | Z31: 43901 | AA31: 43895 | AB31: 43895 | AC31: OK | AD31: 100 | AE31: 100 | AF31: 100
B32: =B31+1 -> 30 | C32: 20200303 | D32: PSW | E32: CNMS Super Deuterium BSS01 | F32: rb\as\rbcn\core\app\dcom\RBAPLCust\src\IPB | G32: 1341660 | H32: RBAPLCUST_RDBI_SystemSensor.c | I32: Manual | J32: - | K32: CNMS_Deuterium_Int | L32: =IF(D32="ASW","PUT_VERSION","-") -> - | M32: LU Martin (CC-AS/ESW2-CN) | O32: T03 | P32: loc.do-phu | S32: 164 | T32: 196 | U32: 196 | V32: =ROUNDDOWN(T32/HLOOKUP(D32,Table!$C$3:$D$4,2,0)*8,2) -> 3.48 | W32: 4 | X32: Ready for review | Z32: 43901 | AA32: 43896 | AB32: 43896 | AC32: OK | AD32: 100 | AE32: 100 | AF32: 100
B33: =B32+1 -> 31 | C33: 20200303 | D33: PSW | E33: CNMS Super Deuterium BSS01 | F33: rb\as\rbcn\core\app\dcom\RBAPLCust\src\IPB | G33: 1341660 | H33: RBAPLCUST_RoutineControl_INSCalibration.c | I33: Manual | J33: - | K33: CNMS_Deuterium_Int | L33: =IF(D33="ASW","PUT_VERSION","-") -> - | M33: LU Martin (CC-AS/ESW2-CN) | O33: T03 | P33: loc.do-phu | S33: 104 | T33: 104 | V33: =ROUNDDOWN(T33/HLOOKUP(D33,Table!$C$3:$D$4,2,0)*8,2) -> 1.84 | W33: 1 | X33: Ongoing | Z33: 43901 | AA33: 43896 | AC33: NG | AG33: Waiting for OPL answer.
B34: =B33+1 -> 32 | C34: 20200303 | D34: PSW | E34: CNMS Super Deuterium BSS01 | F34: rb\as\rbcn\core\app\dcom\RBAPLCust\src\IPB | G34: 1341660 | H34: RBAPLCUST_RoutineControl_IPBAirMonitoring.c | I34: Manual | J34: - | K34: CNMS_Deuterium_Int | L34: =IF(D34="ASW","PUT_VERSION","-") -> - | M34: LU Martin (CC-AS/ESW2-CN) | O34: T03 | P34: loc.do-phu | S34: 154 | T34: 154 | V34: =ROUNDDOWN(T34/HLOOKUP(D34,Table!$C$3:$D$4,2,0)*8,2) -> 2.73 | X34: N/A | Z34: 43901
B35: =B34+1 -> 33 | C35: 20200303 | D35: PSW | E35: CNMS Super Deuterium BSS01 | F35: rb\as\rbcn\core\app\dcom\RBAPLCust\src\IPB | G35: 1341660 | H35: RBAPLCUST_RoutineControl_IPBBrakeFluidChange.c | I35: Manual | J35: - | K35: CNMS_Deuterium_Int | L35: =IF(D35="ASW","PUT_VERSION","-") -> - | M35: LU Martin (CC-AS/ESW2-CN) | O35: T03 | P35: loc.do-phu | S35: 167 | T35: 167 | V35: =ROUNDDOWN(T35/HLOOKUP(D35,Table!$C$3:$D$4,2,0)*8,2) -> 2.96 | X35: N/A | Z35: 43901
B36: =B35+1 -> 34 | C36: 20200303 | D36: PSW | E36: CNMS Super Deuterium BSS01 | F36: rb\as\rbcn\core\app\dcom\RBAPLCust\src\IPB | G36: 1341660 | H36: RBAPLCUST_RoutineControl_IPBComfortPulseCalibration.c | I36: Manual | J36: - | K36: CNMS_Deuterium_Int | L36: =IF(D36="ASW","PUT_VERSION","-") -> - | M36: LU Martin (CC-AS/ESW2-CN) | O36: T03 | P36: loc.do-phu | S36: 147 | T36: 147 | V36: =ROUNDDOWN(T36/HLOOKUP(D36,Table!$C$3:$D$4,2,0)*8,2) -> 2.61 | X36: N/A | Z36: 43901
B37: =B36+1 -> 35 | C37: 20200303 | D37: PSW | E37: CNMS Super Deuterium BSS01 | F37: rb\as\rbcn\core\app\dcom\RBAPLCust\src\IPB | G37: 1341660 | H37: RBAPLCUST_RoutineControl_IPBDynamicTest.c | I37: Manual | J37: - | K37: CNMS_Deuterium_Int | L37: =IF(D37="ASW","PUT_VERSION","-") -> - | M37: LU Martin (CC-AS/ESW2-CN) | O37: T03 | P37: loc.do-phu | S37: 254 | T37: 254 | V37: =ROUNDDOWN(T37/HLOOKUP(D37,Table!$C$3:$D$4,2,0)*8,2) -> 4.51 | X37: N/A | Z37: 43901
B38: =B37+1 -> 36 | C38: 20200303 | D38: PSW | E38: CNMS Super Deuterium BSS01 | F38: rb\as\rbcn\core\app\dcom\RBAPLCust\src\IPB | G38: 1341660 | H38: RBAPLCUST_RoutineControl_IPBEvacAndFill.c | I38: Manual | J38: - | K38: CNMS_Deuterium_Int | L38: =IF(D38="ASW","PUT_VERSION","-") -> - | M38: LU Martin (CC-AS/ESW2-CN) | O38: T03 | S38: 193 | T38: 193 | V38: =ROUNDDOWN(T38/HLOOKUP(D38,Table!$C$3:$D$4,2,0)*8,2) -> 3.43 | X38: N/A | Z38: 43901
B39: =B38+1 -> 37 | C39: 20200303 | D39: PSW | E39: CNMS Super Deuterium BSS01 | F39: rb\as\rbcn\core\app\dcom\RBAPLCust\src\IPB | G39: 1341660 | H39: RBAPLCUST_RoutineControl_IPBLeakageAndAirTest.c | I39: Manual | J39: - | K39: CNMS_Deuterium_Int | L39: =IF(D39="ASW","PUT_VERSION","-") -> - | M39: LU Martin (CC-AS/ESW2-CN) | O39: T03 | S39: 204 | T39: 204 | V39: =ROUNDDOWN(T39/HLOOKUP(D39,Table!$C$3:$D$4,2,0)*8,2) -> 3.62 | X39: N/A | Z39: 43901
B40: =B39+1 -> 38 | C40: 20200303 | D40: PSW | E40: CNMS Super Deuterium BSS01 | F40: rb\as\rbcn\core\app\dcom\RBAPLCust\src\IPB | G40: 1341660 | H40: RBAPLCUST_RoutineControl_IPBRepairBleed.c | I40: Manual | J40: - | K40: CNMS_Deuterium_Int | L40: =IF(D40="ASW","PUT_VERSION","-") -> - | M40: LU Martin (CC-AS/ESW2-CN) | O40: T03 | S40: 194 | T40: 194 | V40: =ROUNDDOWN(T40/HLOOKUP(D40,Table!$C$3:$D$4,2,0)*8,2) -> 3.44 | X40: N/A | Z40: 43901
B41: =B40+1 -> 39 | C41: 20200303 | D41: PSW | E41: CNMS Super Deuterium BSS01 | F41: rb\as\rbcn\core\app\dcom\RBAPLCust\src\IPB | G41: 1341660 | H41: RBAPLCUST_RoutineControl_IPBRPSCalibration.c | I41: Manual | J41: - | K41: CNMS_Deuterium_Int | L41: =IF(D41="ASW","PUT_VERSION","-") -> - | M41: LU Martin (CC-AS/ESW2-CN) | O41: T03 | S41: 141 | T41: 141 | V41: =ROUNDDOWN(T41/HLOOKUP(D41,Table!$C$3:$D$4,2,0)*8,2) -> 2.5 | X41: N/A | Z41: 43901
...

Sheet |->

Sheet Template
B2: No | C2: Package | D2: Type | E2: Project | F2: ComponentName | G2: TaskID | H2: ItemName | I2: ItemRevision | J2: Task Jira | K2: TaskGroup | L2: Tester | M2: LOC | N2: LOC Complete | O2: Estimation hour | P2: Actual hour | Q2: Status | R2: Planned Start | S2: Planned End | T2: Start | U2: End | V2: C0 | W2: C1 | X2: MCDC | Y2: Reason
B3: 1 | C3: 1 | D3: PSW | E3: GAC_220680_Carbon_A18_ESPHevx_FPA/RPA_BL03 | F3: rb\as\gaig\prj\dsmpr\src\RBVoltageHandler\src\ | G3: 1348323 | H3: RBVoltageHandler_Suppression.c | I3: - | J3: N/A | M3: 113 | O3: =ROUNDDOWN(M3/HLOOKUP(Template!D3,Table!$C$3:$D$4,2,0)*8,2) -> 2 | Q3: Ongoing | R3: 43892 | S3: 43924 | T3: 43892
B4: 2 | C4: 1 | D4: PSW | E4: MC_227282_SGMW_E200_Plus_ESPCPiGen9.3_BSS04_SP02 | F4: rb\as\sgmw\CN210S\app\net\RBScl\RBScl_SGMW\src\ | G4: 1345876 | H4: SGMW_RBA_NDS_HBCRequest_Callout.c | I4: - | J4: N/A | M4: 148 | O4: =ROUNDDOWN(M4/HLOOKUP(Template!D4,Table!$C$3:$D$4,2,0)*8,2) -> 2.63 | Q4: Ongoing | R4: 43892 | S4: 43924 | T4: 43892
B5: 3 | C5: 1 | D5: PSW | E5: 241595_GAC_A27_ESP9.3CP_BL04 | F5: rb\as\gaig\A10\dsmpr\src\RBHMI\src\ | G5: 1350941 | H5: RBHMI_LDMLamp_CNMS.c | I5: - | J5: N/A | M5: 291 | O5: =ROUNDDOWN(M5/HLOOKUP(Template!D5,Table!$C$3:$D$4,2,0)*8,2) -> 5.17 | Q5: Ongoing | R5: 43892 | S5: 43924 | T5: 43892
B6: 4 | C6: 1 | D6: PSW | E6: 223331_GAC_A39_Carbon_ESP9.3HD_OBD_BL07 | F6: rb\as\cnms_core\app\obd\ObdCyclesHandler\src\ | G6: 1351929 | H6: ObdCyclesHandler.c | I6: - | J6: N/A | M6: 254 | O6: =ROUNDDOWN(M6/HLOOKUP(Template!D6,Table!$C$3:$D$4,2,0)*8,2) -> 4.51 | Q6: Ongoing | R6: 43892 | S6: 43924 | T6: 43892
B7: 5 | C7: 1 | D7: ASW | E7: DFN_ESP_Gen9.3_532EC_244112_BSS01 | F7: - | G7: 1351929 | H7: PAP_Odometry | I7: 4.2.104.1 | J7: N/A | M7: 19 | O7: =ROUNDDOWN(M7/HLOOKUP(Template!D7,Table!$C$3:$D$4,2,0)*8,2) -> 1.16 | Q7: Ongoing | R7: 43892 | S7: 43924 | T7: 43892
B8: 6 | C8: 2 | D8: PSW | E8: MC_232534_SGMW_CN202C_ESP9.3CPi_ACC_BSS04_SP02 | F8: RBAPLCust\src\ESP\ | G8: 1351848 | H8: RBAPLCUST_EOLDelayCtrlOrAPBMi.c | I8: - | J8: N/A | M8: 478 | O8: =ROUNDDOWN(M8/HLOOKUP(Template!D8,Table!$C$3:$D$4,2,0)*8,2) -> 8.49 | Q8: Ongoing | R8: 43892 | S8: 43924 | T8: 43892
B9: 7 | C9: 2 | D9: PSW | E9: MC_232534_SGMW_CN202C_ESP9.3CPi_ACC_BSS04_SP02 | F9: RBAPLCust\src\ESP\ | G9: 1351848 | H9: RBAPLCUST_RDBI_TPMS.c | I9: - | J9: N/A | M9: 286 | O9: =ROUNDDOWN(M9/HLOOKUP(Template!D9,Table!$C$3:$D$4,2,0)*8,2) -> 5.08 | Q9: Ongoing | R9: 43892 | S9: 43924 | T9: 43892
B10: 8 | C10: 2 | D10: PSW | E10: MC_232534_SGMW_CN202C_ESP9.3CPi_ACC_BSS04_SP02 | F10: RBAPLCust\src\ESP\ | G10: 1351848 | H10: RBAPLCUST_RoutineControl_TPMSReset.c | I10: - | J10: N/A | M10: 110 | O10: =ROUNDDOWN(M10/HLOOKUP(Template!D10,Table!$C$3:$D$4,2,0)*8,2) -> 1.95 | Q10: Ongoing | R10: 43892 | S10: 43924 | T10: 43892
B17: Table KPI ASW
B18: No | C18: Tester | D18: Total Loc Assigned | E18: Total LOC Complete | F18: Total Day | G18: KPI/days | H18: Status (%)
B19: 1 | C19: hieu.nguyen-trung | D19: =SUMIFS($M$3:$M$6,$D$3:$D$6,Table!$C$3,$L$3:$L$6,Table!C13) -> 0 | E19: =SUMIFS($N$3:$N$6,$D$3:$D$6,Table!$C$3,$L$3:$L$6,Table!C13)-SUM(SUMIFS($N$3:$N$6,$D$3:$D$6,Table!$C$3,$L$3:$L$6,Table!C13,$Q$3:$Q$6,{"Ongoing","N/A"})) -> 0 | F19: =1/8*(SUMIFS($P$3:$P$6,$D$3:$D$6,Table!$C$3,$L$3:$L$6,Table!C13)-SUM(SUMIFS($P$3:$P$6,$D$3:$D$6,Table!$C$3,$L$3:$L$6,Table!C13,$Q$3:$Q$6,{"Ongoing","N/A"}))) -> 0 | G19: =E19/(F19) -> #DIV/0! | H19: =E19/D19 -> #DIV/0!
B20: 2 | C20: duong.nguyen-tuan | D20: =SUMIFS($M$3:$M$6,$D$3:$D$6,Table!$C$3,$L$3:$L$6,Table!#REF!) -> 0 | E20: =SUMIFS($N$3:$N$6,$D$3:$D$6,Table!$C$3,$L$3:$L$6,Table!#REF!)-SUM(SUMIFS($N$3:$N$6,$D$3:$D$6,Table!$C$3,$L$3:$L$6,Table!#REF!,$Q$3:$Q$6,{"Ongoing","N/A"})) -> 0 | F20: =1/8*(SUMIFS($P$3:$P$6,$D$3:$D$6,Table!$C$3,$L$3:$L$6,Table!#REF!)-SUM(SUMIFS($P$3:$P$6,$D$3:$D$6,Table!$C$3,$L$3:$L$6,Table!#REF!,$Q$3:$Q$6,{"Ongoing","N/A"}))) -> 0 | G20: =E20/(F20) -> #DIV/0! | H20: =E20/D20 -> #DIV/0!
B21: 3 | C21: duong.nguyen-tuan | D21: =SUMIFS($M$3:$M$6,$D$3:$D$6,Table!$C$3,$L$3:$L$6,Table!C21) -> 0 | E21: =SUMIFS($N$3:$N$6,$D$3:$D$6,Table!$C$3,$L$3:$L$6,Table!C21)-SUM(SUMIFS($N$3:$N$6,$D$3:$D$6,Table!$C$3,$L$3:$L$6,Table!C21,$Q$3:$Q$6,{"Ongoing","N/A"})) -> 0 | F21: =1/8*(SUMIFS($P$3:$P$6,$D$3:$D$6,Table!$C$3,$L$3:$L$6,Table!C21)-SUM(SUMIFS($P$3:$P$6,$D$3:$D$6,Table!$C$3,$L$3:$L$6,Table!C21,$Q$3:$Q$6,{"Ongoing","N/A"}))) -> 0 | G21: =E21/(F21) -> #DIV/0! | H21: =E21/D21 -> #DIV/0!
B22: 4 | C22: duong.nguyen-tuan | D22: =SUMIFS($M$3:$M$6,$D$3:$D$6,Table!$C$3,$L$3:$L$6,Table!C22) -> 0 | E22: =SUMIFS($N$3:$N$6,$D$3:$D$6,Table!$C$3,$L$3:$L$6,Table!C22)-SUM(SUMIFS($N$3:$N$6,$D$3:$D$6,Table!$C$3,$L$3:$L$6,Table!C22,$Q$3:$Q$6,{"Ongoing","N/A"})) -> 0 | F22: =1/8*(SUMIFS($P$3:$P$6,$D$3:$D$6,Table!$C$3,$L$3:$L$6,Table!C22)-SUM(SUMIFS($P$3:$P$6,$D$3:$D$6,Table!$C$3,$L$3:$L$6,Table!C22,$Q$3:$Q$6,{"Ongoing","N/A"}))) -> 0 | G22: =E22/(F22) -> #DIV/0! | H22: =E22/D22 -> #DIV/0!
B23: 5 | C23: duong.nguyen-tuan | D23: =SUMIFS($M$3:$M$6,$D$3:$D$6,Table!$C$3,$L$3:$L$6,Table!C23) -> 0 | E23: =SUMIFS($N$3:$N$6,$D$3:$D$6,Table!$C$3,$L$3:$L$6,Table!C23)-SUM(SUMIFS($N$3:$N$6,$D$3:$D$6,Table!$C$3,$L$3:$L$6,Table!C23,$Q$3:$Q$6,{"Ongoing","N/A"})) -> 0 | F23: =1/8*(SUMIFS($P$3:$P$6,$D$3:$D$6,Table!$C$3,$L$3:$L$6,Table!C23)-SUM(SUMIFS($P$3:$P$6,$D$3:$D$6,Table!$C$3,$L$3:$L$6,Table!C23,$Q$3:$Q$6,{"Ongoing","N/A"}))) -> 0 | G23: =E23/(F23) -> #DIV/0! | H23: =E23/D23 -> #DIV/0!
B24: 6 | C24: duong.nguyen-tuan | D24: =SUMIFS($M$3:$M$6,$D$3:$D$6,Table!$C$3,$L$3:$L$6,Table!C24) -> 0 | E24: =SUMIFS($N$3:$N$6,$D$3:$D$6,Table!$C$3,$L$3:$L$6,Table!C24)-SUM(SUMIFS($N$3:$N$6,$D$3:$D$6,Table!$C$3,$L$3:$L$6,Table!C24,$Q$3:$Q$6,{"Ongoing","N/A"})) -> 0 | F24: =1/8*(SUMIFS($P$3:$P$6,$D$3:$D$6,Table!$C$3,$L$3:$L$6,Table!C24)-SUM(SUMIFS($P$3:$P$6,$D$3:$D$6,Table!$C$3,$L$3:$L$6,Table!C24,$Q$3:$Q$6,{"Ongoing","N/A"}))) -> 0 | G24: =E24/(F24) -> #DIV/0! | H24: =E24/D24 -> #DIV/0!
B25: 7 | C25: duong.nguyen-tuan | D25: =SUMIFS($M$3:$M$6,$D$3:$D$6,Table!$C$3,$L$3:$L$6,Table!C25) -> 0 | E25: =SUMIFS($N$3:$N$6,$D$3:$D$6,Table!$C$3,$L$3:$L$6,Table!C25)-SUM(SUMIFS($N$3:$N$6,$D$3:$D$6,Table!$C$3,$L$3:$L$6,Table!C25,$Q$3:$Q$6,{"Ongoing","N/A"})) -> 0 | F25: =1/8*(SUMIFS($P$3:$P$6,$D$3:$D$6,Table!$C$3,$L$3:$L$6,Table!C25)-SUM(SUMIFS($P$3:$P$6,$D$3:$D$6,Table!$C$3,$L$3:$L$6,Table!C25,$Q$3:$Q$6,{"Ongoing","N/A"}))) -> 0 | G25: =E25/(F25) -> #DIV/0! | H25: =E25/D25 -> #DIV/0!
B26: 8 | C26: duong.nguyen-tuan | D26: =SUMIFS($M$3:$M$6,$D$3:$D$6,Table!$C$3,$L$3:$L$6,Table!C26) -> 0 | E26: =SUMIFS($N$3:$N$6,$D$3:$D$6,Table!$C$3,$L$3:$L$6,Table!C26)-SUM(SUMIFS($N$3:$N$6,$D$3:$D$6,Table!$C$3,$L$3:$L$6,Table!C26,$Q$3:$Q$6,{"Ongoing","N/A"})) -> 0 | F26: =1/8*(SUMIFS($P$3:$P$6,$D$3:$D$6,Table!$C$3,$L$3:$L$6,Table!C26)-SUM(SUMIFS($P$3:$P$6,$D$3:$D$6,Table!$C$3,$L$3:$L$6,Table!C26,$Q$3:$Q$6,{"Ongoing","N/A"}))) -> 0 | G26: =E26/(F26) -> #DIV/0! | H26: =E26/D26 -> #DIV/0!
B27: 9 | C27: duong.nguyen-tuan | D27: =SUMIFS($M$3:$M$6,$D$3:$D$6,Table!$C$3,$L$3:$L$6,Table!C30) -> 0 | E27: =SUMIFS($N$3:$N$6,$D$3:$D$6,Table!$C$3,$L$3:$L$6,Table!C30)-SUM(SUMIFS($N$3:$N$6,$D$3:$D$6,Table!$C$3,$L$3:$L$6,Table!C30,$Q$3:$Q$6,{"Ongoing","N/A"})) -> 0 | F27: =1/8*(SUMIFS($P$3:$P$6,$D$3:$D$6,Table!$C$3,$L$3:$L$6,Table!C30)-SUM(SUMIFS($P$3:$P$6,$D$3:$D$6,Table!$C$3,$L$3:$L$6,Table!C30,$Q$3:$Q$6,{"Ongoing","N/A"}))) -> 0 | G27: =E27/(F27) -> #DIV/0! | H27: =E27/D27 -> #DIV/0!
B28: 10 | C28: duong.nguyen-tuan | D28: =SUMIFS($M$3:$M$6,$D$3:$D$6,Table!$C$3,$L$3:$L$6,Table!C31) -> 0 | E28: =SUMIFS($N$3:$N$6,$D$3:$D$6,Table!$C$3,$L$3:$L$6,Table!C31)-SUM(SUMIFS($N$3:$N$6,$D$3:$D$6,Table!$C$3,$L$3:$L$6,Table!C31,$Q$3:$Q$6,{"Ongoing","N/A"})) -> 0 | F28: =1/8*(SUMIFS($P$3:$P$6,$D$3:$D$6,Table!$C$3,$L$3:$L$6,Table!C31)-SUM(SUMIFS($P$3:$P$6,$D$3:$D$6,Table!$C$3,$L$3:$L$6,Table!C31,$Q$3:$Q$6,{"Ongoing","N/A"}))) -> 0 | G28: =E28/(F28) -> #DIV/0! | H28: =E28/D28 -> #DIV/0!
B29: 2 | C29: duong.nguyen-tuan | D29: =SUMIFS($M$3:$M$6,$D$3:$D$6,Table!$C$3,$L$3:$L$6,Table!C32) -> 0 | E29: =SUMIFS($N$3:$N$6,$D$3:$D$6,Table!$C$3,$L$3:$L$6,Table!C32)-SUM(SUMIFS($N$3:$N$6,$D$3:$D$6,Table!$C$3,$L$3:$L$6,Table!C32,$Q$3:$Q$6,{"Ongoing","N/A"})) -> 0 | F29: =1/8*(SUMIFS($P$3:$P$6,$D$3:$D$6,Table!$C$3,$L$3:$L$6,Table!C32)-SUM(SUMIFS($P$3:$P$6,$D$3:$D$6,Table!$C$3,$L$3:$L$6,Table!C32,$Q$3:$Q$6,{"Ongoing","N/A"}))) -> 0 | G29: =E29/(F29) -> #DIV/0! | H29: =E29/D29 -> #DIV/0!
B30: 2 | C30: duong.nguyen-tuan | D30: =SUMIFS($M$3:$M$6,$D$3:$D$6,Table!$C$3,$L$3:$L$6,Table!C33) -> 0 | E30: =SUMIFS($N$3:$N$6,$D$3:$D$6,Table!$C$3,$L$3:$L$6,Table!C33)-SUM(SUMIFS($N$3:$N$6,$D$3:$D$6,Table!$C$3,$L$3:$L$6,Table!C33,$Q$3:$Q$6,{"Ongoing","N/A"})) -> 0 | F30: =1/8*(SUMIFS($P$3:$P$6,$D$3:$D$6,Table!$C$3,$L$3:$L$6,Table!C33)-SUM(SUMIFS($P$3:$P$6,$D$3:$D$6,Table!$C$3,$L$3:$L$6,Table!C33,$Q$3:$Q$6,{"Ongoing","N/A"}))) -> 0 | G30: =E30/(F30) -> #DIV/0! | H30: =E30/D30 -> #DIV/0!
B31: 3
B34: Table KPI PSW
B35: No | C35: Tester | D35: Total Loc Assigned | E35: Total LOC Complete | F35: Total Day | G35: KPI/days | H35: Status (%)
B36: 1 | C36: hieu.nguyen-trung | D36: =SUMIFS($M$3:$M$6,$D$3:$D$6,Table!$D$3,$L$3:$L$6,Table!C13) -> 0 | E36: =SUMIFS($M$3:$M$6,$D$3:$D$6,Table!$D$3,$L$3:$L$6,Table!C13)-SUM(SUMIFS($M$3:$M$6,$D$3:$D$6,Table!$D$3,$L$3:$L$6,Table!C13,$Q$3:$Q$6,{"Ongoing","N/A"})) -> 0 | F36: =1/8*(SUMIFS($P$3:$P$6,$D$3:$D$6,Table!$D$3,$L$3:$L$6,Table!C13)-SUM(SUMIFS($P$3:$P$6,$D$3:$D$6,Table!$D$3,$L$3:$L$6,Table!C13,$Q$3:$Q$6,{"Ongoing","N/A"}))) -> 0 | G36: =E36/(F36) -> #DIV/0! | H36: =E36/D36 -> #DIV/0!
B37: 2 | C37: duong.nguyen-tuan | D37: =SUMIFS($M$3:$M$6,$D$3:$D$6,Table!$D$3,$L$3:$L$6,Table!#REF!) -> 0 | E37: =SUMIFS($M$3:$M$6,$D$3:$D$6,Table!$D$3,$L$3:$L$6,Table!#REF!)-SUM(SUMIFS($M$3:$M$6,$D$3:$D$6,Table!$D$3,$L$3:$L$6,Table!#REF!,$Q$3:$Q$6,{"Ongoing","N/A"})) -> 0 | F37: =1/8*(SUMIFS($P$3:$P$6,$D$3:$D$6,Table!$D$3,$L$3:$L$6,Table!#REF!)-SUM(SUMIFS($P$3:$P$6,$D$3:$D$6,Table!$D$3,$L$3:$L$6,Table!#REF!,$Q$3:$Q$6,{"Ongoing","N/A"}))) -> 0 | G37: =E37/(F37) -> #DIV/0! | H37: =E37/D37 -> #DIV/0!
B38: 3

Sheet Table
B2: KPI Table
B3: No\Type | C3: ASW | D3: PSW
B4: 1 | C4: 130 | D4: 450
B6: Table Type of Testing
B7: No | C7: Type | D7: Tool | E7: Detail Output
B8: 1 | C8: ASW | D8: ATT | E8: 1. Test Design (.xls) 2. Plot File (.plt) 3. ATT project 4. Coverage Log
B9: 2 | C9: PSW | D9: Cantata | E9: 1. TPA file (.tpa) 2. test report (.html) 3. test report (.xml) 4. test summary (.html) 5. File Coverage Fail Reason (.xls)
B11: Table Tester
B12: No | C12: Member
B13: 1 | C13: hieu.nguyen-trung
B14: 2 | C14: hau.nguyen-tai
B15: 3 | C15: bang.nguyen-duy
B16: 4 | C16: dac.luu-cong
B17: 5 | C17: duong.nguyen
B18: 6 | C18: loc.do-phu
B19: 7 | C19: thanh.nguyen-kim
B20: 8 | C20: chung.ly
B22: Status Table
B23: No | C23: Status
B24: 1 | C24: N/A | E24: COEM process: test-->review test----(feedback no finding)-->generate WT----(review WT no finding)---> done task Tức là bên anh gửi UT output cho internal => Có OPL có bug => Internal review OK => Làm walkthrough => Sau đó internal review Walkthrough => Send email cho External confirm OK => Mark Done
B25: 2 | C25: Ongoing
B26: 3 | C26: Ready for review
B27: 4 | C27: Ready for delivery
B28: 5 | C28: Ready for PLC
B29: 6 | C29: Pending for OPL
B30: 7 | C30: Complete & Closed

Sheet Template_Weekly_Report
A1: Date | B1: 43864
A2: Total Days | B2: 20
B4: 1. Completed ELOCs of the team from the beginning of Month (Mar) till Now:
C5: # | D5: Types | E5: Assigned ELOCs | F5: Completed ELOCs | G5: Status (%) (Completed/Assigned)
C6: 1 | D6: PSW | E6: ??? | F6: ??? | G6: ???
C7: 2 | D7: ASW | E7: ??? | F7: ??? | G7: ???
B9: 2. Completed ELOCs of each member from the beginning of Month (Mar) till Now:
C10: # | D10: External Name | E10: PSW ELOCs | F10: ASW ELOCs
C11: 1 | D11: hieu.nguyen-trung | E11: ??? | F11: ???
C12: 2 | D12: duong.nguyen-tuan | E12: ??? | F12: ???
B14: 3. Risks/ Pending Issues:
C15: # | D15: Risks/ Issues
C16: 1
C17: 2
B19: 4. Found Defects/ OPLs in Month (Mar):
C20: # | D20: Defects / OPLs
C21: 1
C22: 2
B24: 5. Leave Plan (Mar):
C25: # | D25: External Name | E25: Num of Day | F25: Detail
C26: 1 | D26: hieu.nguyen-trung | E26: ??? | F26: ???
C27: 2 | D27: duong.nguyen-tuan | E27: ??? | F27: ???
B29: Note:
C30: Productivity of each Member per Day
D31: PSW: 450 ELOCs
D32: ASW: 150 ELOCs
C33: Total Productivity per Month
D34: PSW: 450x4x20 = 36,000 ELOCs
D35: ASW: 130x4x20 = 10,400 ELOCs

Sheet Check_List
A1: Location
B2: + Location Internal Project: | C2: \\hc-ut40346c\NHI5HC\hieunguyen\0000_Project
B3: + Location Internal Your Output: | C3: \\hc-ut40346c\NHI5HC\hieunguyen\0000_Project\001_Prj\01_COEM\01_Output_Package
B5: Please ensure your push correct the Package name with the TaskGroup
B6: + Location Internal Your Release Output: | C6: \\hc-ut40346c\NHI5HC\hieunguyen\0000_Project\001_Prj\01_COEM\02_Release_Package
B8: + Location for delivery to internal team: | C8: \\hc-ut40745c\Ban_Vien_external\Release\Gen_9.3
