Workbook

Sheet Sheet1
B1: Project | C1: Tester | D1: Actual effort | E1: Estimate effort
B2: GWM_B30_CP | C2: hieu.nguyen-trung | D2: 2 | E2: 1.1 | G2: BL
B3: GWM_B30_CP | C3: hieu.nguyen-trung | D3: 0.5 | E3: 0.39 | G3: BS
B4: GWM_B30_CP | C4: hieu.nguyen-trung | D4: 0.5 | E4: 0.46 | G4: BSS
B5: GWM_B30_CP | C5: hieu.nguyen-trung | D5: 1 | E5: 0.62 | G5: BSL
B6: GWM_B30_CP | C6: hieu.nguyen-trung | D6: 1 | E6: 1.79
B7: GWM_B30_CP | C7: hieu.nguyen-trung | D7: 1 | E7: 1.19
B8: GWM_B30_CP | C8: hieu.nguyen-trung | D8: 1 | E8: 2.43
B9: GWM_B30_CP | C9: hieu.nguyen-trung | D9: 1 | E9: 2.84
B10: GWM_B30_CP | C10: hieu.nguyen-trung | D10: 1 | E10: 2.45
B11: GWM_B30_CP | C11: hieu.nguyen-trung | D11: 1 | E11: 3.34
B12: GWM_B30_CP | C12: hau.nguyen-tai | D12: 2 | E12: 3.36
B13: GWM_B30_CP | C13: hau.nguyen-tai | D13: 2 | E13: 3.07
B14: GWM_B30_CP | C14: hau.nguyen-tai | D14: 2 | E14: 3.12
B15: GWM_B30_CP | C15: hau.nguyen-tai | D15: 2 | E15: 4.24
B16: GWM_B30_CP | C16: hau.nguyen-tai | D16: 1 | E16: 4.21
B17: GWM_B30_CP | C17: hau.nguyen-tai | D17: 1 | E17: 0.14
... B225: FAW_E111_ESPhev | C225: loc.do-phu | D225: 0.5 | E225: 1.76
B226: 241595_GAC_A27_ESP9.3CP | C226: chung.ly | D226: 2.5
B227: 235149_FAW_HS7_RC_BL02 | C227: loc.do-phu | D227: 4.5
B228: 235149_FAW_HS7_RC_BL02 | C228: duong.nguyen | D228: 2
B229: GWM_B30HP ESP | C229: loc.do-phu | D229: 2
B230: GWM_B30HP ESP | C230: duong.nguyen | D230: 1
B231: GWM_B30HP ESP | C231: loc.do-phu | D231: 2
B232: GWM_B30HP ESP | C232: duong.nguyen | D232: 1
B233: GWM_B30HP ESP | C233: chung.ly | D233: 0.5
B234: GWM_B30HP ESP | C234: duong.nguyen | D234: 4
B235: GWM_B30HP ESP | C235: duong.nguyen | D235: 3
B236: GWM_B30HP ESP | C236: thanh.nguyen-kim | D236: 0.4
B237: GWM_B30HP ESP | C237: thanh.nguyen-kim | D237: 1.5
... B446: XE431RC ABS10.3ME | C446: thanh.nguyen-kim | D446: 2
B447: XE431RC ABS10.3ME | C447: thanh.nguyen-kim | D447: =0.4 -> 0.4
B448: XE431RC ABS10.3ME | C448: thanh.nguyen-kim | D448: 2
B449: XE431RC ABS10.3ME | C449: thanh.nguyen-kim | D449: 1.5
B450: XE431RC ABS10.3ME | C450: thanh.nguyen-kim | D450: 3
B451: XE431RC ABS10.3ME | C451: thanh.nguyen-kim | D451: 0.5
B452: XE431RC ABS10.3ME | C452: duong.nguyen | D452: 1.8
B453: XE431RC ABS10.3ME | C453: duong.nguyen | D453: 2
B454: XE431RC ABS10.3ME | C454: duong.nguyen | D454: 3
B455: XE431RC ABS10.3ME | C455: loc.do-phu | D455: 2
...

Sheet Sheet3
B1: Project | C1: Tester | D1: Actual effort
B2: 206370_BYD_ESP9.3_New_Hybrid_MS15.1 | C2: huy.do-anh | D2: 0.5 | F2: =IF(AND($C2 = Temp!$B$1, $B2 = Temp!$A$16),$D2,0) -> 0 | G2: =IF(AND($C2 = Temp!$C$1, $B2 = Temp!$A$16),$D2,0) -> 0 | H2: =IF(AND($C2 = Temp!$D$1, $B2 = Temp!$A$16),$D2,0) -> 0 | I2: =IF(AND($C2 = Temp!$E$1, $B2 = Temp!$A$16),$D2,0) -> 0 | J2: =IF(AND($C2 = Temp!$F$1, $B2 = Temp!$A$16),$D2,0) -> 0 | K2: =IF(AND($C2 = Temp!$G$1, $B2 = Temp!$A$16),$D2,0) -> 0 | L2: =IF(AND($C2 = Temp!$H$1, $B2 = Temp!$A$16),$D2,0) -> 0 | M2: =IF(AND($C2 = Temp!$I$1, $B2 = Temp!$A$16),$D2,0) -> 0 | N2: =IF(AND($C2 = Temp!$J$1, $B2 = Temp!$A$16),$D2,0) -> 0 | O2: =IF(AND($C2 = Temp!$K$1, $B2 = Temp!$A$16),$D2,0) -> 0
B3: 206370_BYD_ESP9.3_New_Hybrid_MS15.1 | C3: huy.do-anh | D3: 0 | F3: =IF(AND($C3 = Temp!$B$1, $B3 = Temp!$A$16),$D3,0) -> 0 | G3: =IF(AND($C3 = Temp!$C$1, $B3 = Temp!$A$16),$D3,0) -> 0 | H3: =IF(AND($C3 = Temp!$D$1, $B3 = Temp!$A$16),$D3,0) -> 0 | I3: =IF(AND($C3 = Temp!$E$1, $B3 = Temp!$A$16),$D3,0) -> 0 | J3: =IF(AND($C3 = Temp!$F$1, $B3 = Temp!$A$16),$D3,0) -> 0 | K3: =IF(AND($C3 = Temp!$G$1, $B3 = Temp!$A$16),$D3,0) -> 0 | L3: =IF(AND($C3 = Temp!$H$1, $B3 = Temp!$A$16),$D3,0) -> 0 | M3: =IF(AND($C3 = Temp!$I$1, $B3 = Temp!$A$16),$D3,0) -> 0 | N3: =IF(AND($C3 = Temp!$J$1, $B3 = Temp!$A$16),$D3,0) -> 0 | O3: =IF(AND($C3 = Temp!$K$1, $B3 = Temp!$A$16),$D3,0) -> 0
B4: 206370_BYD_ESP9.3_New_Hybrid_MS15.1 | C4: hau.nguyen-tai | D4: 1 | F4: =IF(AND($C4 = Temp!$B$1, $B4 = Temp!$A$16),$D4,0) -> 0 | G4: =IF(AND($C4 = Temp!$C$1, $B4 = Temp!$A$16),$D4,0) -> 0 | H4: =IF(AND($C4 = Temp!$D$1, $B4 = Temp!$A$16),$D4,0) -> 0 | I4: =IF(AND($C4 = Temp!$E$1, $B4 = Temp!$A$16),$D4,0) -> 0 | J4: =IF(AND($C4 = Temp!$F$1, $B4 = Temp!$A$16),$D4,0) -> 0 | K4: =IF(AND($C4 = Temp!$G$1, $B4 = Temp!$A$16),$D4,0) -> 0 | L4: =IF(AND($C4 = Temp!$H$1, $B4 = Temp!$A$16),$D4,0) -> 0 | M4: =IF(AND($C4 = Temp!$I$1, $B4 = Temp!$A$16),$D4,0) -> 0 | N4: =IF(AND($C4 = Temp!$J$1, $B4 = Temp!$A$16),$D4,0) -> 0 | O4: =IF(AND($C4 = Temp!$K$1, $B4 = Temp!$A$16),$D4,0) -> 0
B5: 206370_BYD_ESP9.3_New_Hybrid_MS15.1 | C5: hau.nguyen-tai | D5: 2 | F5: =IF(AND($C5 = Temp!$B$1, $B5 = Temp!$A$16),$D5,0) -> 0 | G5: =IF(AND($C5 = Temp!$C$1, $B5 = Temp!$A$16),$D5,0) -> 0 | H5: =IF(AND($C5 = Temp!$D$1, $B5 = Temp!$A$16),$D5,0) -> 0 | I5: =IF(AND($C5 = Temp!$E$1, $B5 = Temp!$A$16),$D5,0) -> 0 | J5: =IF(AND($C5 = Temp!$F$1, $B5 = Temp!$A$16),$D5,0) -> 0 | K5: =IF(AND($C5 = Temp!$G$1, $B5 = Temp!$A$16),$D5,0) -> 0 | L5: =IF(AND($C5 = Temp!$H$1, $B5 = Temp!$A$16),$D5,0) -> 0 | M5: =IF(AND($C5 = Temp!$I$1, $B5 = Temp!$A$16),$D5,0) -> 0 | N5: =IF(AND($C5 = Temp!$J$1, $B5 = Temp!$A$16),$D5,0) -> 0 | O5: =IF(AND($C5 = Temp!$K$1, $B5 = Temp!$A$16),$D5,0) -> 0
B6: 206370_BYD_ESP9.3_New_Hybrid_MS15.1 | C6: hau.nguyen-tai | D6: 4 | F6: =IF(AND($C6 = Temp!$B$1, $B6 = Temp!$A$16),$D6,0) -> 0 | G6: =IF(AND($C6 = Temp!$C$1, $B6 = Temp!$A$16),$D6,0) -> 0 | H6: =IF(AND($C6 = Temp!$D$1, $B6 = Temp!$A$16),$D6,0) -> 0 | I6: =IF(AND($C6 = Temp!$E$1, $B6 = Temp!$A$16),$D6,0) -> 0 | J6: =IF(AND($C6 = Temp!$F$1, $B6 = Temp!$A$16),$D6,0) -> 0 | K6: =IF(AND($C6 = Temp!$G$1, $B6 = Temp!$A$16),$D6,0) -> 0 | L6: =IF(AND($C6 = Temp!$H$1, $B6 = Temp!$A$16),$D6,0) -> 0 | M6: =IF(AND($C6 = Temp!$I$1, $B6 = Temp!$A$16),$D6,0) -> 0 | N6: =IF(AND($C6 = Temp!$J$1, $B6 = Temp!$A$16),$D6,0) -> 0 | O6: =IF(AND($C6 = Temp!$K$1, $B6 = Temp!$A$16),$D6,0) -> 0
B7: 206370_BYD_ESP9.3_New_Hybrid_MS15.1 | C7: bang.nguyen-duy | D7: 2 | F7: =IF(AND($C7 = Temp!$B$1, $B7 = Temp!$A$16),$D7,0) -> 0 | G7: =IF(AND($C7 = Temp!$C$1, $B7 = Temp!$A$16),$D7,0) -> 0 | H7: =IF(AND($C7 = Temp!$D$1, $B7 = Temp!$A$16),$D7,0) -> 0 | I7: =IF(AND($C7 = Temp!$E$1, $B7 = Temp!$A$16),$D7,0) -> 0 | J7: =IF(AND($C7 = Temp!$F$1, $B7 = Temp!$A$16),$D7,0) -> 0 | K7: =IF(AND($C7 = Temp!$G$1, $B7 = Temp!$A$16),$D7,0) -> 0 | L7: =IF(AND($C7 = Temp!$H$1, $B7 = Temp!$A$16),$D7,0) -> 0 | M7: =IF(AND($C7 = Temp!$I$1, $B7 = Temp!$A$16),$D7,0) -> 0 | N7: =IF(AND($C7 = Temp!$J$1, $B7 = Temp!$A$16),$D7,0) -> 0 | O7: =IF(AND($C7 = Temp!$K$1, $B7 = Temp!$A$16),$D7,0) -> 0
B8: 206370_BYD_ESP9.3_New_Hybrid_MS15.1 | C8: hau.nguyen-tai | D8: 4 | F8: =IF(AND($C8 = Temp!$B$1, $B8 = Temp!$A$16),$D8,0) -> 0 | G8: =IF(AND($C8 = Temp!$C$1, $B8 = Temp!$A$16),$D8,0) -> 0 | H8: =IF(AND($C8 = Temp!$D$1, $B8 = Temp!$A$16),$D8,0) -> 0 | I8: =IF(AND($C8 = Temp!$E$1, $B8 = Temp!$A$16),$D8,0) -> 0 | J8: =IF(AND($C8 = Temp!$F$1, $B8 = Temp!$A$16),$D8,0) -> 0 | K8: =IF(AND($C8 = Temp!$G$1, $B8 = Temp!$A$16),$D8,0) -> 0 | L8: =IF(AND($C8 = Temp!$H$1, $B8 = Temp!$A$16),$D8,0) -> 0 | M8: =IF(AND($C8 = Temp!$I$1, $B8 = Temp!$A$16),$D8,0) -> 0 | N8: =IF(AND($C8 = Temp!$J$1, $B8 = Temp!$A$16),$D8,0) -> 0 | O8: =IF(AND($C8 = Temp!$K$1, $B8 = Temp!$A$16),$D8,0) -> 0
B9: 216916_FAW_E115_L3_ESPhev_APB(CBi) | C9: loc.do-phu | D9: 4 | F9: =IF(AND($C9 = Temp!$B$1, $B9 = Temp!$A$16),$D9,0) -> 0 | G9: =IF(AND($C9 = Temp!$C$1, $B9 = Temp!$A$16),$D9,0) -> 0 | H9: =IF(AND($C9 = Temp!$D$1, $B9 = Temp!$A$16),$D9,0) -> 0 | I9: =IF(AND($C9 = Temp!$E$1, $B9 = Temp!$A$16),$D9,0) -> 0 | J9: =IF(AND($C9 = Temp!$F$1, $B9 = Temp!$A$16),$D9,0) -> 0 | K9: =IF(AND($C9 = Temp!$G$1, $B9 = Temp!$A$16),$D9,0) -> 0 | L9: =IF(AND($C9 = Temp!$H$1, $B9 = Temp!$A$16),$D9,0) -> 0 | M9: =IF(AND($C9 = Temp!$I$1, $B9 = Temp!$A$16),$D9,0) -> 0 | N9: =IF(AND($C9 = Temp!$J$1, $B9 = Temp!$A$16),$D9,0) -> 0 | O9: =IF(AND($C9 = Temp!$K$1, $B9 = Temp!$A$16),$D9,0) -> 0
B10: 217437_FAW_C229 | C10: hau.nguyen-tai | D10: 4 | F10: =IF(AND($C10 = Temp!$B$1, $B10 = Temp!$A$16),$D10,0) -> 0 | G10: =IF(AND($C10 = Temp!$C$1, $B10 = Temp!$A$16),$D10,0) -> 0 | H10: =IF(AND($C10 = Temp!$D$1, $B10 = Temp!$A$16),$D10,0) -> 0 | I10: =IF(AND($C10 = Temp!$E$1, $B10 = Temp!$A$16),$D10,0) -> 0 | J10: =IF(AND($C10 = Temp!$F$1, $B10 = Temp!$A$16),$D10,0) -> 0 | K10: =IF(AND($C10 = Temp!$G$1, $B10 = Temp!$A$16),$D10,0) -> 0 | L10: =IF(AND($C10 = Temp!$H$1, $B10 = Temp!$A$16),$D10,0) -> 0 | M10: =IF(AND($C10 = Temp!$I$1, $B10 = Temp!$A$16),$D10,0) -> 0 | N10: =IF(AND($C10 = Temp!$J$1, $B10 = Temp!$A$16),$D10,0) -> 0 | O10: =IF(AND($C10 = Temp!$K$1, $B10 = Temp!$A$16),$D10,0) -> 0
B11: 217437_FAW_C229 | C11: hau.nguyen-tai | D11: 4 | F11: =IF(AND($C11 = Temp!$B$1, $B11 = Temp!$A$16),$D11,0) -> 0 | G11: =IF(AND($C11 = Temp!$C$1, $B11 = Temp!$A$16),$D11,0) -> 0 | H11: =IF(AND($C11 = Temp!$D$1, $B11 = Temp!$A$16),$D11,0) -> 0 | I11: =IF(AND($C11 = Temp!$E$1, $B11 = Temp!$A$16),$D11,0) -> 0 | J11: =IF(AND($C11 = Temp!$F$1, $B11 = Temp!$A$16),$D11,0) -> 0 | K11: =IF(AND($C11 = Temp!$G$1, $B11 = Temp!$A$16),$D11,0) -> 0 | L11: =IF(AND($C11 = Temp!$H$1, $B11 = Temp!$A$16),$D11,0) -> 0 | M11: =IF(AND($C11 = Temp!$I$1, $B11 = Temp!$A$16),$D11,0) -> 0 | N11: =IF(AND($C11 = Temp!$J$1, $B11 = Temp!$A$16),$D11,0) -> 0 | O11: =IF(AND($C11 = Temp!$K$1, $B11 = Temp!$A$16),$D11,0) -> 0
B12: 218053_CA_CD569_ESP9.3CP | C12: dac.luu-cong | D12: 1 | F12: =IF(AND($C12 = Temp!$B$1, $B12 = Temp!$A$16),$D12,0) -> 0 | G12: =IF(AND($C12 = Temp!$C$1, $B12 = Temp!$A$16),$D12,0) -> 0 | H12: =IF(AND($C12 = Temp!$D$1, $B12 = Temp!$A$16),$D12,0) -> 0 | I12: =IF(AND($C12 = Temp!$E$1, $B12 = Temp!$A$16),$D12,0) -> 0 | J12: =IF(AND($C12 = Temp!$F$1, $B12 = Temp!$A$16),$D12,0) -> 0 | K12: =IF(AND($C12 = Temp!$G$1, $B12 = Temp!$A$16),$D12,0) -> 0 | L12: =IF(AND($C12 = Temp!$H$1, $B12 = Temp!$A$16),$D12,0) -> 0 | M12: =IF(AND($C12 = Temp!$I$1, $B12 = Temp!$A$16),$D12,0) -> 0 | N12: =IF(AND($C12 = Temp!$J$1, $B12 = Temp!$A$16),$D12,0) -> 0 | O12: =IF(AND($C12 = Temp!$K$1, $B12 = Temp!$A$16),$D12,0) -> 0
B13: 224752_GAC_A18_CarbonESP9.3CP | C13: chung.ly | D13: 1 | F13: =IF(AND($C13 = Temp!$B$1, $B13 = Temp!$A$16),$D13,0) -> 0 | G13: =IF(AND($C13 = Temp!$C$1, $B13 = Temp!$A$16),$D13,0) -> 0 | H13: =IF(AND($C13 = Temp!$D$1, $B13 = Temp!$A$16),$D13,0) -> 0 | I13: =IF(AND($C13 = Temp!$E$1, $B13 = Temp!$A$16),$D13,0) -> 0 | J13: =IF(AND($C13 = Temp!$F$1, $B13 = Temp!$A$16),$D13,0) -> 0 | K13: =IF(AND($C13 = Temp!$G$1, $B13 = Temp!$A$16),$D13,0) -> 0 | L13: =IF(AND($C13 = Temp!$H$1, $B13 = Temp!$A$16),$D13,0) -> 0 | M13: =IF(AND($C13 = Temp!$I$1, $B13 = Temp!$A$16),$D13,0) -> 0 | N13: =IF(AND($C13 = Temp!$J$1, $B13 = Temp!$A$16),$D13,0) -> 0 | O13: =IF(AND($C13 = Temp!$K$1, $B13 = Temp!$A$16),$D13,0) -> 0
... B493: XE431RC ABS10.3ME | C493: thanh.nguyen-kim | D493: 2 | F493: =IF(AND($C493 = Temp!$B$1, $B493 = Temp!$A$16),$D493,0) -> 0 | G493: =IF(AND($C493 = Temp!$C$1, $B493 = Temp!$A$16),$D493,0) -> 0 | H493: =IF(AND($C493 = Temp!$D$1, $B493 = Temp!$A$16),$D493,0) -> 0 | I493: =IF(AND($C493 = Temp!$E$1, $B493 = Temp!$A$16),$D493,0) -> 0 | J493: =IF(AND($C493 = Temp!$F$1, $B493 = Temp!$A$16),$D493,0) -> 0 | K493: =IF(AND($C493 = Temp!$G$1, $B493 = Temp!$A$16),$D493,0) -> 0 | L493: =IF(AND($C493 = Temp!$H$1, $B493 = Temp!$A$16),$D493,0) -> 0 | M493: =IF(AND($C493 = Temp!$I$1, $B493 = Temp!$A$16),$D493,0) -> 0 | N493: =IF(AND($C493 = Temp!$J$1, $B493 = Temp!$A$16),$D493,0) -> 0 | O493: =IF(AND($C493 = Temp!$K$1, $B493 = Temp!$A$16),$D493,0) -> 0
B494: XE431RC ABS10.3ME | C494: thanh.nguyen-kim | D494: =0.4 -> 0.4 | F494: =IF(AND($C494 = Temp!$B$1, $B494 = Temp!$A$16),$D494,0) -> 0 | G494: =IF(AND($C494 = Temp!$C$1, $B494 = Temp!$A$16),$D494,0) -> 0 | H494: =IF(AND($C494 = Temp!$D$1, $B494 = Temp!$A$16),$D494,0) -> 0 | I494: =IF(AND($C494 = Temp!$E$1, $B494 = Temp!$A$16),$D494,0) -> 0 | J494: =IF(AND($C494 = Temp!$F$1, $B494 = Temp!$A$16),$D494,0) -> 0 | K494: =IF(AND($C494 = Temp!$G$1, $B494 = Temp!$A$16),$D494,0) -> 0 | L494: =IF(AND($C494 = Temp!$H$1, $B494 = Temp!$A$16),$D494,0) -> 0 | M494: =IF(AND($C494 = Temp!$I$1, $B494 = Temp!$A$16),$D494,0) -> 0 | N494: =IF(AND($C494 = Temp!$J$1, $B494 = Temp!$A$16),$D494,0) -> 0 | O494: =IF(AND($C494 = Temp!$K$1, $B494 = Temp!$A$16),$D494,0) -> 0
B495: XE431RC ABS10.3ME | C495: thanh.nguyen-kim | D495: 2 | F495: =IF(AND($C495 = Temp!$B$1, $B495 = Temp!$A$16),$D495,0) -> 0 | G495: =IF(AND($C495 = Temp!$C$1, $B495 = Temp!$A$16),$D495,0) -> 0 | H495: =IF(AND($C495 = Temp!$D$1, $B495 = Temp!$A$16),$D495,0) -> 0 | I495: =IF(AND($C495 = Temp!$E$1, $B495 = Temp!$A$16),$D495,0) -> 0 | J495: =IF(AND($C495 = Temp!$F$1, $B495 = Temp!$A$16),$D495,0) -> 0 | K495: =IF(AND($C495 = Temp!$G$1, $B495 = Temp!$A$16),$D495,0) -> 0 | L495: =IF(AND($C495 = Temp!$H$1, $B495 = Temp!$A$16),$D495,0) -> 0 | M495: =IF(AND($C495 = Temp!$I$1, $B495 = Temp!$A$16),$D495,0) -> 0 | N495: =IF(AND($C495 = Temp!$J$1, $B495 = Temp!$A$16),$D495,0) -> 0 | O495: =IF(AND($C495 = Temp!$K$1, $B495 = Temp!$A$16),$D495,0) -> 0
B496: XE431RC ABS10.3ME | C496: thanh.nguyen-kim | D496: 1.5 | F496: =IF(AND($C496 = Temp!$B$1, $B496 = Temp!$A$16),$D496,0) -> 0 | G496: =IF(AND($C496 = Temp!$C$1, $B496 = Temp!$A$16),$D496,0) -> 0 | H496: =IF(AND($C496 = Temp!$D$1, $B496 = Temp!$A$16),$D496,0) -> 0 | I496: =IF(AND($C496 = Temp!$E$1, $B496 = Temp!$A$16),$D496,0) -> 0 | J496: =IF(AND($C496 = Temp!$F$1, $B496 = Temp!$A$16),$D496,0) -> 0 | K496: =IF(AND($C496 = Temp!$G$1, $B496 = Temp!$A$16),$D496,0) -> 0 | L496: =IF(AND($C496 = Temp!$H$1, $B496 = Temp!$A$16),$D496,0) -> 0 | M496: =IF(AND($C496 = Temp!$I$1, $B496 = Temp!$A$16),$D496,0) -> 0 | N496: =IF(AND($C496 = Temp!$J$1, $B496 = Temp!$A$16),$D496,0) -> 0 | O496: =IF(AND($C496 = Temp!$K$1, $B496 = Temp!$A$16),$D496,0) -> 0
B497: XE431RC ABS10.3ME | C497: thanh.nguyen-kim | D497: 3 | F497: =IF(AND($C497 = Temp!$B$1, $B497 = Temp!$A$16),$D497,0) -> 0 | G497: =IF(AND($C497 = Temp!$C$1, $B497 = Temp!$A$16),$D497,0) -> 0 | H497: =IF(AND($C497 = Temp!$D$1, $B497 = Temp!$A$16),$D497,0) -> 0 | I497: =IF(AND($C497 = Temp!$E$1, $B497 = Temp!$A$16),$D497,0) -> 0 | J497: =IF(AND($C497 = Temp!$F$1, $B497 = Temp!$A$16),$D497,0) -> 0 | K497: =IF(AND($C497 = Temp!$G$1, $B497 = Temp!$A$16),$D497,0) -> 0 | L497: =IF(AND($C497 = Temp!$H$1, $B497 = Temp!$A$16),$D497,0) -> 0 | M497: =IF(AND($C497 = Temp!$I$1, $B497 = Temp!$A$16),$D497,0) -> 0 | N497: =IF(AND($C497 = Temp!$J$1, $B497 = Temp!$A$16),$D497,0) -> 0 | O497: =IF(AND($C497 = Temp!$K$1, $B497 = Temp!$A$16),$D497,0) -> 0
B498: XE431RC ABS10.3ME | C498: thanh.nguyen-kim | D498: 0.5 | F498: =IF(AND($C498 = Temp!$B$1, $B498 = Temp!$A$16),$D498,0) -> 0 | G498: =IF(AND($C498 = Temp!$C$1, $B498 = Temp!$A$16),$D498,0) -> 0 | H498: =IF(AND($C498 = Temp!$D$1, $B498 = Temp!$A$16),$D498,0) -> 0 | I498: =IF(AND($C498 = Temp!$E$1, $B498 = Temp!$A$16),$D498,0) -> 0 | J498: =IF(AND($C498 = Temp!$F$1, $B498 = Temp!$A$16),$D498,0) -> 0 | K498: =IF(AND($C498 = Temp!$G$1, $B498 = Temp!$A$16),$D498,0) -> 0 | L498: =IF(AND($C498 = Temp!$H$1, $B498 = Temp!$A$16),$D498,0) -> 0 | M498: =IF(AND($C498 = Temp!$I$1, $B498 = Temp!$A$16),$D498,0) -> 0 | N498: =IF(AND($C498 = Temp!$J$1, $B498 = Temp!$A$16),$D498,0) -> 0 | O498: =IF(AND($C498 = Temp!$K$1, $B498 = Temp!$A$16),$D498,0) -> 0
B499: XE431RC ABS10.3ME | C499: duong.nguyen | D499: 1.8 | F499: =IF(AND($C499 = Temp!$B$1, $B499 = Temp!$A$16),$D499,0) -> 0 | G499: =IF(AND($C499 = Temp!$C$1, $B499 = Temp!$A$16),$D499,0) -> 0 | H499: =IF(AND($C499 = Temp!$D$1, $B499 = Temp!$A$16),$D499,0) -> 0 | I499: =IF(AND($C499 = Temp!$E$1, $B499 = Temp!$A$16),$D499,0) -> 0 | J499: =IF(AND($C499 = Temp!$F$1, $B499 = Temp!$A$16),$D499,0) -> 0 | K499: =IF(AND($C499 = Temp!$G$1, $B499 = Temp!$A$16),$D499,0) -> 0 | L499: =IF(AND($C499 = Temp!$H$1, $B499 = Temp!$A$16),$D499,0) -> 0 | M499: =IF(AND($C499 = Temp!$I$1, $B499 = Temp!$A$16),$D499,0) -> 0 | N499: =IF(AND($C499 = Temp!$J$1, $B499 = Temp!$A$16),$D499,0) -> 0 | O499: =IF(AND($C499 = Temp!$K$1, $B499 = Temp!$A$16),$D499,0) -> 0
B500: XE431RC ABS10.3ME | C500: duong.nguyen | D500: 2 | F500: =IF(AND($C500 = Temp!$B$1, $B500 = Temp!$A$16),$D500,0) -> 0 | G500: =IF(AND($C500 = Temp!$C$1, $B500 = Temp!$A$16),$D500,0) -> 0 | H500: =IF(AND($C500 = Temp!$D$1, $B500 = Temp!$A$16),$D500,0) -> 0 | I500: =IF(AND($C500 = Temp!$E$1, $B500 = Temp!$A$16),$D500,0) -> 0 | J500: =IF(AND($C500 = Temp!$F$1, $B500 = Temp!$A$16),$D500,0) -> 0 | K500: =IF(AND($C500 = Temp!$G$1, $B500 = Temp!$A$16),$D500,0) -> 0 | L500: =IF(AND($C500 = Temp!$H$1, $B500 = Temp!$A$16),$D500,0) -> 0 | M500: =IF(AND($C500 = Temp!$I$1, $B500 = Temp!$A$16),$D500,0) -> 0 | N500: =IF(AND($C500 = Temp!$J$1, $B500 = Temp!$A$16),$D500,0) -> 0 | O500: =IF(AND($C500 = Temp!$K$1, $B500 = Temp!$A$16),$D500,0) -> 0
B501: XE431RC ABS10.3ME | C501: duong.nguyen | D501: 3 | F501: =IF(AND($C501 = Temp!$B$1, $B501 = Temp!$A$16),$D501,0) -> 0 | G501: =IF(AND($C501 = Temp!$C$1, $B501 = Temp!$A$16),$D501,0) -> 0 | H501: =IF(AND($C501 = Temp!$D$1, $B501 = Temp!$A$16),$D501,0) -> 0 | I501: =IF(AND($C501 = Temp!$E$1, $B501 = Temp!$A$16),$D501,0) -> 0 | J501: =IF(AND($C501 = Temp!$F$1, $B501 = Temp!$A$16),$D501,0) -> 0 | K501: =IF(AND($C501 = Temp!$G$1, $B501 = Temp!$A$16),$D501,0) -> 0 | L501: =IF(AND($C501 = Temp!$H$1, $B501 = Temp!$A$16),$D501,0) -> 0 | M501: =IF(AND($C501 = Temp!$I$1, $B501 = Temp!$A$16),$D501,0) -> 0 | N501: =IF(AND($C501 = Temp!$J$1, $B501 = Temp!$A$16),$D501,0) -> 0 | O501: =IF(AND($C501 = Temp!$K$1, $B501 = Temp!$A$16),$D501,0) -> 0
B502: XE431RC ABS10.3ME | C502: loc.do-phu | D502: 2 | F502: =IF(AND($C502 = Temp!$B$1, $B502 = Temp!$A$16),$D502,0) -> 0 | G502: =IF(AND($C502 = Temp!$C$1, $B502 = Temp!$A$16),$D502,0) -> 0 | H502: =IF(AND($C502 = Temp!$D$1, $B502 = Temp!$A$16),$D502,0) -> 0 | I502: =IF(AND($C502 = Temp!$E$1, $B502 = Temp!$A$16),$D502,0) -> 0 | J502: =IF(AND($C502 = Temp!$F$1, $B502 = Temp!$A$16),$D502,0) -> 0 | K502: =IF(AND($C502 = Temp!$G$1, $B502 = Temp!$A$16),$D502,0) -> 0 | L502: =IF(AND($C502 = Temp!$H$1, $B502 = Temp!$A$16),$D502,0) -> 0 | M502: =IF(AND($C502 = Temp!$I$1, $B502 = Temp!$A$16),$D502,0) -> 0 | N502: =IF(AND($C502 = Temp!$J$1, $B502 = Temp!$A$16),$D502,0) -> 0 | O502: =IF(AND($C502 = Temp!$K$1, $B502 = Temp!$A$16),$D502,0) -> 0
B503: XE431RC ABS10.3ME | C503: loc.do-phu | D503: 4 | F503: =IF(AND($C503 = Temp!$B$1, $B503 = Temp!$A$16),$D503,0) -> 0 | G503: =IF(AND($C503 = Temp!$C$1, $B503 = Temp!$A$16),$D503,0) -> 0 | H503: =IF(AND($C503 = Temp!$D$1, $B503 = Temp!$A$16),$D503,0) -> 0 | I503: =IF(AND($C503 = Temp!$E$1, $B503 = Temp!$A$16),$D503,0) -> 0 | J503: =IF(AND($C503 = Temp!$F$1, $B503 = Temp!$A$16),$D503,0) -> 0 | K503: =IF(AND($C503 = Temp!$G$1, $B503 = Temp!$A$16),$D503,0) -> 0 | L503: =IF(AND($C503 = Temp!$H$1, $B503 = Temp!$A$16),$D503,0) -> 0 | M503: =IF(AND($C503 = Temp!$I$1, $B503 = Temp!$A$16),$D503,0) -> 0 | N503: =IF(AND($C503 = Temp!$J$1, $B503 = Temp!$A$16),$D503,0) -> 0 | O503: =IF(AND($C503 = Temp!$K$1, $B503 = Temp!$A$16),$D503,0) -> 0
B504: XE431RC ABS10.3ME | C504: loc.do-phu | D504: 2 | F504: =IF(AND($C504 = Temp!$B$1, $B504 = Temp!$A$16),$D504,0) -> 0 | G504: =IF(AND($C504 = Temp!$C$1, $B504 = Temp!$A$16),$D504,0) -> 0 | H504: =IF(AND($C504 = Temp!$D$1, $B504 = Temp!$A$16),$D504,0) -> 0 | I504: =IF(AND($C504 = Temp!$E$1, $B504 = Temp!$A$16),$D504,0) -> 0 | J504: =IF(AND($C504 = Temp!$F$1, $B504 = Temp!$A$16),$D504,0) -> 0 | K504: =IF(AND($C504 = Temp!$G$1, $B504 = Temp!$A$16),$D504,0) -> 0 | L504: =IF(AND($C504 = Temp!$H$1, $B504 = Temp!$A$16),$D504,0) -> 0 | M504: =IF(AND($C504 = Temp!$I$1, $B504 = Temp!$A$16),$D504,0) -> 0 | N504: =IF(AND($C504 = Temp!$J$1, $B504 = Temp!$A$16),$D504,0) -> 0 | O504: =IF(AND($C504 = Temp!$K$1, $B504 = Temp!$A$16),$D504,0) -> 0
B505: XE431RC ABS10.3ME | C505: chung.ly | D505: 1 | F505: =IF(AND($C505 = Temp!$B$1, $B505 = Temp!$A$16),$D505,0) -> 0 | G505: =IF(AND($C505 = Temp!$C$1, $B505 = Temp!$A$16),$D505,0) -> 0 | H505: =IF(AND($C505 = Temp!$D$1, $B505 = Temp!$A$16),$D505,0) -> 0 | I505: =IF(AND($C505 = Temp!$E$1, $B505 = Temp!$A$16),$D505,0) -> 0 | J505: =IF(AND($C505 = Temp!$F$1, $B505 = Temp!$A$16),$D505,0) -> 0 | K505: =IF(AND($C505 = Temp!$G$1, $B505 = Temp!$A$16),$D505,0) -> 0 | L505: =IF(AND($C505 = Temp!$H$1, $B505 = Temp!$A$16),$D505,0) -> 0 | M505: =IF(AND($C505 = Temp!$I$1, $B505 = Temp!$A$16),$D505,0) -> 0 | N505: =IF(AND($C505 = Temp!$J$1, $B505 = Temp!$A$16),$D505,0) -> 0 | O505: =IF(AND($C505 = Temp!$K$1, $B505 = Temp!$A$16),$D505,0) -> 0
B506: XE431RC ABS10.3ME | C506: loc.do-phu | D506: 1 | F506: =IF(AND($C506 = Temp!$B$1, $B506 = Temp!$A$16),$D506,0) -> 0 | G506: =IF(AND($C506 = Temp!$C$1, $B506 = Temp!$A$16),$D506,0) -> 0 | H506: =IF(AND($C506 = Temp!$D$1, $B506 = Temp!$A$16),$D506,0) -> 0 | I506: =IF(AND($C506 = Temp!$E$1, $B506 = Temp!$A$16),$D506,0) -> 0 | J506: =IF(AND($C506 = Temp!$F$1, $B506 = Temp!$A$16),$D506,0) -> 0 | K506: =IF(AND($C506 = Temp!$G$1, $B506 = Temp!$A$16),$D506,0) -> 0 | L506: =IF(AND($C506 = Temp!$H$1, $B506 = Temp!$A$16),$D506,0) -> 0 | M506: =IF(AND($C506 = Temp!$I$1, $B506 = Temp!$A$16),$D506,0) -> 0 | N506: =IF(AND($C506 = Temp!$J$1, $B506 = Temp!$A$16),$D506,0) -> 0 | O506: =IF(AND($C506 = Temp!$K$1, $B506 = Temp!$A$16),$D506,0) -> 0
... B516: XE431RC ABS10.3ME | C516: loc.do-phu | D516: 1 | F516: =IF(AND($C516 = Temp!$B$1, $B516 = Temp!$A$16),$D516,0) -> 0 | G516: =IF(AND($C516 = Temp!$C$1, $B516 = Temp!$A$16),$D516,0) -> 0 | H516: =IF(AND($C516 = Temp!$D$1, $B516 = Temp!$A$16),$D516,0) -> 0 | I516: =IF(AND($C516 = Temp!$E$1, $B516 = Temp!$A$16),$D516,0) -> 0 | J516: =IF(AND($C516 = Temp!$F$1, $B516 = Temp!$A$16),$D516,0) -> 0 | K516: =IF(AND($C516 = Temp!$G$1, $B516 = Temp!$A$16),$D516,0) -> 0 | L516: =IF(AND($C516 = Temp!$H$1, $B516 = Temp!$A$16),$D516,0) -> 0 | M516: =IF(AND($C516 = Temp!$I$1, $B516 = Temp!$A$16),$D516,0) -> 0 | N516: =IF(AND($C516 = Temp!$J$1, $B516 = Temp!$A$16),$D516,0) -> 0 | O516: =IF(AND($C516 = Temp!$K$1, $B516 = Temp!$A$16),$D516,0) -> 0
C520: =IF(AND($C2 = Temp!$B$1, $B2 = Temp!$A$16),$D2,0) -> 0
C521: =IF(AND($C2 = Temp!$C$1, $B2 = Temp!$A$16),$D2,0) -> 0
C522: =IF(AND($C2 = Temp!$D$1, $B2 = Temp!$A$16),$D2,0) -> 0
C523: =IF(AND($C2 = Temp!$E$1, $B2 = Temp!$A$16),$D2,0) -> 0 | F523: =SUM(F2:F516) -> 0 | G523: =SUM(G2:G516) -> 0 | H523: =SUM(H2:H516) -> 0 | I523: =SUM(I2:I516) -> 1 | J523: =SUM(J2:J516) -> 0 | K523: =SUM(K2:K516) -> 0 | L523: =SUM(L2:L516) -> 0 | M523: =SUM(M2:M516) -> 0.2 | ... O523: =SUM(O2:O516) -> 0
C524: =IF(AND($C2 = Temp!$F$1, $B2 = Temp!$A$16),$D2,0) -> 0
C525: =IF(AND($C2 = Temp!$G$1, $B2 = Temp!$A$16),$D2,0) -> 0
C526: =IF(AND($C2 = Temp!$H$1, $B2 = Temp!$A$16),$D2,0) -> 0
C527: =IF(AND($C2 = Temp!$I$1, $B2 = Temp!$A$16),$D2,0) -> 0
C528: =IF(AND($C2 = Temp!$J$1, $B2 = Temp!$A$16),$D2,0) -> 0
C529: =IF(AND($C2 = Temp!$K$1, $B2 = Temp!$A$16),$D2,0) -> 0

Sheet Sheet4
A1: Project / Tester | B1: huy.do-anh | C1: hau.nguyen-tai | D1: bang.nguyen-duy | E1: loc.do-phu | F1: dac.luu-cong | G1: chung.ly | H1: phuong.nguyen-thanh | I1: duong.nguyen | J1: hieu.nguyen-trung | K1: thanh.nguyen-kim
A2: 206370_BYD_ESP9.3_New_Hybrid_MS15.1 | B2: 0 | C2: 0 | D2: 0 | E2: 0 | F2: 0 | G2: 0 | H2: 0 | I2: 0 | J2: 0 | K2: 0
A3: 216916_FAW_E115_L3_ESPhev_APB(CBi) | B3: 0 | C3: 0 | D3: 0 | E3: 0 | F3: 0 | G3: 0 | H3: 0 | I3: 0 | J3: 0 | K3: 0
A4: 217437_FAW_C229 | B4: 0 | C4: 0 | D4: 0 | E4: 0 | F4: 0 | G4: 0 | H4: 0 | I4: 0 | J4: 0 | K4: 0
A5: 218053_CA_CD569_ESP9.3CP | B5: 0 | C5: 0 | D5: 0 | E5: 0 | F5: 0 | G5: 0 | H5: 0 | I5: 0 | J5: 0 | K5: 0
A6: 224752_GAC_A18_CarbonESP9.3CP | B6: 0 | C6: 0 | D6: 0 | E6: 0 | F6: 0 | G6: 0 | H6: 0 | I6: 0 | J6: 0 | K6: 0
A7: 228771_SAIC EP22 X1 & IP31E w/o_DA ESPHevX BSS04_SP01 | B7: 0 | C7: 0 | D7: 0 | E7: 0 | F7: 0 | G7: 0 | H7: 0 | I7: 0 | J7: 0 | K7: 0
A8: 231839_DearCC_IC321_ESP9.3 | B8: 0 | C8: 0 | D8: 0 | E8: 0 | F8: 0 | G8: 0 | H8: 0 | I8: 0 | J8: 0 | K8: 0
A9: 233324_JAC_P843_ESP9.3 | B9: 0 | C9: 0 | D9: 0 | E9: 0 | F9: 0 | G9: 0 | H9: 0 | I9: 0 | J9: 0 | K9: 0
A10: 235149_FAW_HS7_RC | B10: 0 | C10: 0 | D10: 0 | E10: 0 | F10: 0 | G10: 0 | H10: 0 | I10: 0 | J10: 0 | K10: 0
A11: 241595_GAC_A27_ESP9.3CP | B11: 0 | C11: 0 | D11: 0 | E11: 0 | F11: 0 | G11: 0 | H11: 0 | I11: 0 | J11: 0 | K11: 0
A12: 242899_GAC_A39_ESP9.3CPHD_RC4 | B12: 0 | C12: 0 | D12: 0 | E12: 0 | F12: 0 | G12: 0 | H12: 0 | I12: 0 | J12: 0 | K12: 0
A13: AB30IB2 | B13: 0 | C13: 0 | D13: 0 | E13: 0 | F13: 0 | G13: 0 | H13: 0 | I13: 0 | J13: 0 | K13: 0
... A63: XE431RC ABS10.3ME | B63: 0 | C63: 0 | D63: 0 | E63: 0 | F63: 0 | G63: 0 | H63: 0 | I63: 0 | J63: 0 | K63: 0

Sheet Temp
A1: Project / Tester | B1: huy.do-anh | C1: hau.nguyen-tai | D1: bang.nguyen-duy | E1: loc.do-phu | F1: dac.luu-cong | G1: chung.ly | H1: phuong.nguyen-thanh | I1: duong.nguyen | J1: hieu.nguyen-trung | K1: thanh.nguyen-kim
A2: 206370_BYD_ESP9.3_New_Hybrid_MS15.1 | B2: 0.5 | C2: 11 | D2: 2 | E2: 0 | F2: 0 | G2: 0 | H2: 0 | I2: 0 | J2: 0 | K2: 0
A3: 216916_FAW_E115_L3_ESPhev_APB(CBi) | B3: 0 | C3: 0 | D3: 0 | E3: 4 | F3: 0 | G3: 0 | H3: 0 | I3: 0 | J3: 0 | K3: 0
A4: 217437_FAW_C229 | B4: 0 | C4: 8 | D4: 0 | E4: 0 | F4: 0 | G4: 0 | H4: 0 | I4: 0 | J4: 0 | K4: 0
A5: 218053_CA_CD569_ESP9.3CP | B5: 0 | C5: 0 | D5: 0 | E5: 0 | F5: 1 | G5: 0 | H5: 0 | I5: 0 | J5: 0 | K5: 0
A6: 224752_GAC_A18_CarbonESP9.3CP | B6: 0 | C6: 0 | D6: 0 | E6: 0 | F6: 0 | G6: 1 | H6: 0 | I6: 0 | J6: 0 | K6: 0
A7: 228771_SAIC EP22 X1 & IP31E w/o_DA ESPHevX BSS04_SP01 | B7: 0 | C7: 0 | D7: 0 | E7: 0 | F7: 0 | G7: 0 | H7: 1.25 | I7: 0 | J7: 0 | K7: 0
A8: 231839_DearCC_IC321_ESP9.3 | B8: 0 | C8: 0 | D8: 2 | E8: 0 | F8: 0 | G8: 0 | H8: 0 | I8: 0 | J8: 0 | K8: 0
A9: 233324_JAC_P843_ESP9.3 | B9: 0 | C9: 0 | D9: 0 | E9: 0 | F9: 5 | G9: 0 | H9: 8.12 | I9: 0 | J9: 0 | K9: 0
A10: 235149_FAW_HS7_RC | B10: 0 | C10: 0 | D10: 0 | E10: 4.5 | F10: 0 | G10: 0 | H10: 0 | I10: 2 | J10: 0 | K10: 0
A11: 241595_GAC_A27_ESP9.3CP | B11: 0 | C11: 0 | D11: 0 | E11: 0 | F11: 0 | G11: 2.5 | H11: 0 | I11: 0 | J11: 0 | K11: 0
A12: 242899_GAC_A39_ESP9.3CPHD_RC4 | B12: 0 | C12: 0 | D12: 0 | E12: 3.5 | F12: 0 | G12: 0 | H12: 0 | I12: 0 | J12: 0 | K12: 0
A13: AB30IB2 | B13: 15 | C13: 0 | D13: 0 | E13: 0 | F13: 0 | G13: 0 | H13: 0 | I13: 0.5 | J13: 0 | K13: 0
... A63: XE431RC ABS10.3ME | B63: 0 | C63: 0 | D63: 0 | E63: 0 | F63: 0 | G63: 0 | H63: 0 | I63: 0 | J63: 0 | K63: 0

Sheet Sheet2
A2: 0
A3: 0
A4: 0 | B4: Project | C4: TaskID | D4: ItemName | E4: Baseline | F4: Database | G4: ItemRevision | H4: Owner Contact | I4: Task Jira | J4: TaskGroup | K4: Tester | L4: PeerReviewer | M4: Status Review | N4: ELOC Assigned | O4: ELOC Recheck With Tool | P4: LOC Complete | Q4: Estimation base TOOL | R4: Actual hour
A5: 0 | B5: GWM_B30_CP | C5: 1415974 | D5: PbcWrapper.c | E5: BSSL07 | F5: hieu.nguyen-trung | G5: 2
A6: 0 | B6: GWM_B30_CP | C6: 1415974 | D6: DcmAppl_DcmCommControlConditionCheck.c | E6: BSSL07 | F6: hieu.nguyen-trung | G6: 0.5
A7: 0 | B7: GWM_B30_CP | C7: 1415974 | D7: DcmAppl_DcmNotification.c | E7: BSSL07 | F7: hieu.nguyen-trung | G7: 0.5
A8: 0 | B8: GWM_B30_CP | C8: 1415974 | D8: RBAPLCUST_CNMSCORE_CallbackFun.c | E8: BSSL07 | F8: hieu.nguyen-trung | G8: 1
A9: 0 | B9: GWM_B30_CP | C9: 1415974 | D9: RBAPLCUST_InputOutputControl_GeneralFunctions.c | E9: BSSL07 | F9: hieu.nguyen-trung | G9: 1
A10: 0 | B10: GWM_B30_CP | C10: 1415974 | D10: RBAPLCUST_ProjectSpecific_Routines.c | E10: BSSL07 | F10: hieu.nguyen-trung | G10: 1
A11: 0 | B11: GWM_B30_CP | C11: 1415974 | D11: RBAPLCUST_RDBI_StatusInformation.c | E11: BSSL07 | F11: hieu.nguyen-trung | G11: 1
B12: GWM_B30_CP | C12: 1415974 | D12: RBAPLCUST_RDBI_SystemSensor.c | E12: BSSL07 | F12: hieu.nguyen-trung | G12: 1
B13: GWM_B30_CP | C13: 1415974 | D13: RBAPLCUST_RoutineControl.c | E13: BSSL07 | F13: hieu.nguyen-trung | G13: 1
B14: GWM_B30_CP | C14: 1415974 | D14: RBAPLCUST_RoutineControl_ActuatorTest.c | E14: BSSL07 | F14: hieu.nguyen-trung | G14: 1
B15: GWM_B30_CP | C15: 1415974 | D15: RBAPLCUST_RoutineControl_DynamicTest.c | E15: BSSL07 | F15: hau.nguyen-tai | G15: 2
B16: GWM_B30_CP | C16: 1415974 | D16: RBAPLCUST_RoutineControl_EvacAndFill.c | E16: BSSL07 | F16: hau.nguyen-tai | G16: 2
B17: GWM_B30_CP | C17: 1415974 | D17: RBAPLCUST_RoutineControl_RepairBleeding.c | E17: BSSL07 | F17: hau.nguyen-tai | G17: 2
B18: GWM_B30_CP | C18: 1415974 | D18: RBAPLCUST_RoutineControl_WheelSpeedSensorTest.c | E18: BSSL07 | F18: hau.nguyen-tai | G18: 2
B19: GWM_B30_CP | C19: 1415974 | D19: RBAPLCUST_ValvesToggling.c | E19: BSSL07 | F19: hau.nguyen-tai | G19: 1
B20: GWM_B30_CP | C20: 1415974 | D20: ApbHostData_Project.c | E20: BSSL07 | F20: hau.nguyen-tai | G20: 1
B21: GWM_B30_CP | C21: 1415974 | D21: Dem_PrjSpecificIndiHandling.c | E21: BSSL07 | F21: hau.nguyen-tai | G21: 1
B22: GWM_B30_CP | C22: 1415974 | D22: Obd_CalId.c | E22: BSSL07 | F22: hau.nguyen-tai | G22: 0
B23: GWM_B30_CP | C23: 1415974 | D23: CNMS_Var_DcmRead.c | E23: BSSL07 | F23: dac.luu-cong | G23: 1
... B169: BYD_IPB_SW_Mainstream_BL05_Defect | C169: 1405296 | D169: RBA_NDS_Complex_Callout.c | E169: BL05 | F169: bang.nguyen-duy | G169: 5
B170: BYD_IPB_SW_Mainstream_BL05_Defect | C170: 1405296 | D170: NET_SCL_Rx_VAF_Complex.c | E170: BL05 | F170: dac.luu-cong
B171: BYD_IPB_SW_Mainstream_BL05_SP11 | C171: 1417022 | D171: rba_SCL_Settings.c | E171: BL05_SP11 | F171: dac.luu-cong | G171: 1
B172: BYD_IPB_SW_Mainstream_BL05_SP11 | C172: 1417022 | D172: NET_SCL_Tx_VAF_Complex.c | E172: BL05_SP11 | F172: dac.luu-cong | G172: 1
B173: BYD_IPB_SW_Mainstream_BL05_SP11 | C173: 1417022 | D173: NET_SCL_Rx_VAF_Complex.c | E173: BL05_SP11 | F173: dac.luu-cong | G173: 2
B174: BYD_IPB_SW_Mainstream_BL05_SP11 | C174: 1417022 | D174: RBPduHandler_Callouts.c | E174: BL05_SP11 | F174: dac.luu-cong | G174: 2
B175: BYD_Carbon_Mainstream_BL02spr04 | C175: 1414681 | D175: RBNetSAS_Rx_Lws_Standard.c | E175: BL02spr04 | F175: dac.luu-cong | G175: 1
B176: GAC_220680_Carbon_A18_ESPHevx_FPA/RPA_BL04_TestExecution | C176: 1416204 | D176: RBAPLCUST_RoutineControl_SteeringAngleSensorCalibration.c | E176: BL04 | F176: dac.luu-cong | G176: 1
B177: GAC_220680_Carbon_A18_ESPHevx_FPA/RPA_BL04_TestExecution | C177: 1416204 | D177: RBAPLCUST_RoutineControl_INSCalibration.c | E177: BL04 | F177: dac.luu-cong | G177: 1
B178: KX63_FL_ACC_232961_BSS03 | C178: 1417780 | D178: RBDHP_HighSystemPressureProtection.c | E178: BSS03 | F178: dac.luu-cong | G178: 1
B179: KX63_FL_ACC_232961_BSS03 | C179: 1417780 | D179: RBDHP_PumpMotorActuationTimeLimitation.c | E179: BSS03 | F179: dac.luu-cong | G179: 1
B180: KX63_FL_ACC_232961_BSS03 | C180: 1417780 | D180: RBDHP_StateMachine.c | E180: BSS03 | F180: dac.luu-cong | G180: 1
B181: KX63_FL_ACC_232961_BSS03 | C181: 1417780 | D181: RBDHP_ValveActuationTimeLimitation.c | E181: BSS03 | F181: dac.luu-cong | G181: 1
B182: KX63_FL_ACC_232961_BSS03 | C182: 1417780 | D182: Dem_VarCode_PRJ.c | E182: BSS03 | F182: dac.luu-cong | G182: 0.1
... B229: FAW_E111_ESPhev | C229: 1427716 | D229: RBHMI_LDMLamp_FAW.C | E229: BSL31 | F229: loc.do-phu | G229: 0.5
B230: 241595_GAC_A27_ESP9.3CP | C230: 1405783 | D230: NET_SCL_Rx_RBC.c | F230: chung.ly | G230: 2.5
B231: 235149_FAW_HS7_RC_BL02 | C231: 1405633 | D231: RBAPLCUST_SecurityAccess.c | F231: loc.do-phu | G231: 4.5
B232: 235149_FAW_HS7_RC_BL02 | C232: 1405633 | D232: RBAPLCUST_WDBI_NVMData.c | F232: duong.nguyen | G232: 2
...

Sheet |-->

Sheet Total
B2: No | C2: Package | D2: Type | E2: Project | F2: ComponentName | G2: TaskID | H2: MT_Number | I2: ItemName | J2: MT_Needed | K2: Type of Comment | L2: BB | M2: Baseline | N2: Database | O2: ItemRevision | P2: Owner Contact | Q2: Task Jira | R2: TaskGroup | S2: Tester | T2: PeerReviewer | U2: Status Review | V2: ELOC Assigned | W2: ELOC Recheck With Tool | X2: LOC Complete | Y2: Estimation base TOOL | Z2: Actual hour | AA2: Status | AB2: Release Date | AC2: Planned Start | AD2: Planned End | AE2: Start | AF2: End | AG2: Status Result | AH2: C0 | AI2: C1 | AJ2: MCDC | AK2: OPL/Defect | AL2: Reason For code coverage | AM2: Reason for Fail Testcase | AN2: Remark
B3: 70 | C3: 20200414 | D3: PSW | E3: GWM_B30_CP | F3: rb\as\core\app\asw\apbmi\host\PBC\SRC | G3: 1415974 | H3: - | I3: PbcWrapper.c | J3: - | K3: Auto | L3: 80433 | M3: BSSL07 | N3: GWM_AB30_CP_Int | O3: - | P3: ZHANG Wenjia (CC-AS/EVA-SW33-CN) | R3: - | S3: hieu.nguyen-trung | V3: 62 | W3: 62 | X3: 62 | Y3: 1.1 | Z3: 2 | AA3: Complete & Closed | AB3: 43938 | AC3: 43935 | AD3: 43938 | AE3: 43935 | AF3: 43935 | AG3: OK | AH3: 1 | AI3: 1 | AJ3: 1 | AK3: None
B4: 71 | C4: 20200414 | D4: PSW | E4: GWM_B30_CP | F4: rb\as\gwm\core\app\dcom\Cubas\src\Dcm_CNMS | G4: 1415974 | H4: - | I4: DcmAppl_DcmCommControlConditionCheck.c | J4: - | K4: Auto | L4: 80433 | M4: BSSL07 | N4: GWM_AB30_CP_Int | O4: - | P4: ZHANG Wenjia (CC-AS/EVA-SW33-CN) | R4: - | S4: hieu.nguyen-trung | V4: 22 | W4: 22 | X4: 22 | Y4: 0.39 | Z4: 0.5 | AA4: Complete & Closed | AB4: 43938 | AC4: 43935 | AD4: 43938 | AE4: 43936 | AF4: 43936 | AG4: OK | AH4: 1 | AI4: 1 | AJ4: 1 | AK4: None
B5: 72 | C5: 20200414 | D5: PSW | E5: GWM_B30_CP | F5: rb\as\gwm\core\app\dcom\Cubas\src\Dcm | G5: 1415974 | H5: - | I5: DcmAppl_DcmNotification.c | J5: - | K5: Auto | L5: 80433 | M5: BSSL07 | N5: GWM_AB30_CP_Int | O5: - | P5: ZHANG Wenjia (CC-AS/EVA-SW33-CN) | R5: - | S5: hieu.nguyen-trung | V5: 26 | W5: 26 | X5: 26 | Y5: 0.46 | Z5: 0.5 | AA5: Complete & Closed | AB5: 43938 | AC5: 43935 | AD5: 43938 | AE5: 43936 | AF5: 43936 | AG5: OK | AH5: 1 | AI5: 1 | AJ5: 1 | AK5: None
B6: 73 | C6: 20200414 | D6: PSW | E6: GWM_B30_CP | F6: rb\as\gwm\core\app\dcom\RBAPLCust\src\common | G6: 1415974 | H6: - | I6: RBAPLCUST_CNMSCORE_CallbackFun.c | J6: - | K6: Auto | L6: 80433 | M6: BSSL07 | N6: GWM_AB30_CP_Int | O6: - | P6: ZHANG Wenjia (CC-AS/EVA-SW33-CN) | R6: - | S6: hieu.nguyen-trung | V6: 35 | W6: 35 | X6: 35 | Y6: 0.62 | Z6: 1 | AA6: Complete & Closed | AB6: 43938 | AC6: 43935 | AD6: 43938 | AE6: 43936 | AF6: 43936 | AG6: OK | AH6: 1 | AI6: 1 | AJ6: 1 | AK6: None
B7: 74 | C7: 20200414 | D7: PSW | E7: GWM_B30_CP | F7: rb\as\gwm\core\app\dcom\RBAPLCust\src\ESP | G7: 1415974 | H7: - | I7: RBAPLCUST_InputOutputControl_GeneralFunctions.c | J7: - | K7: Auto | L7: 80433 | M7: BSSL07 | N7: GWM_AB30_CP_Int | O7: - | P7: ZHANG Wenjia (CC-AS/EVA-SW33-CN) | R7: - | S7: hieu.nguyen-trung | V7: 101 | W7: 101 | X7: 101 | Y7: 1.79 | Z7: 1 | AA7: Complete & Closed | AB7: 43938 | AC7: 43935 | AD7: 43938 | AE7: 43936 | AF7: 43936 | AG7: OK | AH7: 1 | AI7: 1 | AJ7: 1 | AK7: None
B8: 75 | C8: 20200414 | D8: PSW | E8: GWM_B30_CP | F8: rb\as\gwm\core\app\dcom\RBAPLCust\src\common | G8: 1415974 | H8: - | I8: RBAPLCUST_ProjectSpecific_Routines.c | J8: - | K8: Auto | L8: 80433 | M8: BSSL07 | N8: GWM_AB30_CP_Int | O8: - | P8: ZHANG Wenjia (CC-AS/EVA-SW33-CN) | R8: - | S8: hieu.nguyen-trung | V8: 67 | W8: 67 | X8: 67 | Y8: 1.19 | Z8: 1 | AA8: Complete & Closed | AB8: 43938 | AC8: 43935 | AD8: 43938 | AE8: 43936 | AF8: 43936 | AG8: OK | AH8: 1 | AI8: 1 | AJ8: 1 | AK8: None
B9: 76 | C9: 20200414 | D9: PSW | E9: GWM_B30_CP | F9: rb\as\gwm\core\app\dcom\RBAPLCust\src\iBooster | G9: 1415974 | H9: - | I9: RBAPLCUST_RDBI_StatusInformation.c | J9: - | K9: Auto | L9: 80433 | M9: BSSL07 | N9: GWM_AB30_CP_Int | O9: - | P9: ZHANG Wenjia (CC-AS/EVA-SW33-CN) | R9: - | S9: hieu.nguyen-trung | V9: 137 | W9: 137 | X9: 137 | Y9: 2.43 | Z9: 1 | AA9: Complete & Closed | AB9: 43938 | AC9: 43935 | AD9: 43938 | AE9: 43936 | AF9: 43936 | AG9: OK | AH9: 1 | AI9: 1 | AJ9: 1 | AK9: None
B10: 77 | C10: 20200414 | D10: PSW | E10: GWM_B30_CP | F10: rb\as\gwm\core\app\dcom\RBAPLCust\src\ESP | G10: 1415974 | H10: - | I10: RBAPLCUST_RDBI_SystemSensor.c | J10: - | K10: Auto | L10: 80433 | M10: BSSL07 | N10: GWM_AB30_CP_Int | O10: - | P10: ZHANG Wenjia (CC-AS/EVA-SW33-CN) | R10: - | S10: hieu.nguyen-trung | V10: 160 | W10: 160 | X10: 160 | Y10: 2.84 | Z10: 1 | AA10: Complete & Closed | AB10: 43938 | AC10: 43935 | AD10: 43938 | AE10: 43936 | AF10: 43936 | AG10: OK | AH10: 1 | AI10: 1 | AJ10: 1 | AK10: None
B11: 78 | C11: 20200414 | D11: PSW | E11: GWM_B30_CP | F11: rb\as\gwm\core\app\dcom\RBAPLCust\src\common | G11: 1415974 | H11: - | I11: RBAPLCUST_RoutineControl.c | J11: - | K11: Auto | L11: 80433 | M11: BSSL07 | N11: GWM_AB30_CP_Int | O11: - | P11: ZHANG Wenjia (CC-AS/EVA-SW33-CN) | R11: - | S11: hieu.nguyen-trung | V11: 138 | W11: 138 | X11: 138 | Y11: 2.45 | Z11: 1 | AA11: Complete & Closed | AB11: 43938 | AC11: 43935 | AD11: 43938 | AE11: 43936 | AF11: 43936 | AG11: OK | AH11: 1 | AI11: 1 | AJ11: 1 | AK11: None
B12: 79 | C12: 20200414 | D12: PSW | E12: GWM_B30_CP | F12: rb\as\gwm\core\app\dcom\RBAPLCust\src\ESP | G12: 1415974 | H12: - | I12: RBAPLCUST_RoutineControl_ActuatorTest.c | J12: - | K12: Auto | L12: 80433 | M12: BSSL07 | N12: GWM_AB30_CP_Int | O12: - | P12: ZHANG Wenjia (CC-AS/EVA-SW33-CN) | R12: - | S12: hieu.nguyen-trung | V12: 188 | W12: 188 | X12: 188 | Y12: 3.34 | Z12: 1 | AA12: Complete & Closed | AB12: 43938 | AC12: 43935 | AD12: 43938 | AE12: 43936 | AF12: 43936 | AG12: OK | AH12: 1 | AI12: 1 | AJ12: 1 | AK12: None
B13: 80 | C13: 20200414 | D13: PSW | E13: GWM_B30_CP | F13: rb\as\gwm\core\app\dcom\RBAPLCust\src\ESP | G13: 1415974 | H13: - | I13: RBAPLCUST_RoutineControl_DynamicTest.c | J13: - | K13: Auto | L13: 80433 | M13: BSSL07 | N13: GWM_AB30_CP_Int | O13: - | P13: ZHANG Wenjia (CC-AS/EVA-SW33-CN) | R13: - | S13: hau.nguyen-tai | V13: 189 | W13: 189 | X13: 189 | Y13: 3.36 | Z13: 2 | AA13: Complete & Closed | AB13: 43938 | AC13: 43935 | AD13: 43938 | AE13: 43935 | AF13: 43935 | AG13: OK | AH13: 1 | AI13: 1 | AJ13: 1 | AK13: None
B14: 81 | C14: 20200414 | D14: PSW | E14: GWM_B30_CP | F14: rb\as\gwm\core\app\dcom\RBAPLCust\src\ESP | G14: 1415974 | H14: - | I14: RBAPLCUST_RoutineControl_EvacAndFill.c | J14: - | K14: Auto | L14: 80433 | M14: BSSL07 | N14: GWM_AB30_CP_Int | O14: - | P14: ZHANG Wenjia (CC-AS/EVA-SW33-CN) | R14: - | S14: hau.nguyen-tai | V14: 173 | W14: 173 | X14: 173 | Y14: 3.07 | Z14: 2 | AA14: Complete & Closed | AB14: 43938 | AC14: 43935 | AD14: 43938 | AE14: 43935 | AF14: 43935 | AG14: OK | AH14: 1 | AI14: 1 | AJ14: 1 | AK14: None
B15: 82 | C15: 20200414 | D15: PSW | E15: GWM_B30_CP | F15: rb\as\gwm\core\app\dcom\RBAPLCust\src\ESP | G15: 1415974 | H15: - | I15: RBAPLCUST_RoutineControl_RepairBleeding.c | J15: - | K15: Auto | L15: 80433 | M15: BSSL07 | N15: GWM_AB30_CP_Int | O15: - | P15: ZHANG Wenjia (CC-AS/EVA-SW33-CN) | R15: - | S15: hau.nguyen-tai | V15: 176 | W15: 176 | X15: 176 | Y15: 3.12 | Z15: 2 | AA15: Complete & Closed | AB15: 43938 | AC15: 43935 | AD15: 43938 | AE15: 43935 | AF15: 43935 | AG15: NG | AH15: 0.98 | AI15: 0.97 | AJ15: 1 | AK15: OPL | AL15: Can't cover case default for switch at line #116. Because of the conditon "if ((RBAPLCUST_PHASESEQUENCE_MINIMUM > dataIn1) || (RBAPLCUST_PHASESEQUENCE_MAXIMUM < dataIn1))" at line #87 false when range vaule of dataIn1 to 1 from 4. | AN15: Owner said it's OK "no impact"
B16: 83 | C16: 20200414 | D16: PSW | E16: GWM_B30_CP | F16: rb\as\gwm\core\app\dcom\RBAPLCust\src\ESP | G16: 1415974 | H16: - | I16: RBAPLCUST_RoutineControl_WheelSpeedSensorTest.c | J16: - | K16: Auto | L16: 80433 | M16: BSSL07 | N16: GWM_AB30_CP_Int | O16: - | P16: ZHANG Wenjia (CC-AS/EVA-SW33-CN) | R16: - | S16: hau.nguyen-tai | V16: 239 | W16: 239 | X16: 239 | Y16: 4.24 | Z16: 2 | AA16: Complete & Closed | AB16: 43938 | AC16: 43935 | AD16: 43938 | AE16: 43936 | AF16: 43936 | AG16: OK | AH16: 1 | AI16: 1 | AJ16: 1 | AK16: None
B17: 84 | C17: 20200414 | D17: PSW | E17: GWM_B30_CP | F17: rb\as\gwm\core\app\dcom\RBAPLCust\src\ESP | G17: 1415974 | H17: - | I17: RBAPLCUST_ValvesToggling.c | J17: - | K17: Auto | L17: 80433 | M17: BSSL07 | N17: GWM_AB30_CP_Int | O17: - | P17: ZHANG Wenjia (CC-AS/EVA-SW33-CN) | R17: - | S17: hau.nguyen-tai | V17: 237 | W17: 237 | X17: 237 | Y17: 4.21 | Z17: 1 | AA17: Complete & Closed | AB17: 43938 | AC17: 43935 | AD17: 43938 | AE17: 43936 | AF17: 43936 | AG17: OK | AH17: 1 | AI17: 1 | AJ17: 1 | AK17: None
B18: 85 | C18: 20200414 | D18: PSW | E18: GWM_B30_CP | F18: rb\as\gwm\cp\app\asw\apbmi\host\PDM\APBHostData_Project_C\SRC | G18: 1415974 | H18: - | I18: ApbHostData_Project.c | J18: - | K18: Auto | L18: 80433 | M18: BSSL07 | N18: GWM_AB30_CP_Int | O18: - | P18: ZHANG Wenjia (CC-AS/EVA-SW33-CN) | R18: - | S18: hau.nguyen-tai | V18: 8 | W18: 8 | X18: 8 | Y18: 0.14 | Z18: 1 | AA18: Complete & Closed | AB18: 43938 | AC18: 43935 | AD18: 43938 | AE18: 43936 | AF18: 43936 | AG18: OK | AH18: 1 | AI18: 1 | AJ18: 1 | AK18: None
B19: 86 | C19: 20200414 | D19: PSW | E19: GWM_B30_CP | F19: rb\as\gwm\cp\app\dsm\RBWarningIndicator\src | G19: 1415974 | H19: - | I19: Dem_PrjSpecificIndiHandling.c | J19: - | K19: Auto | L19: 80433 | M19: BSSL07 | N19: GWM_AB30_CP_Int | O19: - | P19: ZHANG Wenjia (CC-AS/EVA-SW33-CN) | R19: - | S19: hau.nguyen-tai | V19: 165 | W19: 165 | X19: 165 | Y19: 2.93 | Z19: 1 | AA19: Complete & Closed | AB19: 43938 | AC19: 43935 | AD19: 43938 | AE19: 43936 | AF19: 43936 | AG19: OK | AH19: 1 | AI19: 1 | AJ19: 1 | AK19: None
B20: 87 | C20: 20200414 | D20: PSW | E20: GWM_B30_CP | F20: rb\as\gwm\cp\app\obd\ObdCvnCalId\src | G20: 1415974 | H20: - | I20: Obd_CalId.c | J20: - | K20: Auto | L20: 80433 | M20: BSSL07 | N20: GWM_AB30_CP_Int | O20: - | P20: ZHANG Wenjia (CC-AS/EVA-SW33-CN) | R20: - | S20: hau.nguyen-tai | V20: 0 | W20: 0 | X20: 0 | Y20: 0 | Z20: 0 | AA20: Complete & Closed | AB20: 43938 | AC20: 43935 | AD20: 43938 | AE20: 43936 | AF20: 43936 | AG20: OK | AH20: - | AI20: - | AJ20: - | AK20: None | AN20: No function to test
B21: 88 | C21: 20200414 | D21: PSW | E21: GWM_B30_CP | F21: rb\as\gwm\cp\varcode | G21: 1415974 | H21: - | I21: CNMS_Var_DcmRead.c | J21: - | K21: Auto | L21: 80433 | M21: BSSL07 | N21: GWM_AB30_CP_Int | O21: - | P21: ZHANG Wenjia (CC-AS/EVA-SW33-CN) | R21: - | S21: dac.luu-cong | V21: 12 | W21: 12 | X21: 12 | Y21: 0.21 | Z21: 1 | AA21: Complete & Closed | AB21: 43938 | AC21: 43935 | AD21: 43938 | AE21: 43936 | AF21: 43936 | AG21: OK | AH21: - | AI21: - | AJ21: - | AK21: None | AN21: No function to test
B22: 89 | C22: 20200414 | D22: PSW | E22: GWM_B30_CP | F22: rb\as\gwm\cp\varcode | G22: 1415974 | H22: - | I22: CNMS_Var_Global.c | J22: - | K22: Auto | L22: 80433 | M22: BSSL07 | N22: GWM_AB30_CP_Int | O22: - | P22: ZHANG Wenjia (CC-AS/EVA-SW33-CN) | R22: - | S22: dac.luu-cong | V22: 37 | W22: 37 | X22: 37 | Y22: 0.65 | Z22: 1 | AA22: Complete & Closed | AB22: 43938 | AC22: 43935 | AD22: 43938 | AE22: 43936 | AF22: 43936 | AG22: OK | AH22: 1 | AI22: 1 | AJ22: 1 | AK22: None
B23: 90 | C23: 20200414 | D23: PSW | E23: GWM_B30_CP | F23: rb\as\gwm\cp\dsmpr\src\Cubas\ESM\EcuM\src | G23: 1415974 | H23: - | I23: EcuM_stub.c | J23: - | K23: Auto | L23: 80433 | M23: BSSL07 | N23: GWM_AB30_CP_Int | O23: - | P23: ZHANG Wenjia (CC-AS/EVA-SW33-CN) | R23: - | S23: dac.luu-cong | V23: 3 | W23: 3 | X23: 3 | Y23: 0.05 | Z23: 0.1 | AA23: Complete & Closed | AB23: 43938 | AC23: 43935 | AD23: 43938 | AE23: 43936 | AF23: 43936 | AG23: OK | AH23: - | AI23: - | AJ23: - | AK23: None | AN23: No function to test
B24: 91 | C24: 20200414 | D24: PSW | E24: HHT_VX1_ESPHevX_BL2_Sprint4 | F24: rb\as\hht\core\app\net\RBScl\src | G24: 1416009 | H24: - | I24: ComScl_UserDefinedProcessing.c | J24: - | K24: Auto | L24: 80426 | M24: BL2_Sprint4 | N24: HHT_VX1_ESPHevX_Carbon_Int | O24: - | P24: YAN Jiebing (BEG/ESW-CN) | R24: - | S24: dac.luu-cong | V24: 322 | W24: 322 | X24: 322 | Y24: 5.72 | Z24: 1 | AA24: Complete & Closed | AB24: 43938 | AC24: 43935 | AD24: 43938 | AE24: 43936 | AF24: 43936 | AG24: OK | AH24: 1 | AI24: 1 | AJ24: 1 | AK24: None
B25: 92 | C25: 20200414 | D25: PSW | E25: HHT_VX1_ESPHevX_BL2 | F25: rb\as\hht\core\app\dcom\RBAPLCust\src\ESP | G25: 1416093 | H25: - | I25: RBAPLCUST_ActualServiceLife_ReadData.c | J25: - | K25: Auto | L25: 80426 | M25: BL2 | N25: HHT_VX1_ESPHevX_Carbon_Int | O25: - | P25: LI Jianming (BEG/ESW-CN) | R25: - | S25: dac.luu-cong | V25: 25 | W25: 25 | X25: 25 | Y25: 0.44 | Z25: 0.2 | AA25: Complete & Closed | AB25: 43938 | AC25: 43935 | AD25: 43938 | AE25: 43936 | AF25: 43936 | AG25: OK | AH25: 1 | AI25: 1 | AJ25: 1 | AK25: None
B26: 93 | C26: 20200414 | D26: PSW | E26: HHT_VX1_ESPHevX_BL2 | F26: rb\as\hht\core\app\dcom\RBAPLCust\src\ESP | G26: 1416093 | H26: - | I26: RBAPLCUST_DateTime_ReadData.c | J26: - | K26: Auto | L26: 80426 | M26: BL2 | N26: HHT_VX1_ESPHevX_Carbon_Int | O26: - | P26: LI Jianming (BEG/ESW-CN) | R26: - | S26: dac.luu-cong | V26: 28 | W26: 28 | X26: 28 | Y26: 0.49 | Z26: 0.2 | AA26: Complete & Closed | AB26: 43938 | AC26: 43935 | AD26: 43938 | AE26: 43936 | AF26: 43936 | AG26: OK | AH26: 1 | AI26: 1 | AJ26: 1 | AK26: None
B27: 94 | C27: 20200414 | D27: PSW | E27: HHT_VX1_ESPHevX_BL2 | F27: rb\as\hht\core\app\dcom\RBAPLCust\src\ESP | G27: 1416093 | H27: - | I27: RBAPLCUST_InputDataBattery_Snapshot_ReadData.c | J27: - | K27: Auto | L27: 80426 | M27: BL2 | N27: HHT_VX1_ESPHevX_Carbon_Int | O27: - | P27: LI Jianming (BEG/ESW-CN) | R27: - | S27: dac.luu-cong | V27: 46 | W27: 46 | X27: 46 | Y27: 0.81 | Z27: 0.1 | AA27: Complete & Closed | AB27: 43938 | AC27: 43935 | AD27: 43938 | AE27: 43936 | AF27: 43936 | AG27: OK | AH27: 1 | AI27: 1 | AJ27: 1 | AK27: None
B28: 95 | C28: 20200414 | D28: PSW | E28: HHT_VX1_ESPHevX_BL2 | F28: rb\as\hht\core\app\dcom\RBAPLCust\src\ESP | G28: 1416093 | H28: - | I28: RBAPLCUST_VSOInformation_Snapshot_ReadData.c | J28: - | K28: Auto | L28: 80426 | M28: BL2 | N28: HHT_VX1_ESPHevX_Carbon_Int | O28: - | P28: LI Jianming (BEG/ESW-CN) | R28: - | S28: dac.luu-cong | V28: 31 | W28: 31 | X28: 31 | Y28: 0.55 | Z28: 0.1 | AA28: Complete & Closed | AB28: 43938 | AC28: 43935 | AD28: 43938 | AE28: 43936 | AF28: 43936 | AG28: OK | AH28: 1 | AI28: 1 | AJ28: 1 | AK28: None
B29: 96 | C29: 20200414 | D29: PSW | E29: HHT_VX1_ESPHevX_BL2 | F29: rb\as\hht\core\app\dcom\RBAPLCust\src\ESP | G29: 1416093 | H29: - | I29: RBAPLCUST_HHT_RBDI_NVM.c | J29: - | K29: Auto | L29: 80426 | M29: BL2 | N29: HHT_VX1_ESPHevX_Carbon_Int | O29: - | P29: LI Jianming (BEG/ESW-CN) | R29: - | S29: dac.luu-cong | V29: 102 | W29: 102 | X29: 102 | Y29: 1.81 | Z29: 1 | AA29: Complete & Closed | AB29: 43938 | AC29: 43935 | AD29: 43938 | AE29: 43936 | AF29: 43936 | AG29: OK | AH29: 1 | AI29: 1 | AJ29: 1 | AK29: None
B30: 97 | C30: 20200414 | D30: PSW | E30: HHT_VX1_ESPHevX_BL2 | F30: rb\as\hht\core\app\dcom\RBAPLCust\src\ESP | G30: 1416093 | H30: - | I30: RBAPLCUST_HHT_WBDI_NVM.c | J30: - | K30: Auto | L30: 80426 | M30: BL2 | N30: HHT_VX1_ESPHevX_Carbon_Int | O30: - | P30: LI Jianming (BEG/ESW-CN) | R30: - | S30: dac.luu-cong | V30: 66 | W30: 66 | X30: 66 | Y30: 1.17 | Z30: 1 | AA30: Complete & Closed | AB30: 43938 | AC30: 43935 | AD30: 43938 | AE30: 43936 | AF30: 43936 | AG30: OK | AH30: 1 | AI30: 1 | AJ30: 1 | AK30: None
B31: 98 | C31: 20200414 | D31: PSW | E31: HHT_VX1_ESPHevX_BL2 | F31: rb\as\hht\vx1\dcompr\esp\src | G31: 1416093 | H31: - | I31: RBFSWBootInterface_HHT.c | J31: - | K31: Auto | L31: 80426 | M31: BL2 | N31: HHT_VX1_ESPHevX_Carbon_Int | O31: - | P31: LI Jianming (BEG/ESW-CN) | R31: - | S31: dac.luu-cong | V31: 19 | W31: 19 | X31: 19 | Y31: 0.33 | Z31: 0.1 | AA31: Complete & Closed | AB31: 43938 | AC31: 43935 | AD31: 43938 | AE31: 43936 | AF31: 43936 | AG31: OK | AH31: - | AI31: - | AJ31: - | AK31: None | AN31: No function to test
B32: 99 | C32: 20200414 | D32: PSW | E32: HHT_VX1_IBooster_Gen2_BL2 | F32: rb\as\hht\core\app\dcom\RBAPLCust\src\iBooster | G32: 1416090 | H32: - | I32: RBAPLCUST_ActualServiceLife_ReadData.c | J32: - | K32: Auto | L32: 80428 | M32: BL2 | N32: HHT_VX1_IB2_Carbon_Int | O32: - | P32: LI Jianming (BEG/ESW-CN) | R32: - | S32: phuong.nguyen-thanh | V32: 25 | W32: 25 | X32: 25 | Y32: 0.44 | Z32: 0.25 | AA32: Complete & Closed | AB32: 43938 | AC32: 43935 | AD32: 43938 | AE32: 43938 | AF32: 43938 | AG32: OK | AH32: 1 | AI32: 1 | AJ32: 1 | AK32: None
B33: 100 | C33: 20200414 | D33: PSW | E33: HHT_VX1_IBooster_Gen2_BL2 | F33: rb\as\hht\core\app\dcom\RBAPLCust\src\iBooster | G33: 1416090 | H33: - | I33: RBAPLCUST_DateTime_ReadData.c | J33: - | K33: Auto | L33: 80428 | M33: BL2 | N33: HHT_VX1_IB2_Carbon_Int | O33: - | P33: LI Jianming (BEG/ESW-CN) | R33: - | S33: phuong.nguyen-thanh | V33: 28 | W33: 28 | X33: 28 | Y33: 0.49 | Z33: 0.12 | AA33: Complete & Closed | AB33: 43938 | AC33: 43935 | AD33: 43938 | AE33: 43938 | AF33: 43938 | AG33: OK | AH33: 1 | AI33: 1 | AJ33: 1 | AK33: None
B34: 101 | C34: 20200414 | D34: PSW | E34: HHT_VX1_IBooster_Gen2_BL2 | F34: rb\as\hht\core\app\dcom\RBAPLCust\src\iBooster | G34: 1416090 | H34: - | I34: RBAPLCUST_InputDataBattery_Snapshot_ReadData.c | J34: - | K34: Auto | L34: 80428 | M34: BL2 | N34: HHT_VX1_IB2_Carbon_Int | O34: - | P34: LI Jianming (BEG/ESW-CN) | R34: - | S34: phuong.nguyen-thanh | V34: 46 | W34: 46 | X34: 46 | Y34: 0.81 | Z34: 0.12 | AA34: Complete & Closed | AB34: 43938 | AC34: 43935 | AD34: 43938 | AE34: 43938 | AF34: 43938 | AG34: OK | AH34: 1 | AI34: 1 | AJ34: 1 | AK34: None
B35: 102 | C35: 20200414 | D35: PSW | E35: HHT_VX1_IBooster_Gen2_BL2 | F35: rb\as\hht\core\app\dcom\RBAPLCust\src\iBooster | G35: 1416090 | H35: - | I35: RBAPLCUST_VSOInformation_Snapshot_ReadData.c | J35: - | K35: Auto | L35: 80428 | M35: BL2 | N35: HHT_VX1_IB2_Carbon_Int | O35: - | P35: LI Jianming (BEG/ESW-CN) | R35: - | S35: phuong.nguyen-thanh | V35: 31 | W35: 31 | X35: 31 | Y35: 0.55 | Z35: 0.25 | AA35: Complete & Closed | AB35: 43938 | AC35: 43935 | AD35: 43938 | AE35: 43938 | AF35: 43938 | AG35: OK | AH35: 1 | AI35: 1 | AJ35: 1 | AK35: None
B36: 103 | C36: 20200414 | D36: PSW | E36: HHT_VX1_IBooster_Gen2_BL2 | F36: rb\as\hht\core\app\dcom\RBAPLCust\src\iBooster | G36: 1416090 | H36: - | I36: RBAPLCUST_HHT_RBDI_NVM.c | J36: - | K36: Auto | L36: 80428 | M36: BL2 | N36: HHT_VX1_IB2_Carbon_Int | O36: - | P36: LI Jianming (BEG/ESW-CN) | R36: - | S36: dac.luu-cong | V36: 102 | W36: 102 | X36: 102 | Y36: 1.81 | Z36: 1 | AA36: Complete & Closed | AB36: 43938 | AC36: 43935 | AD36: 43938 | AE36: 43936 | AF36: 43936 | AG36: OK | AH36: 1 | AI36: 1 | AJ36: 1 | AK36: None
B37: 104 | C37: 20200414 | D37: PSW | E37: HHT_VX1_IBooster_Gen2_BL2 | F37: rb\as\hht\core\app\dcom\RBAPLCust\src\iBooster | G37: 1416090 | H37: - | I37: RBAPLCUST_HHT_WBDI_NVM.c | J37: - | K37: Auto | L37: 80428 | M37: BL2 | N37: HHT_VX1_IB2_Carbon_Int | O37: - | P37: LI Jianming (BEG/ESW-CN) | R37: - | S37: dac.luu-cong | V37: 66 | W37: 66 | X37: 66 | Y37: 1.17 | Z37: 1 | AA37: Complete & Closed | AB37: 43938 | AC37: 43935 | AD37: 43938 | AE37: 43936 | AF37: 43936 | AG37: OK | AH37: 1 | AI37: 1 | AJ37: 1 | AK37: None
B38: 105 | C38: 20200414 | D38: PSW | E38: HHT_VX1_IBooster_Gen2_BL2 | F38: rb\as\hht\vx1\dcompr\ib2\src | G38: 1416090 | H38: - | I38: RBFSWBootInterface_HHT.c | J38: - | K38: Auto | L38: 80428 | M38: BL2 | N38: HHT_VX1_IB2_Carbon_Int | O38: - | P38: LI Jianming (BEG/ESW-CN) | R38: - | S38: dac.luu-cong | V38: 19 | W38: 19 | X38: 19 | Y38: 0.33 | Z38: 0.1 | AA38: Complete & Closed | AB38: 43938 | AC38: 43935 | AD38: 43938 | AE38: 43936 | AF38: 43936 | AG38: OK | AH38: - | AI38: - | AJ38: - | AK38: None | AN38: No function to test
B39: 106 | C39: 20200414 | D39: PSW | E39: HHT_VX1_IBooster_Gen2_BL2 | F39: iBoosterGen2\rb\as\hht\vx1\netpr\src | G39: 1417373 | H39: - | I39: ComScl_UserDefinedProcessing.c | J39: - | K39: Auto | L39: 80428 | M39: BL2 | N39: HHT_VX1_IB2_Carbon_Int | O39: - | P39: YUAN Jessica(BEG/ESW-CN) | R39: - | S39: bang.nguyen-duy | V39: 322 | W39: 322 | X39: 322 | Y39: 5.72 | Z39: 2 | AA39: Complete & Closed | AB39: 43938 | AC39: 43935 | AD39: 43938 | AE39: 43935 | AF39: 43935 | AG39: OK | AH39: 1 | AI39: 1 | AJ39: 1 | AK39: None
B40: 107 | C40: 20200414 | D40: PSW | E40: HHT_VX1_IBooster_Gen2_BL2 | F40: iBoosterGen2\rb\as\hht\vx1\netpr\gen\Cubas\CAN_OBD_Off | G40: 1417373 | H40: - | I40: ComScl_Scl_ADCM_BU_2_Rx.c | J40: - | K40: Auto | L40: 80428 | M40: BL2 | N40: HHT_VX1_IB2_Carbon_Int | O40: - | P40: YUAN Jessica(BEG/ESW-CN) | R40: - | S40: bang.nguyen-duy | V40: 268 | W40: 268 | X40: 268 | Y40: 4.76 | Z40: 2 | AA40: Complete & Closed | AB40: 43938 | AC40: 43935 | AD40: 43938 | AE40: 43936 | AF40: 43936 | AG40: OK | AH40: 1 | AI40: 1 | AJ40: 1 | AK40: None
B41: 108 | C41: 20200414 | D41: PSW | E41: HHT_VX1_IBooster_Gen2_BL2 | F41: iBoosterGen2\rb\as\hht\vx1\netpr\gen\Cubas\CAN_OBD_Off | G41: 1417373 | H41: - | I41: ComScl_Scl_ADCM_FD_1_Rx.c | J41: - | K41: Auto | L41: 80428 | M41: BL2 | N41: HHT_VX1_IB2_Carbon_Int | O41: - | P41: YUAN Jessica(BEG/ESW-CN) | R41: - | S41: bang.nguyen-duy | V41: 275 | W41: 275 | X41: 275 | Y41: 4.88 | Z41: 2 | AA41: Complete & Closed | AB41: 43938 | AC41: 43935 | AD41: 43938 | AE41: 43936 | AF41: 43936 | AG41: OK | AH41: 1 | AI41: 1 | AJ41: 1 | AK41: None
...

Sheet Sheet7
B2: No | C2: Package | D2: Type | E2: Project | F2: Project - convert | G2: Tester | H2: ELOC Recheck With Tool | I2: Estimation base TOOL | J2: Status | K2: Planned Start | L2: Planned End | M2: Start | N2: End | O2: Status Result
B3: 70 | C3: 20200414 | D3: PSW | E3: GWM_B30_CP | F3: GWM_B30_CP | G3: hieu.nguyen-trung | H3: 62 | I3: 1.1 | J3: Complete & Closed | K3: 43935 | L3: 43938 | M3: 43935 | N3: 43935 | O3: OK
B4: 71 | C4: 20200414 | D4: PSW | E4: GWM_B30_CP | F4: GWM_B30_CP | G4: hieu.nguyen-trung | H4: 22 | I4: 0.39 | J4: Complete & Closed | K4: 43935 | L4: 43938 | M4: 43936 | N4: 43936 | O4: OK
B5: 72 | C5: 20200414 | D5: PSW | E5: GWM_B30_CP | F5: GWM_B30_CP | G5: hieu.nguyen-trung | H5: 26 | I5: 0.46 | J5: Complete & Closed | K5: 43935 | L5: 43938 | M5: 43936 | N5: 43936 | O5: OK
B6: 73 | C6: 20200414 | D6: PSW | E6: GWM_B30_CP | F6: GWM_B30_CP | G6: hieu.nguyen-trung | H6: 35 | I6: 0.62 | J6: Complete & Closed | K6: 43935 | L6: 43938 | M6: 43936 | N6: 43936 | O6: OK
B7: 74 | C7: 20200414 | D7: PSW | E7: GWM_B30_CP | F7: GWM_B30_CP | G7: hieu.nguyen-trung | H7: 101 | I7: 1.79 | J7: Complete & Closed | K7: 43935 | L7: 43938 | M7: 43936 | N7: 43936 | O7: OK
B8: 75 | C8: 20200414 | D8: PSW | E8: GWM_B30_CP | F8: GWM_B30_CP | G8: hieu.nguyen-trung | H8: 67 | I8: 1.19 | J8: Complete & Closed | K8: 43935 | L8: 43938 | M8: 43936 | N8: 43936 | O8: OK
B9: 76 | C9: 20200414 | D9: PSW | E9: GWM_B30_CP | F9: GWM_B30_CP | G9: hieu.nguyen-trung | H9: 137 | I9: 2.43 | J9: Complete & Closed | K9: 43935 | L9: 43938 | M9: 43936 | N9: 43936 | O9: OK
B10: 77 | C10: 20200414 | D10: PSW | E10: GWM_B30_CP | F10: GWM_B30_CP | G10: hieu.nguyen-trung | H10: 160 | I10: 2.84 | J10: Complete & Closed | K10: 43935 | L10: 43938 | M10: 43936 | N10: 43936 | O10: OK
B11: 78 | C11: 20200414 | D11: PSW | E11: GWM_B30_CP | F11: GWM_B30_CP | G11: hieu.nguyen-trung | H11: 138 | I11: 2.45 | J11: Complete & Closed | K11: 43935 | L11: 43938 | M11: 43936 | N11: 43936 | O11: OK
B12: 79 | C12: 20200414 | D12: PSW | E12: GWM_B30_CP | F12: GWM_B30_CP | G12: hieu.nguyen-trung | H12: 188 | I12: 3.34 | J12: Complete & Closed | K12: 43935 | L12: 43938 | M12: 43936 | N12: 43936 | O12: OK
B13: 80 | C13: 20200414 | D13: PSW | E13: GWM_B30_CP | F13: GWM_B30_CP | G13: hau.nguyen-tai | H13: 189 | I13: 3.36 | J13: Complete & Closed | K13: 43935 | L13: 43938 | M13: 43935 | N13: 43935 | O13: OK
B14: 81 | C14: 20200414 | D14: PSW | E14: GWM_B30_CP | F14: GWM_B30_CP | G14: hau.nguyen-tai | H14: 173 | I14: 3.07 | J14: Complete & Closed | K14: 43935 | L14: 43938 | M14: 43935 | N14: 43935 | O14: OK
... B112: 179 | C112: 20200416 | D112: PSW | E112: BAIC_C62XP_IB2 | F112: BAIC_C62XP_IB2 | G112: dac.luu-cong | H112: 72 | I112: 1.28 | J112: Complete & Closed | K112: 43937 | L112: 43938 | M112: 43938 | N112: 43938 | O112: OK
B113: 180 | C113: 20200416_1 | D113: PSW | E113: Adapt_236246_SMART_BBM_Ibooster_E2_SP3 | F113: Adapt_236246_SMART_BBM_Ibooster_E2_SP3 | G113: bang.nguyen-duy | H113: 1434 | I113: 25.49 | J113: Complete & Closed | K113: 43941 | L113: 43945 | M113: 43943 | N113: 43943 | O113: NG
B114: 181 | C114: 20200416_1 | D114: PSW | E114: Adapt_236246_SMART_BBM_Ibooster_E2_SP3 | F114: Adapt_236246_SMART_BBM_Ibooster_E2_SP3 | G114: huy.do-anh | H114: 75 | I114: 1.33 | J114: Complete & Closed | K114: 43941 | L114: 43945 | M114: 43944 | N114: 43944 | O114: OK
B115: 182 | C115: 20200416_1 | D115: PSW | E115: Adapt_236246_SMART_BBM_Ibooster_E2_SP3 | F115: Adapt_236246_SMART_BBM_Ibooster_E2_SP3 | G115: huy.do-anh | H115: 166 | I115: 2.95 | J115: Complete & Closed | K115: 43941 | L115: 43945 | M115: 43944 | N115: 43944 | O115: OK
B116: 183 | C116: 20200416_1 | D116: PSW | E116: Adapt_236246_SMART_BBM_Ibooster_E2_SP3 | F116: Adapt_236246_SMART_BBM_Ibooster_E2_SP3 | G116: hieu.nguyen-trung | H116: 46 | I116: 0.81 | J116: Complete & Closed | K116: 43941 | L116: 43945 | M116: 43944 | N116: 43944 | O116: OK
B117: 184 | C117: 20200416_1 | D117: PSW | E117: Adapt_236234_SMART_VDDM_ESPHevX_BSS02_E2_SP3 | F117: Adapt_236234_SMART_VDDM_ESPHevX | G117: huy.do-anh | H117: 60 | I117: 1.06 | J117: Complete & Closed | K117: 43941 | L117: 43945 | M117: 43944 | N117: 43944 | O117: OK
B118: 185 | C118: 20200416_1 | D118: PSW | E118: BYD_IPB_SW_Mainstream_BL05_SP10 | F118: BYD_IPB_SW_Mainstream | G118: huy.do-anh | H118: 221 | I118: 3.92 | J118: Complete & Closed | K118: 43941 | L118: 43942 | M118: 43941 | N118: 43941 | O118: OK
B119: 186 | C119: 20200416_1 | D119: PSW | E119: BYD_IPB_SW_Mainstream_BL05_SP10 | F119: BYD_IPB_SW_Mainstream | G119: hieu.nguyen-trung | H119: 919 | I119: 16.33 | J119: Complete & Closed | K119: 43941 | L119: 43942 | M119: 43941 | N119: 43942 | O119: NG
B120: 187 | C120: 20200416_1 | D120: PSW | E120: 206370_BYD_ESP9.3_New_Hybrid_MS15.1_BSS18 | F120: 206370_BYD_ESP9.3_New_Hybrid_MS15.1 | G120: huy.do-anh | H120: 101 | I120: 1.79 | J120: Complete & Closed | K120: 43941 | L120: 43942 | M120: 43941 | N120: 43941 | O120: OK
B121: 188 | C121: 20200416_1 | D121: PSW | E121: 206370_BYD_ESP9.3_New_Hybrid_MS15.1_BSS18 | F121: 206370_BYD_ESP9.3_New_Hybrid_MS15.1 | G121: huy.do-anh | H121: 51 | I121: 0.9 | J121: Complete & Closed | K121: 43941 | L121: 43942 | M121: 43941 | N121: 43941 | O121: OK
B122: 189 | C122: 20200416_1 | D122: PSW | E122: AB30IB2 | F122: AB30IB2 | G122: huy.do-anh | H122: 84 | I122: 1.49 | J122: Complete & Closed | K122: 43941 | L122: 43951 | M122: 43944 | N122: 43944 | O122: OK
B123: 190 | C123: 20200416_1 | D123: PSW | E123: AB30IB2 | F123: AB30IB2 | G123: huy.do-anh | H123: 7 | I123: 0.12 | J123: Complete & Closed | K123: 43941 | L123: 43951 | M123: 43944 | N123: 43944 | O123: OK
B124: 191 | C124: 20200416_1 | D124: PSW | E124: AB30IB2 | F124: AB30IB2 | G124: huy.do-anh | H124: 259 | I124: 4.6 | J124: Complete & Closed | K124: 43941 | L124: 43951 | M124: 43944 | N124: 43944 | O124: NG
... B167: 234 | C167: 20200416_1 | D167: PSW | E167: BYD_IPB_SW_Mainstream_BL05_Defect | F167: BYD_IPB_SW_Mainstream | G167: bang.nguyen-duy | H167: 803 | I167: 14.27 | J167: Complete & Closed | K167: 43941 | L167: 43942 | M167: 43941 | N167: 43942 | O167: NG
B168: 235 | C168: 20200416_1 | D168: PSW | E168: BYD_IPB_SW_Mainstream_BL05_Defect | F168: BYD_IPB_SW_Mainstream
B169: 236 | C169: 20200416_1 | D169: PSW | E169: BYD_IPB_SW_Mainstream_BL05_SP11 | F169: BYD_IPB_SW_Mainstream | G169: dac.luu-cong | H169: 259 | I169: 4.6 | J169: Complete & Closed | K169: 43941 | L169: 43942 | M169: 43941 | N169: 43941 | O169: NG
B170: 237 | C170: 20200416_1 | D170: PSW | E170: BYD_IPB_SW_Mainstream_BL05_SP11 | F170: BYD_IPB_SW_Mainstream | G170: dac.luu-cong | H170: 85 | I170: 1.51 | J170: Complete & Closed | K170: 43941 | L170: 43942 | M170: 43942 | N170: 43942 | O170: OK
B171: 238 | C171: 20200416_1 | D171: PSW | E171: BYD_IPB_SW_Mainstream_BL05_SP11 | F171: BYD_IPB_SW_Mainstream | G171: dac.luu-cong | H171: 208 | I171: 3.69 | J171: Complete & Closed | K171: 43941 | L171: 43942 | M171: 43942 | N171: 43942 | O171: OK
B172: 239 | C172: 20200416_1 | D172: PSW | E172: BYD_IPB_SW_Mainstream_BL05_SP11 | F172: BYD_IPB_SW_Mainstream | G172: dac.luu-cong | H172: 321 | I172: 5.7 | J172: Complete & Closed | K172: 43941 | L172: 43942 | M172: 43941 | N172: 43941 | O172: OK
