Workbook

Sheet Merged_COEM
A1: Summary
B2: Table KPI PSW
B3: No | C3: Tester | D3: Loc Assigned | E3: LOC Complete | F3: Actual Effort (days) | G3: KPI\days | H3: Status (%) | J3: Note:
B4: 1 | C4: hieu.nguyen-trung | D4: 0 | E4: 0 | F4: 0 | G4: N/A | H4: N/A | K4: Productivity of each Member per Day
B5: 2 | C5: hau.nguyen-tai | D5: 596 | E5: 596 | F5: 0.75 | G5: 794.66667 | H5: 1 | L5: PSW: 450 ELOCs
B6: 3 | C6: bang.nguyen-duy | D6: 0 | E6: 0 | F6: 0 | G6: N/A | H6: N/A | L6: ASW: 130 ELOCs
B7: 4 | C7: dac.luu-cong | D7: 0 | E7: 0 | F7: 0 | G7: N/A | H7: N/A | K7: Total Productivity per Month
B8: 5 | C8: duong.nguyen | D8: 6916 | E8: 6916 | F8: 8.91875 | G8: 775.44499 | H8: 1 | L8: PSW: 450x4x20 = 36;000 ELOCs
B9: 6 | C9: loc.do-phu | D9: 5766 | E9: 5766 | F9: 7.0625 | G9: 816.42478 | H9: 1 | L9: ASW: 130x4x20 = 10;400 ELOCs
B10: 7 | C10: thanh.nguyen-kim | D10: 6065 | E10: 6065 | F10: 8.5875 | G10: 706.2591 | H10: 1
B11: 8 | C11: chung.ly | D11: 6314 | E11: 6314 | F11: 6.2875 | G11: 1004.2147 | H11: 1
B12: 9 | C12: huy.do-anh | D12: 0 | E12: 0 | F12: 0 | G12: N/A | H12: N/A
B13: 10 | C13: phuong.nguyen-thanh | D13: 520 | E13: 520 | F13: 0.875 | G13: 594.28571 | H13: 1 | J13: Date | K13: 43952 | M13: 43965
B14: Total | D14: 26177 | E14: 26177 | F14: 32.48125 | G14: 805.9111 | H14: 1 | J14: Total Days | K14: 10
J15: Holidays | K15: 1 | L15: 1st May
J16: Duration | K16: 9
B17: Table KPI ASW
B18: No | C18: Tester | D18: Loc Assigned | E18: LOC Complete | F18: Actual Effort (days) | G18: KPI/days | H18: Status (%)
B19: 1 | C19: hieu.nguyen-trung | D19: 0 | E19: 0 | F19: 0 | G19: N/A | H19: N/A
B20: 2 | C20: hau.nguyen-tai | D20: 0 | E20: 0 | F20: 0 | G20: N/A | H20: N/A
B21: 3 | C21: bang.nguyen-duy | D21: 0 | E21: 0 | F21: 0 | G21: N/A | H21: N/A
B22: 4 | C22: dac.luu-cong | D22: 0 | E22: 0 | F22: 0 | G22: N/A | H22: N/A
B23: 5 | C23: duong.nguyen | D23: 340 | E23: 340 | F23: 2.375 | G23: 143.15789 | H23: 1
B24: 6 | C24: loc.do-phu | D24: 178 | E24: 178 | F24: 1 | G24: 178 | H24: 1
B25: 7 | C25: thanh.nguyen-kim | D25: 243 | E25: 243 | F25: 1.75 | G25: 138.85714 | H25: 1
B26: 8 | C26: chung.ly | D26: 208 | E26: 208 | F26: 1 | G26: 208 | H26: 1
B27: 9 | C27: huy.do-anh | D27: 0 | E27: 0 | F27: 0 | G27: N/A | H27: N/A
B28: 10 | C28: phuong.nguyen-thanh | D28: 0 | E28: 0 | F28: 0 | G28: N/A | H28: N/A
B29: Total | D29: 969 | E29: 969 | F29: 6.125 | G29: 158.20408 | H29: 1
A32: Refer | B32: Judge Total KPI
B33: No | C33: Tester | D33: Loc Assigned | E33: LOC Complete | F33: Effort (days) | G33: KPI/days | H33: Status (%) | I33: OPL | J33: Defect
B34: 1 | C34: hieu.nguyen-trung | D34: 0 | E34: 0 | F34: 9 | G34: 0 | H34: N/A | I34: 0 | J34: 0
B35: 2 | C35: hau.nguyen-tai | D35: 596 | E35: 596 | F35: 9 | G35: 66.222222 | H35: 1 | I35: 1 | J35: 0
B36: 3 | C36: bang.nguyen-duy | D36: 0 | E36: 0 | F36: 9 | G36: 0 | H36: N/A | I36: 0 | J36: 0
B37: 4 | C37: dac.luu-cong | D37: 0 | E37: 0 | F37: 9 | G37: 0 | H37: N/A | I37: 0 | J37: 0
B38: 5 | C38: duong.nguyen | D38: 8092.9231 | E38: 8092.9231 | F38: 9 | G38: 899.21368 | H38: 1 | I38: 6 | J38: 1
B39: 6 | C39: loc.do-phu | D39: 6382.1538 | E39: 6382.1538 | F39: 9 | G39: 709.12821 | H39: 1 | I39: 7 | J39: 1
B40: 7 | C40: thanh.nguyen-kim | D40: 6906.1538 | E40: 6906.1538 | F40: 9 | G40: 767.35043 | H40: 1 | I40: 4 | J40: 0
B41: 8 | C41: chung.ly | D41: 7034 | E41: 7034 | F41: 9 | G41: 781.55556 | H41: 1 | I41: 5 | J41: 0
B42: 9 | C42: huy.do-anh | D42: 0 | E42: 0 | F42: 9 | G42: 0 | H42: N/A | I42: 0 | J42: 0
...

Sheet RAW
A1: Summary
B2: Table KPI PSW
B3: No | C3: Tester | D3: Loc Assigned | E3: LOC Complete | F3: Actual Effort (days) | G3: KPI\days | H3: Status (%) | J3: Note:
B4: 1 | C4: hieu.nguyen-trung | D4: 0 | E4: 0 | F4: 0 | G4: N/A | H4: N/A | K4: Productivity of each Member per Day
B5: 2 | C5: hau.nguyen-tai | D5: 596 | E5: 596 | F5: 0.75 | G5: 794.66667 | H5: 1 | L5: PSW: 450 ELOCs
B6: 3 | C6: bang.nguyen-duy | D6: 0 | E6: 0 | F6: 0 | G6: N/A | H6: N/A | L6: ASW: 130 ELOCs
B7: 4 | C7: dac.luu-cong | D7: 0 | E7: 0 | F7: 0 | G7: N/A | H7: N/A | K7: Total Productivity per Month
B8: 5 | C8: duong.nguyen | D8: 6916 | E8: 6916 | F8: 8.91875 | G8: 775.44499 | H8: 1 | L8: PSW: 450x4x20 = 36;000 ELOCs
B9: 6 | C9: loc.do-phu | D9: 5766 | E9: 5766 | F9: 7.0625 | G9: 816.42478 | H9: 1 | L9: ASW: 130x4x20 = 10;400 ELOCs
B10: 7 | C10: thanh.nguyen-kim | D10: 6065 | E10: 6065 | F10: 8.5875 | G10: 706.2591 | H10: 1
B11: 8 | C11: chung.ly | D11: 6314 | E11: 6314 | F11: 6.2875 | G11: 1004.2147 | H11: 1
B12: 9 | C12: huy.do-anh | D12: 0 | E12: 0 | F12: 0 | G12: N/A | H12: N/A
B13: 10 | C13: phuong.nguyen-thanh | D13: 520 | E13: 520 | F13: 0.875 | G13: 594.28571 | H13: 1 | J13: Date | K13: 43952 | M13: 43965
B14: Total | D14: 26177 | E14: 26177 | F14: 32.48125 | G14: 805.9111 | H14: 1 | J14: Total Days | K14: 10
J15: Holidays | K15: 1 | L15: 1st May
J16: Duration | K16: 9
B17: Table KPI ASW
B18: No | C18: Tester | D18: Loc Assigned | E18: LOC Complete | F18: Actual Effort (days) | G18: KPI/days | H18: Status (%)
B19: 1 | C19: hieu.nguyen-trung | D19: 0 | E19: 0 | F19: 0 | G19: N/A | H19: N/A
B20: 2 | C20: hau.nguyen-tai | D20: 0 | E20: 0 | F20: 0 | G20: N/A | H20: N/A
B21: 3 | C21: bang.nguyen-duy | D21: 0 | E21: 0 | F21: 0 | G21: N/A | H21: N/A
B22: 4 | C22: dac.luu-cong | D22: 0 | E22: 0 | F22: 0 | G22: N/A | H22: N/A
B23: 5 | C23: duong.nguyen | D23: 340 | E23: 340 | F23: 2.375 | G23: 143.15789 | H23: 1
B24: 6 | C24: loc.do-phu | D24: 178 | E24: 178 | F24: 1 | G24: 178 | H24: 1
B25: 7 | C25: thanh.nguyen-kim | D25: 243 | E25: 243 | F25: 1.75 | G25: 138.85714 | H25: 1
B26: 8 | C26: chung.ly | D26: 208 | E26: 208 | F26: 1 | G26: 208 | H26: 1
B27: 9 | C27: huy.do-anh | D27: 0 | E27: 0 | F27: 0 | G27: N/A | H27: N/A
B28: 10 | C28: phuong.nguyen-thanh | D28: 0 | E28: 0 | F28: 0 | G28: N/A | H28: N/A
B29: Total | D29: 969 | E29: 969 | F29: 6.125 | G29: 158.20408 | H29: 1
A32: Refer | B32: Judge Total KPI
B33: No | C33: Tester | D33: Loc Assigned | E33: LOC Complete | F33: Effort (days) | G33: KPI/days | H33: Status (%) | I33: OPL | J33: Defect
B34: 1 | C34: hieu.nguyen-trung | D34: 0 | E34: 0 | F34: 9 | G34: 0 | H34: N/A | I34: 0 | J34: 0
B35: 2 | C35: hau.nguyen-tai | D35: 596 | E35: 596 | F35: 9 | G35: 66.222222 | H35: 1 | I35: 1 | J35: 0
B36: 3 | C36: bang.nguyen-duy | D36: 0 | E36: 0 | F36: 9 | G36: 0 | H36: N/A | I36: 0 | J36: 0
B37: 4 | C37: dac.luu-cong | D37: 0 | E37: 0 | F37: 9 | G37: 0 | H37: N/A | I37: 0 | J37: 0
B38: 5 | C38: duong.nguyen | D38: 8092.9231 | E38: 8092.9231 | F38: 9 | G38: 899.21368 | H38: 1 | I38: 6 | J38: 1
B39: 6 | C39: loc.do-phu | D39: 6382.1538 | E39: 6382.1538 | F39: 9 | G39: 709.12821 | H39: 1 | I39: 7 | J39: 1
B40: 7 | C40: thanh.nguyen-kim | D40: 6906.1538 | E40: 6906.1538 | F40: 9 | G40: 767.35043 | H40: 1 | I40: 4 | J40: 0
B41: 8 | C41: chung.ly | D41: 7034 | E41: 7034 | F41: 9 | G41: 781.55556 | H41: 1 | I41: 5 | J41: 0
B42: 9 | C42: huy.do-anh | D42: 0 | E42: 0 | F42: 9 | G42: 0 | H42: N/A | I42: 0 | J42: 0
...

Sheet RAW_remove_BL
A1: Summary
B2: Table KPI PSW
B3: No | C3: Tester | D3: Loc Assigned | E3: LOC Complete | F3: Actual Effort (days) | G3: KPI\days | H3: Status (%) | J3: Note:
B4: 1 | C4: hieu.nguyen-trung | D4: 0 | E4: 0 | F4: 0 | G4: N/A | H4: N/A | K4: Productivity of each Member per Day
B5: 2 | C5: hau.nguyen-tai | D5: 596 | E5: 596 | F5: 0.75 | G5: 794.66667 | H5: 1 | L5: PSW: 450 ELOCs
B6: 3 | C6: bang.nguyen-duy | D6: 0 | E6: 0 | F6: 0 | G6: N/A | H6: N/A | L6: ASW: 130 ELOCs
B7: 4 | C7: dac.luu-cong | D7: 0 | E7: 0 | F7: 0 | G7: N/A | H7: N/A | K7: Total Productivity per Month
B8: 5 | C8: duong.nguyen | D8: 6916 | E8: 6916 | F8: 8.91875 | G8: 775.44499 | H8: 1 | L8: PSW: 450x4x20 = 36;000 ELOCs
B9: 6 | C9: loc.do-phu | D9: 5766 | E9: 5766 | F9: 7.0625 | G9: 816.42478 | H9: 1 | L9: ASW: 130x4x20 = 10;400 ELOCs
B10: 7 | C10: thanh.nguyen-kim | D10: 6065 | E10: 6065 | F10: 8.5875 | G10: 706.2591 | H10: 1
B11: 8 | C11: chung.ly | D11: 6314 | E11: 6314 | F11: 6.2875 | G11: 1004.2147 | H11: 1
B12: 9 | C12: huy.do-anh | D12: 0 | E12: 0 | F12: 0 | G12: N/A | H12: N/A
B13: 10 | C13: phuong.nguyen-thanh | D13: 520 | E13: 520 | F13: 0.875 | G13: 594.28571 | H13: 1 | J13: Date | K13: 43952 | M13: 43965
B14: Total | D14: 26177 | E14: 26177 | F14: 32.48125 | G14: 805.9111 | H14: 1 | J14: Total Days | K14: 10
J15: Holidays | K15: 1 | L15: 1st May
J16: Duration | K16: 9
B17: Table KPI ASW
B18: No | C18: Tester | D18: Loc Assigned | E18: LOC Complete | F18: Actual Effort (days) | G18: KPI/days | H18: Status (%)
B19: 1 | C19: hieu.nguyen-trung | D19: 0 | E19: 0 | F19: 0 | G19: N/A | H19: N/A
B20: 2 | C20: hau.nguyen-tai | D20: 0 | E20: 0 | F20: 0 | G20: N/A | H20: N/A
B21: 3 | C21: bang.nguyen-duy | D21: 0 | E21: 0 | F21: 0 | G21: N/A | H21: N/A
B22: 4 | C22: dac.luu-cong | D22: 0 | E22: 0 | F22: 0 | G22: N/A | H22: N/A
B23: 5 | C23: duong.nguyen | D23: 340 | E23: 340 | F23: 2.375 | G23: 143.15789 | H23: 1
B24: 6 | C24: loc.do-phu | D24: 178 | E24: 178 | F24: 1 | G24: 178 | H24: 1
B25: 7 | C25: thanh.nguyen-kim | D25: 243 | E25: 243 | F25: 1.75 | G25: 138.85714 | H25: 1
B26: 8 | C26: chung.ly | D26: 208 | E26: 208 | F26: 1 | G26: 208 | H26: 1
B27: 9 | C27: huy.do-anh | D27: 0 | E27: 0 | F27: 0 | G27: N/A | H27: N/A
B28: 10 | C28: phuong.nguyen-thanh | D28: 0 | E28: 0 | F28: 0 | G28: N/A | H28: N/A
B29: Total | D29: 969 | E29: 969 | F29: 6.125 | G29: 158.20408 | H29: 1
A32: Refer | B32: Judge Total KPI
B33: No | C33: Tester | D33: Loc Assigned | E33: LOC Complete | F33: Effort (days) | G33: KPI/days | H33: Status (%) | I33: OPL | J33: Defect
B34: 1 | C34: hieu.nguyen-trung | D34: 0 | E34: 0 | F34: 9 | G34: 0 | H34: N/A | I34: 0 | J34: 0
B35: 2 | C35: hau.nguyen-tai | D35: 596 | E35: 596 | F35: 9 | G35: 66.222222 | H35: 1 | I35: 1 | J35: 0
B36: 3 | C36: bang.nguyen-duy | D36: 0 | E36: 0 | F36: 9 | G36: 0 | H36: N/A | I36: 0 | J36: 0
B37: 4 | C37: dac.luu-cong | D37: 0 | E37: 0 | F37: 9 | G37: 0 | H37: N/A | I37: 0 | J37: 0
B38: 5 | C38: duong.nguyen | D38: 8092.9231 | E38: 8092.9231 | F38: 9 | G38: 899.21368 | H38: 1 | I38: 6 | J38: 1
B39: 6 | C39: loc.do-phu | D39: 6382.1538 | E39: 6382.1538 | F39: 9 | G39: 709.12821 | H39: 1 | I39: 7 | J39: 1
B40: 7 | C40: thanh.nguyen-kim | D40: 6906.1538 | E40: 6906.1538 | F40: 9 | G40: 767.35043 | H40: 1 | I40: 4 | J40: 0
B41: 8 | C41: chung.ly | D41: 7034 | E41: 7034 | F41: 9 | G41: 781.55556 | H41: 1 | I41: 5 | J41: 0
B42: 9 | C42: huy.do-anh | D42: 0 | E42: 0 | F42: 9 | G42: 0 | H42: N/A | I42: 0 | J42: 0
...

Sheet Table
B2: KPI Table
B3: No\Type | C3: ASW | D3: PSW
B4: 1 | C4: 130 | D4: 450
B6: Table Type of Testing
B7: No | C7: Type | D7: Tool | E7: Detail Output
B8: 1 | C8: ASW | D8: ATT | E8: 1. Test Design (.xls) 2. Plot File (.plt) 3. ATT project 4. Coverage Log
B9: 2 | C9: PSW | D9: Cantata | E9: 1. TPA file (.tpa) 2. test report (.html) 3. test report (.xml) 4. test summary (.html) 5. File Coverage Fail Reason (.xls)
B11: Table Tester
B12: No | C12: Member
B13: 1 | C13: hieu.nguyen-trung
B14: 2 | C14: hau.nguyen-tai
B15: 3 | C15: bang.nguyen-duy
B16: 4 | C16: dac.luu-cong
B17: 5 | C17: duong.nguyen
B18: 6 | C18: loc.do-phu
B19: 7 | C19: thanh.nguyen-kim
B20: 8 | C20: chung.ly
B21: 9 | C21: huy.do-anh
B22: 10 | C22: phuong.nguyen-thanh
B24: Status Table
B25: No | C25: Status
B26: 1 | C26: N/A
B27: 2 | C27: Ongoing
B28: 3 | C28: Ready for review
B29: 4 | C29: Ready for delivery
B30: 5 | C30: Ready for PLC
B31: 6 | C31: Pending for OPL
B32: 7 | C32: Complete & Closed
B34: Type of OPL/Defect
B35: No | C35: Status
B36: 1 | C36: OPL
B37: 2 | C37: Defect
B38: 3 | C38: None
B40: Status Result
B41: No | C41: Status
B42: 1 | C42: OK
B43: 2 | C43: NG
B45: Type of Comment
B46: No | C46: Status
B47: 1 | C47: Auto
...

Sheet Sheet1
B1: No | C1: Prj | D1: Prj | E1: Tester | F1: a | G1: a | H1: a | I1: a | J1: a | L1: No | M1: Prj | N1: Prj | O1: Tester | P1: a | Q1: a | R1: a | S1: a | T1: a
B2: 11 | C2: 206370_BYD_ESP9.3_New_Hybrid_MS15.1_BSS18 | D2: 206370_BYD_ESP9.3_New_Hybrid_MS15.1_BSS18 | E2: bang.nguyen-duy | F2: 997 | G2: 17.72 | H2: 2 | I2: Ready for PLC | J2: 43956 | L2: 11 | M2: 206370_BYD_ESP9.3_New_Hybrid_MS15.1_BSS18 | N2: 206370_BYD_ESP9.3_New_Hybrid_MS15.1_BSS18 | O2: bang.nguyen-duy | P2: 997 | Q2: 17.72 | R2: 2 | S2: Ready for PLC | T2: 43956
B3: 17 | C3: MC_239507_SGMW_CN210S_PHEV_ESP9.3CPi_BSS03_SP1 | D3: MC_239507_SGMW_CN210S_PHEV_ESP9.3CPi_BSS03_SP1 | E3: bang.nguyen-duy | F3: 431 | G3: 7.66 | H3: 1 | I3: Complete & Closed | J3: 43957 | L3: 17 | M3: MC_239507_SGMW_CN210S_PHEV_ESP9.3CPi_BSS03_SP1 | N3: MC_239507_SGMW_CN210S_PHEV_ESP9.3CPi_BSS03_SP1 | O3: bang.nguyen-duy | P3: 431 | Q3: 7.66 | R3: 1 | S3: Complete & Closed | T3: 43957
B4: 18 | C4: MC_239507_SGMW_CN210S_PHEV_ESP9.3CPi_BSS03_SP1 | D4: MC_239507_SGMW_CN210S_PHEV_ESP9.3CPi_BSS03_SP1 | E4: bang.nguyen-duy | F4: 184 | G4: 3.27 | H4: 1 | I4: Complete & Closed | J4: 43957 | L4: 18 | M4: MC_239507_SGMW_CN210S_PHEV_ESP9.3CPi_BSS03_SP1 | N4: MC_239507_SGMW_CN210S_PHEV_ESP9.3CPi_BSS03_SP1 | O4: bang.nguyen-duy | P4: 184 | Q4: 3.27 | R4: 1 | S4: Complete & Closed | T4: 43957
B5: 73 | C5: BAIC_C62X_RC_APA_BL01 | D5: BAIC_C62X_RC_APA_BL01 | E5: bang.nguyen-duy | F5: 117 | G5: 2.08 | H5: 0.5 | I5: Ready for PLC | J5: 43959 | L5: 73 | M5: BAIC_C62X_RC_APA_BL01 | N5: BAIC_C62X_RC_APA_BL01 | O5: bang.nguyen-duy | P5: 117 | Q5: 2.08 | R5: 0.5 | S5: Ready for PLC | T5: 43959
B6: 74 | C6: BAIC_C62X_RC_APA_BL01 | D6: BAIC_C62X_RC_APA_BL01 | E6: bang.nguyen-duy | F6: 76 | G6: 1.35 | H6: 0.5 | I6: Ready for PLC | J6: 43959 | L6: 74 | M6: BAIC_C62X_RC_APA_BL01 | N6: BAIC_C62X_RC_APA_BL01 | O6: bang.nguyen-duy | P6: 76 | Q6: 1.35 | R6: 0.5 | S6: Ready for PLC | T6: 43959
B7: 75 | C7: BAIC_C62X_RC_APA_BL01 | D7: BAIC_C62X_RC_APA_BL01 | E7: bang.nguyen-duy | F7: 114 | G7: 2.02 | H7: 0.5 | I7: Ready for PLC | J7: 43959 | L7: 75 | M7: BAIC_C62X_RC_APA_BL01 | N7: BAIC_C62X_RC_APA_BL01 | O7: bang.nguyen-duy | P7: 114 | Q7: 2.02 | R7: 0.5 | S7: Ready for PLC | T7: 43959
B8: 101 | C8: DFN_ESP_Gen9.3_534_238307_BS03SP03 | D8: DFN_ESP_Gen9.3_534_238307_BS03SP03 | E8: bang.nguyen-duy | F8: 309 | G8: 5.49 | H8: 4 | I8: Complete & Closed | J8: 43963 | L8: 101 | M8: DFN_ESP_Gen9.3_534_238307_BS03SP03 | N8: DFN_ESP_Gen9.3_534_238307_BS03SP03 | O8: bang.nguyen-duy | P8: 309 | Q8: 5.49 | R8: 4 | S8: Complete & Closed | T8: 43963
B9: 102 | C9: DFN_ESP_Gen9.3_534_238307_BS03SP03 | D9: DFN_ESP_Gen9.3_534_238307_BS03SP03 | E9: bang.nguyen-duy | F9: 25 | G9: 0.44 | H9: 1 | I9: Complete & Closed | J9: 43963 | L9: 102 | M9: DFN_ESP_Gen9.3_534_238307_BS03SP03 | N9: DFN_ESP_Gen9.3_534_238307_BS03SP03 | O9: bang.nguyen-duy | P9: 25 | Q9: 0.44 | R9: 1 | S9: Complete & Closed | T9: 43963
B10: 103 | C10: DFN_ESP_Gen9.3_534_238307_BS03SP03 | D10: DFN_ESP_Gen9.3_534_238307_BS03SP03 | E10: bang.nguyen-duy | F10: 215 | G10: 3.82 | H10: 2 | I10: Complete & Closed | J10: 43963 | L10: 103 | M10: DFN_ESP_Gen9.3_534_238307_BS03SP03 | N10: DFN_ESP_Gen9.3_534_238307_BS03SP03 | O10: bang.nguyen-duy | P10: 215 | Q10: 3.82 | R10: 2 | S10: Complete & Closed | T10: 43963
B11: 115 | C11: RC_242264_SOKON_S513EVR_ESP9.3 | D11: RC_242264_SOKON_S513EVR_ESP9.3 | E11: bang.nguyen-duy | F11: 107 | G11: 1.9 | H11: 0.5 | I11: Ready for PLC | J11: 43965 | L11: 115 | M11: RC_242264_SOKON_S513EVR_ESP9.3 | N11: RC_242264_SOKON_S513EVR_ESP9.3 | O11: bang.nguyen-duy | P11: 107 | Q11: 1.9 | R11: 0.5 | S11: Ready for PLC | T11: 43965
B12: 124 | C12: MC_237270_GAC_A55CP_Carbon_ESP_BL02 | D12: MC_237270_GAC_A55CP_Carbon_ESP_BL02 | E12: bang.nguyen-duy | F12: 236 | G12: 4.19 | H12: 0.5 | I12: Complete & Closed | J12: 43962 | L12: 124 | M12: MC_237270_GAC_A55CP_Carbon_ESP_BL02 | N12: MC_237270_GAC_A55CP_Carbon_ESP_BL02 | O12: bang.nguyen-duy | P12: 236 | Q12: 4.19 | R12: 0.5 | S12: Complete & Closed | T12: 43962
B13: 183 | C13: HHT_VX1_IBooster_Gen2_BL2 | D13: HHT_VX1_IBooster_Gen2_BL2 | E13: bang.nguyen-duy | F13: 322 | G13: 5.72 | H13: 2 | I13: Complete & Closed | J13: 43938 | L13: 129 | M13: BJEV_N60_2WD_4WD | N13: BJEV_N60_2WD_4WD | O13: bang.nguyen-duy | P13: 134 | Q13: 2.38 | T13: 43966
B14: 184 | C14: HHT_VX1_IBooster_Gen2_BL2 | D14: HHT_VX1_IBooster_Gen2_BL2 | E14: bang.nguyen-duy | F14: 268 | G14: 4.76 | H14: 2 | I14: Complete & Closed | J14: 43938 | L14: 130 | M14: BJEV_N60_2WD_4WD | N14: BJEV_N60_2WD_4WD | O14: bang.nguyen-duy | P14: 200 | Q14: 3.55 | T14: 43966
B15: 185 | C15: HHT_VX1_IBooster_Gen2_BL2 | D15: HHT_VX1_IBooster_Gen2_BL2 | E15: bang.nguyen-duy | F15: 275 | G15: 4.88 | H15: 2 | I15: Complete & Closed | J15: 43938 | L15: 131 | M15: BJEV_N60_2WD_4WD | N15: BJEV_N60_2WD_4WD | O15: bang.nguyen-duy | P15: 145 | Q15: 2.57 | T15: 43966
B16: 186 | C16: HHT_VX1_IBooster_Gen2_BL2 | D16: HHT_VX1_IBooster_Gen2_BL2 | E16: bang.nguyen-duy | F16: 267 | G16: 4.74 | H16: 2.5 | I16: Complete & Closed | J16: 43938 | L16: 132 | M16: BJEV_N60_2WD_4WD | N16: BJEV_N60_2WD_4WD | O16: bang.nguyen-duy | P16: 124 | Q16: 2.2 | T16: 43966
B17: 192 | C17: EC_245950_NIO_ESX_ESPHevX_DTC_BSS01_SP01 | D17: EC_245950_NIO_ESX_ESPHevX_DTC_BSS01_SP01 | E17: bang.nguyen-duy | F17: 194 | G17: 3.44 | H17: 3 | I17: Complete & Closed | J17: 43938 | L17: 133 | M17: BJEV_N60_2WD_4WD | N17: BJEV_N60_2WD_4WD | O17: bang.nguyen-duy | P17: 154 | Q17: 2.73 | T17: 43966
B18: 193 | C18: EC_245950_NIO_ESX_ESPHevX_DTC_BSS01_SP01 | D18: EC_245950_NIO_ESX_ESPHevX_DTC_BSS01_SP01 | E18: bang.nguyen-duy | F18: 321 | G18: 5.7 | H18: 6 | I18: Complete & Closed | J18: 43938 | L18: 134 | M18: BJEV_N60_2WD_4WD | N18: BJEV_N60_2WD_4WD | O18: bang.nguyen-duy | P18: 71 | Q18: 1.26 | T18: 43966
B19: 194 | C19: EC_245950_NIO_ESX_ESPHevX_DTC_BSS01_SP01 | D19: EC_245950_NIO_ESX_ESPHevX_DTC_BSS01_SP01 | E19: bang.nguyen-duy | F19: 52 | G19: 0.92 | H19: 1 | I19: Complete & Closed | J19: 43938 | L19: 135 | M19: BJEV_N60_2WD_4WD | N19: BJEV_N60_2WD_4WD | O19: bang.nguyen-duy | P19: 39 | Q19: 0.69 | T19: 43966
B20: 195 | C20: EC_245950_NIO_ESX_ESPHevX_DTC_BSS01_SP01 | D20: EC_245950_NIO_ESX_ESPHevX_DTC_BSS01_SP01 | E20: bang.nguyen-duy | F20: 209 | G20: 3.71 | H20: 3 | I20: Complete & Closed | J20: 43938 | L20: 136 | M20: BJEV_N60_2WD_4WD | N20: BJEV_N60_2WD_4WD | O20: bang.nguyen-duy | P20: 82 | Q20: 1.45 | T20: 43966
B21: 196 | C21: EC_245950_NIO_ESX_ESPHevX_DTC_BSS01_SP01 | D21: EC_245950_NIO_ESX_ESPHevX_DTC_BSS01_SP01 | E21: bang.nguyen-duy | F21: 67 | G21: 1.19 | H21: 2 | I21: Complete & Closed | J21: 43938 | L21: 137 | M21: BJEV_N60_2WD_4WD | N21: BJEV_N60_2WD_4WD | O21: bang.nguyen-duy | P21: 54 | Q21: 0.96 | T21: 43966
B22: 197 | C22: EC_245950_NIO_ESX_ESPHevX_DTC_BSS01_SP01 | D22: EC_245950_NIO_ESX_ESPHevX_DTC_BSS01_SP01 | E22: bang.nguyen-duy | F22: 202 | G22: 3.59 | H22: 3 | I22: Complete & Closed | J22: 43938 | L22: 138 | M22: BJEV_N60_2WD_4WD | N22: BJEV_N60_2WD_4WD | O22: bang.nguyen-duy | P22: 109 | Q22: 1.93 | T22: 43966
B23: 257 | C23: Adapt_236246_SMART_BBM_Ibooster_E2_SP3 | D23: Adapt_236246_SMART_BBM_Ibooster_E2_SP3 | E23: bang.nguyen-duy | F23: 1434 | G23: 25.49 | H23: 3 | I23: Complete & Closed | J23: 43945 | L23: 139 | M23: BJEV_N60_2WD_4WD | N23: BJEV_N60_2WD_4WD | O23: bang.nguyen-duy | P23: 255 | Q23: 4.53 | T23: 43966
B24: 280 | C24: GWM_B30_HP | D24: GWM_B30_HP | E24: bang.nguyen-duy | F24: 84 | G24: 1.49 | H24: 0.5 | I24: Complete & Closed | J24: 43951 | L24: 183 | M24: HHT_VX1_IBooster_Gen2_BL2 | N24: HHT_VX1_IBooster_Gen2_BL2 | O24: bang.nguyen-duy | P24: 322 | Q24: 5.72 | R24: 2 | S24: Complete & Closed | T24: 43938
B25: 281 | C25: GWM_B30_HP | D25: GWM_B30_HP | E25: bang.nguyen-duy | F25: 7 | G25: 0.12 | H25: 0.12 | I25: Complete & Closed | J25: 43951 | L25: 184 | M25: HHT_VX1_IBooster_Gen2_BL2 | N25: HHT_VX1_IBooster_Gen2_BL2 | O25: bang.nguyen-duy | P25: 268 | Q25: 4.76 | R25: 2 | S25: Complete & Closed | T25: 43938
B26: 282 | C26: GWM_B30_HP | D26: GWM_B30_HP | E26: bang.nguyen-duy | F26: 259 | G26: 4.6 | H26: 0.5 | I26: Complete & Closed | J26: 43951 | L26: 185 | M26: HHT_VX1_IBooster_Gen2_BL2 | N26: HHT_VX1_IBooster_Gen2_BL2 | O26: bang.nguyen-duy | P26: 275 | Q26: 4.88 | R26: 2 | S26: Complete & Closed | T26: 43938
B27: 283 | C27: GWM_B30_HP | D27: GWM_B30_HP | E27: bang.nguyen-duy | F27: 140 | G27: 2.48 | H27: 0.5 | I27: Complete & Closed | J27: 43951 | L27: 186 | M27: HHT_VX1_IBooster_Gen2_BL2 | N27: HHT_VX1_IBooster_Gen2_BL2 | O27: bang.nguyen-duy | P27: 267 | Q27: 4.74 | R27: 2.5 | S27: Complete & Closed | T27: 43938
B28: 284 | C28: GWM_B30_HP | D28: GWM_B30_HP | E28: bang.nguyen-duy | F28: 313 | G28: 5.56 | H28: 2 | I28: Complete & Closed | J28: 43951 | L28: 192 | M28: EC_245950_NIO_ESX_ESPHevX_DTC_BSS01_SP01 | N28: EC_245950_NIO_ESX_ESPHevX_DTC_BSS01_SP01 | O28: bang.nguyen-duy | P28: 194 | Q28: 3.44 | R28: 3 | S28: Complete & Closed | T28: 43938
B29: 285 | C29: GWM_B30_HP | D29: GWM_B30_HP | E29: bang.nguyen-duy | F29: 144 | G29: 2.56 | H29: 0.5 | I29: Complete & Closed | J29: 43951 | L29: 193 | M29: EC_245950_NIO_ESX_ESPHevX_DTC_BSS01_SP01 | N29: EC_245950_NIO_ESX_ESPHevX_DTC_BSS01_SP01 | O29: bang.nguyen-duy | P29: 321 | Q29: 5.7 | R29: 6 | S29: Complete & Closed | T29: 43938
B30: 286 | C30: GWM_B30_HP | D30: GWM_B30_HP | E30: bang.nguyen-duy | F30: 59 | G30: 1.04 | H30: 0.5 | I30: Complete & Closed | J30: 43951 | L30: 194 | M30: EC_245950_NIO_ESX_ESPHevX_DTC_BSS01_SP01 | N30: EC_245950_NIO_ESX_ESPHevX_DTC_BSS01_SP01 | O30: bang.nguyen-duy | P30: 52 | Q30: 0.92 | R30: 1 | S30: Complete & Closed | T30: 43938
B31: 287 | C31: GWM_B30_HP | D31: GWM_B30_HP | E31: bang.nguyen-duy | F31: 354 | G31: 6.29 | H31: 2 | I31: Complete & Closed | J31: 43951 | L31: 195 | M31: EC_245950_NIO_ESX_ESPHevX_DTC_BSS01_SP01 | N31: EC_245950_NIO_ESX_ESPHevX_DTC_BSS01_SP01 | O31: bang.nguyen-duy | P31: 209 | Q31: 3.71 | R31: 3 | S31: Complete & Closed | T31: 43938
B32: 288 | C32: GWM_B30_HP | D32: GWM_B30_HP | E32: bang.nguyen-duy | F32: 186 | G32: 3.3 | H32: 0.5 | I32: Complete & Closed | J32: 43951 | L32: 196 | M32: EC_245950_NIO_ESX_ESPHevX_DTC_BSS01_SP01 | N32: EC_245950_NIO_ESX_ESPHevX_DTC_BSS01_SP01 | O32: bang.nguyen-duy | P32: 67 | Q32: 1.19 | R32: 2 | S32: Complete & Closed | T32: 43938
B33: 289 | C33: GWM_B30_HP | D33: GWM_B30_HP | E33: bang.nguyen-duy | F33: 159 | G33: 2.82 | H33: 0.5 | I33: Complete & Closed | J33: 43951 | L33: 197 | M33: EC_245950_NIO_ESX_ESPHevX_DTC_BSS01_SP01 | N33: EC_245950_NIO_ESX_ESPHevX_DTC_BSS01_SP01 | O33: bang.nguyen-duy | P33: 202 | Q33: 3.59 | R33: 3 | S33: Complete & Closed | T33: 43938
B34: 290 | C34: GWM_B30_HP | D34: GWM_B30_HP | E34: bang.nguyen-duy | F34: 199 | G34: 3.53 | H34: 0.5 | I34: Complete & Closed | J34: 43951 | L34: 257 | M34: Adapt_236246_SMART_BBM_Ibooster_E2_SP3 | N34: Adapt_236246_SMART_BBM_Ibooster_E2_SP3 | O34: bang.nguyen-duy | P34: 1434 | Q34: 25.49 | R34: 3 | S34: Complete & Closed | T34: 43945
B35: 291 | C35: GWM_B30_HP | D35: GWM_B30_HP | E35: bang.nguyen-duy | F35: 6 | G35: 0.1 | H35: 0.5 | I35: Complete & Closed | J35: 43951 | L35: 280 | M35: GWM_B30_HP | N35: GWM_B30_HP | O35: bang.nguyen-duy | P35: 84 | Q35: 1.49 | R35: 0.5 | S35: Complete & Closed | T35: 43951
... B208: 105 | C208: 206370_BYD_ESP9.3_New_Hybrid_MS15.1_BSS18 | D208: 206370_BYD_ESP9.3_New_Hybrid_MS15.1_BSS18 | E208: hau.nguyen-tai | F208: 1193 | G208: 21.2 | H208: 4 | I208: Complete & Closed | J208: 43963 | L208: 5 | M208: GEELY_FE-3AH_CB_CSIS241976_BSS03 | N208: GEELY_FE-3AH_CB_CSIS241976_BSS03 | O208: hau.nguyen-tai | P208: 178 | Q208: 3.16 | R208: 1 | S208: Ready for PLC | T208: 43956
B209: 140 | C209: BJEV_N60_2WD_4WD | D209: BJEV_N60_2WD_4WD | E209: hau.nguyen-tai | F209: 146 | G209: 2.59 | I209: Ready for review | J209: 43966 | L209: 6 | M209: GEELY_FE-3AH_CB_CSIS241976_BSS03 | N209: GEELY_FE-3AH_CB_CSIS241976_BSS03 | O209: hau.nguyen-tai | P209: 124 | Q209: 2.2 | R209: 2 | S209: Ready for PLC | T209: 43956
B210: 141 | C210: BJEV_N60_2WD_4WD | D210: BJEV_N60_2WD_4WD | E210: hau.nguyen-tai | F210: 96 | G210: 1.7 | I210: Ready for review | J210: 43966 | L210: 7 | M210: GEELY_FE-3AH_CB_CSIS241976_BSS03 | N210: GEELY_FE-3AH_CB_CSIS241976_BSS03 | O210: hau.nguyen-tai | P210: 106 | Q210: 1.88 | R210: 2 | S210: Complete & Closed | T210: 43956
B211: 143 | C211: CNMS_226528_IB2_RPA | D211: CNMS_226528_IB2_RPA | E211: hau.nguyen-tai | F211: 20 | G211: 1.23 | H211: 1.23 | I211: Ready for PLC | J211: 43963 | L211: 8 | M211: 206370_BYD_ESP9.3_New_Hybrid_MS15.1_BSS18 | N211: 206370_BYD_ESP9.3_New_Hybrid_MS15.1_BSS18 | O211: hau.nguyen-tai | P211: 188 | Q211: 3.34 | R211: 1 | S211: Ready for PLC | T211: 43956
B212: 157 | C212: GWM_B30_CP | D212: GWM_B30_CP | E212: hau.nguyen-tai | F212: 189 | G212: 3.36 | H212: 2 | I212: Complete & Closed | J212: 43938 | L212: 9 | M212: 206370_BYD_ESP9.3_New_Hybrid_MS15.1_BSS18 | N212: 206370_BYD_ESP9.3_New_Hybrid_MS15.1_BSS18 | O212: hau.nguyen-tai | P212: 257 | Q212: 4.56 | R212: 2 | S212: Ready for PLC | T212: 43956
...

Sheet List
A1: 206370_BYD_ESP9.3_New_Hybrid_MS15.1_BSS18
A2: MC_239507_SGMW_CN210S_PHEV_ESP9.3CPi_BSS03_SP1
A3: BAIC_C62X_RC_APA_BL01
A4: DFN_ESP_Gen9.3_534_238307_BS03SP03
A5: RC_242264_SOKON_S513EVR_ESP9.3
A6: MC_237270_GAC_A55CP_Carbon_ESP_BL02
A7: BJEV_N60_2WD_4WD
A8: HHT_VX1_IBooster_Gen2_BL2
A9: EC_245950_NIO_ESX_ESPHevX_DTC_BSS01_SP01
A10: Adapt_236246_SMART_BBM_Ibooster_E2_SP3
A11: GWM_B30_HP
A12: BYD_IPB_SW_Mainstream_BL05_Defect
... A78: 238493_GAC_A36_CarbonESP9.3CP_BL04

Sheet Output
B2: 206370_BYD_ESP9.3_New_Hybrid_MS15.1_BSS18 | C2: hieu.nguyen-trung | D2: =SUMIFS(Sheet1!$G$2:$G$523,Sheet1!$D$2:$D$523,B2,Sheet1!$E$2:$E$523,C2) -> 0 | F2: 1
B3: MC_239507_SGMW_CN210S_PHEV_ESP9.3CPi_BSS03_SP1 | C3: hieu.nguyen-trung | D3: =SUMIFS(Sheet1!$G$2:$G$523,Sheet1!$D$2:$D$523,B3,Sheet1!$E$2:$E$523,C3) -> 0
B4: BAIC_C62X_RC_APA_BL01 | C4: hieu.nguyen-trung | D4: =SUMIFS(Sheet1!$G$2:$G$523,Sheet1!$D$2:$D$523,B4,Sheet1!$E$2:$E$523,C4) -> 19.75
B5: DFN_ESP_Gen9.3_534_238307_BS03SP03 | C5: hieu.nguyen-trung | D5: =SUMIFS(Sheet1!$G$2:$G$523,Sheet1!$D$2:$D$523,B5,Sheet1!$E$2:$E$523,C5) -> 30.27
B6: RC_242264_SOKON_S513EVR_ESP9.3 | C6: hieu.nguyen-trung | D6: =SUMIFS(Sheet1!$G$2:$G$523,Sheet1!$D$2:$D$523,B6,Sheet1!$E$2:$E$523,C6) -> 0
B7: MC_237270_GAC_A55CP_Carbon_ESP_BL02 | C7: hieu.nguyen-trung | D7: =SUMIFS(Sheet1!$G$2:$G$523,Sheet1!$D$2:$D$523,B7,Sheet1!$E$2:$E$523,C7) -> 0
B8: BJEV_N60_2WD_4WD | C8: hieu.nguyen-trung | D8: =SUMIFS(Sheet1!$G$2:$G$523,Sheet1!$D$2:$D$523,B8,Sheet1!$E$2:$E$523,C8) -> 0
B9: HHT_VX1_IBooster_Gen2_BL2 | C9: hieu.nguyen-trung | D9: =SUMIFS(Sheet1!$G$2:$G$523,Sheet1!$D$2:$D$523,B9,Sheet1!$E$2:$E$523,C9) -> 0
B10: EC_245950_NIO_ESX_ESPHevX_DTC_BSS01_SP01 | C10: hieu.nguyen-trung | D10: =SUMIFS(Sheet1!$G$2:$G$523,Sheet1!$D$2:$D$523,B10,Sheet1!$E$2:$E$523,C10) -> 6.09
B11: Adapt_236246_SMART_BBM_Ibooster_E2_SP3 | C11: hieu.nguyen-trung | D11: =SUMIFS(Sheet1!$G$2:$G$523,Sheet1!$D$2:$D$523,B11,Sheet1!$E$2:$E$523,C11) -> 0.81
B12: GWM_B30_HP | C12: hieu.nguyen-trung | D12: =SUMIFS(Sheet1!$G$2:$G$523,Sheet1!$D$2:$D$523,B12,Sheet1!$E$2:$E$523,C12) -> 0
B13: BYD_IPB_SW_Mainstream_BL05_Defect | C13: hieu.nguyen-trung | D13: =SUMIFS(Sheet1!$G$2:$G$523,Sheet1!$D$2:$D$523,B13,Sheet1!$E$2:$E$523,C13) -> 0
B14: 231839_DearCC_IC321_ESP9.3_BSS02_CAN_MATRIX_VARTABLE | C14: hieu.nguyen-trung | D14: =SUMIFS(Sheet1!$G$2:$G$523,Sheet1!$D$2:$D$523,B14,Sheet1!$E$2:$E$523,C14) -> 0
... B79: 238493_GAC_A36_CarbonESP9.3CP_BL04 | C79: hieu.nguyen-trung | D79: =SUMIFS(Sheet1!$G$2:$G$523,Sheet1!$D$2:$D$523,B79,Sheet1!$E$2:$E$523,C79) -> 0
B80: 206370_BYD_ESP9.3_New_Hybrid_MS15.1_BSS18 | C80: hau.nguyen-tai | D80: =SUMIFS(Sheet1!$G$2:$G$523,Sheet1!$D$2:$D$523,B80,Sheet1!$E$2:$E$523,C80) -> 49.38 | F80: 2
B81: MC_239507_SGMW_CN210S_PHEV_ESP9.3CPi_BSS03_SP1 | C81: hau.nguyen-tai | D81: =SUMIFS(Sheet1!$G$2:$G$523,Sheet1!$D$2:$D$523,B81,Sheet1!$E$2:$E$523,C81) -> 0
B82: BAIC_C62X_RC_APA_BL01 | C82: hau.nguyen-tai | D82: =SUMIFS(Sheet1!$G$2:$G$523,Sheet1!$D$2:$D$523,B82,Sheet1!$E$2:$E$523,C82) -> 0
B83: DFN_ESP_Gen9.3_534_238307_BS03SP03 | C83: hau.nguyen-tai | D83: =SUMIFS(Sheet1!$G$2:$G$523,Sheet1!$D$2:$D$523,B83,Sheet1!$E$2:$E$523,C83) -> 0
B84: RC_242264_SOKON_S513EVR_ESP9.3 | C84: hau.nguyen-tai | D84: =SUMIFS(Sheet1!$G$2:$G$523,Sheet1!$D$2:$D$523,B84,Sheet1!$E$2:$E$523,C84) -> 0
B85: MC_237270_GAC_A55CP_Carbon_ESP_BL02 | C85: hau.nguyen-tai | D85: =SUMIFS(Sheet1!$G$2:$G$523,Sheet1!$D$2:$D$523,B85,Sheet1!$E$2:$E$523,C85) -> 0
B86: BJEV_N60_2WD_4WD | C86: hau.nguyen-tai | D86: =SUMIFS(Sheet1!$G$2:$G$523,Sheet1!$D$2:$D$523,B86,Sheet1!$E$2:$E$523,C86) -> 4.29
B87: HHT_VX1_IBooster_Gen2_BL2 | C87: hau.nguyen-tai | D87: =SUMIFS(Sheet1!$G$2:$G$523,Sheet1!$D$2:$D$523,B87,Sheet1!$E$2:$E$523,C87) -> 0
B88: EC_245950_NIO_ESX_ESPHevX_DTC_BSS01_SP01 | C88: hau.nguyen-tai | D88: =SUMIFS(Sheet1!$G$2:$G$523,Sheet1!$D$2:$D$523,B88,Sheet1!$E$2:$E$523,C88) -> 4.86
B89: Adapt_236246_SMART_BBM_Ibooster_E2_SP3 | C89: hau.nguyen-tai | D89: =SUMIFS(Sheet1!$G$2:$G$523,Sheet1!$D$2:$D$523,B89,Sheet1!$E$2:$E$523,C89) -> 0
B90: GWM_B30_HP | C90: hau.nguyen-tai | D90: =SUMIFS(Sheet1!$G$2:$G$523,Sheet1!$D$2:$D$523,B90,Sheet1!$E$2:$E$523,C90) -> 0
B91: BYD_IPB_SW_Mainstream_BL05_Defect | C91: hau.nguyen-tai | D91: =SUMIFS(Sheet1!$G$2:$G$523,Sheet1!$D$2:$D$523,B91,Sheet1!$E$2:$E$523,C91) -> 0
B92: 231839_DearCC_IC321_ESP9.3_BSS02_CAN_MATRIX_VARTABLE | C92: hau.nguyen-tai | D92: =SUMIFS(Sheet1!$G$2:$G$523,Sheet1!$D$2:$D$523,B92,Sheet1!$E$2:$E$523,C92) -> 0
... B157: 238493_GAC_A36_CarbonESP9.3CP_BL04 | C157: hau.nguyen-tai | D157: =SUMIFS(Sheet1!$G$2:$G$523,Sheet1!$D$2:$D$523,B157,Sheet1!$E$2:$E$523,C157) -> 0
B158: 206370_BYD_ESP9.3_New_Hybrid_MS15.1_BSS18 | C158: bang.nguyen-duy | D158: =SUMIFS(Sheet1!$G$2:$G$523,Sheet1!$D$2:$D$523,B158,Sheet1!$E$2:$E$523,C158) -> 17.72 | F158: 3
B159: MC_239507_SGMW_CN210S_PHEV_ESP9.3CPi_BSS03_SP1 | C159: bang.nguyen-duy | D159: =SUMIFS(Sheet1!$G$2:$G$523,Sheet1!$D$2:$D$523,B159,Sheet1!$E$2:$E$523,C159) -> 10.93
B160: BAIC_C62X_RC_APA_BL01 | C160: bang.nguyen-duy | D160: =SUMIFS(Sheet1!$G$2:$G$523,Sheet1!$D$2:$D$523,B160,Sheet1!$E$2:$E$523,C160) -> 5.45
B161: DFN_ESP_Gen9.3_534_238307_BS03SP03 | C161: bang.nguyen-duy | D161: =SUMIFS(Sheet1!$G$2:$G$523,Sheet1!$D$2:$D$523,B161,Sheet1!$E$2:$E$523,C161) -> 9.75
B162: RC_242264_SOKON_S513EVR_ESP9.3 | C162: bang.nguyen-duy | D162: =SUMIFS(Sheet1!$G$2:$G$523,Sheet1!$D$2:$D$523,B162,Sheet1!$E$2:$E$523,C162) -> 1.9
B163: MC_237270_GAC_A55CP_Carbon_ESP_BL02 | C163: bang.nguyen-duy | D163: =SUMIFS(Sheet1!$G$2:$G$523,Sheet1!$D$2:$D$523,B163,Sheet1!$E$2:$E$523,C163) -> 4.19
B164: BJEV_N60_2WD_4WD | C164: bang.nguyen-duy | D164: =SUMIFS(Sheet1!$G$2:$G$523,Sheet1!$D$2:$D$523,B164,Sheet1!$E$2:$E$523,C164) -> 0
B165: HHT_VX1_IBooster_Gen2_BL2 | C165: bang.nguyen-duy | D165: =SUMIFS(Sheet1!$G$2:$G$523,Sheet1!$D$2:$D$523,B165,Sheet1!$E$2:$E$523,C165) -> 20.1
B166: EC_245950_NIO_ESX_ESPHevX_DTC_BSS01_SP01 | C166: bang.nguyen-duy | D166: =SUMIFS(Sheet1!$G$2:$G$523,Sheet1!$D$2:$D$523,B166,Sheet1!$E$2:$E$523,C166) -> 18.55
B167: Adapt_236246_SMART_BBM_Ibooster_E2_SP3 | C167: bang.nguyen-duy | D167: =SUMIFS(Sheet1!$G$2:$G$523,Sheet1!$D$2:$D$523,B167,Sheet1!$E$2:$E$523,C167) -> 25.49
B168: GWM_B30_HP | C168: bang.nguyen-duy | D168: =SUMIFS(Sheet1!$G$2:$G$523,Sheet1!$D$2:$D$523,B168,Sheet1!$E$2:$E$523,C168) -> 33.89
B169: BYD_IPB_SW_Mainstream_BL05_Defect | C169: bang.nguyen-duy | D169: =SUMIFS(Sheet1!$G$2:$G$523,Sheet1!$D$2:$D$523,B169,Sheet1!$E$2:$E$523,C169) -> 14.27
...

Sheet Sheet5
H2: Resource Name | I2: Team | J2: Domain | K2: Region | L2: BM Number | M2: Project Name | N2: SW PCM | O2: Efforts (Hours) | P2: note
A3: BAIC_C62X_RC_APA_BL01 | B3: BAIC_C62X_RC_APA | C3: Nguyen Trung Hieu | D3: 19.75 | F3: =VLOOKUP(B3,$M$3:$M$132,1,0) -> BAIC_C62X_RC_APA | H3: Do Anh Huy | I3: External | J3: COEM-ESP-UT | K3: M | L3: BM-00053759_004 | M3: BYD_Carbon_Mainstream | O3: 27.75
A4: DFN_ESP_Gen9.3_534_238307_BS03SP03 | B4: DFN_ESP_Gen9.3_534_238307 | C4: Nguyen Trung Hieu | D4: 30.27 | F4: =VLOOKUP(B4,$M$3:$M$132,1,0) -> DFN_ESP_Gen9.3_534_238307 | H4: Do Anh Huy | I4: External | J4: COEM-ESP-UT | K4: E | L4: BM-00051278_004 | M4: Adapt_236234_SMART_VDDM_ESPHevX | O4: 0.25
A5: EC_245950_NIO_ESX_ESPHevX_DTC_BSS01_SP01 | B5: EC_245950_NIO_ESX_ESPHevX_DTC | C5: Nguyen Trung Hieu | D5: 6.09 | F5: =VLOOKUP(B5,$M$3:$M$132,1,0) -> EC_245950_NIO_ESX_ESPHevX_DTC | H5: Do Anh Huy | I5: External | J5: COEM-iBooster-UT | K5: E | L5: BM-00051691-005 | M5: Adapt_236246_SMART_BBM_Ibooster_E2_SP3 | O5: 1
A6: Adapt_236246_SMART_BBM_Ibooster_E2_SP3 | B6: Adapt_236246_SMART_BBM_Ibooster_E2_SP3 | C6: Nguyen Trung Hieu | D6: 0.81 | F6: =VLOOKUP(B6,$M$3:$M$132,1,0) -> Adapt_236246_SMART_BBM_Ibooster_E2_SP3 | H6: Do Anh Huy | I6: External | J6: COEM-ESP-UT | K6: M | L6: BM-00040400_003 | M6: BYD_IPB_SW_Mainstream | O6: 2
A7: GAC_Carbon_RPA_ESPHevx_Mainpath_BL04 | B7: GAC_Carbon_RPA_ESPHevx_Mainpath | C7: Nguyen Trung Hieu | D7: 17.93 | F7: =VLOOKUP(B7,$M$3:$M$132,1,0) -> GAC_Carbon_RPA_ESPHevx_Mainpath | H7: Do Anh Huy | I7: External | J7: COEM-ESP-UT | K7: M | L7: BM-00027762_003 | M7: 206370_BYD_ESP9.3_New_Hybrid_MS15.1 | O7: 0.5
A8: GWM_B30_CP | B8: GWM_B30_CP | C8: Nguyen Trung Hieu | D8: 16.61 | F8: =VLOOKUP(B8,$M$3:$M$132,1,0) -> GWM_B30_CP | H8: Do Anh Huy | I8: External | J8: COEM-iBooster-UT | K8: N | L8: B30_9DCT_IB2: MCR BM-00022611_004, BB80722 A30_DHT_IB2: MCR BM-00049368_003, BB81556 | M8: AB30IB2 | O8: 15
A9: GWM_AB30_CP | B9: GWM_AB30_CP | C9: Nguyen Trung Hieu | D9: 18.21 | F9: =VLOOKUP(B9,$M$3:$M$132,1,0) -> GWM_AB30_CP | H9: Do Anh Huy | I9: External | J9: COEM-ESP-UT | K9: M | L9: BM-00024808_007 | M9: HAIMA_238525_VF00_ESP_RC2 | O9: 13.75
A10: BYD_IPB_SW_Mainstream_BL05_SP10 | B10: BYD_IPB_SW_Mainstream | C10: Nguyen Trung Hieu | D10: 16.33 | F10: =VLOOKUP(B10,$M$3:$M$132,1,0) -> BYD_IPB_SW_Mainstream | H10: Do Anh Huy | I10: External | J10: COEM-ESP-UT | K10: M | L10: BM-00044592_003 | M10: GAC_Carbon_Stream_ESPCP | O10: 5
A11: MC_225750_Geely_KC2A_ESP9.3HB_BB80336_BL04SP03 | B11: MC_225750_Geely_KC2A_ESP9.3HB_BB80336 | C11: Nguyen Trung Hieu | D11: 30.27 | F11: =VLOOKUP(B11,$M$3:$M$132,1,0) -> MC_225750_Geely_KC2A_ESP9.3HB_BB80336 | H11: Do Phu Loc | I11: External | J11: BEG-UT | L11: RG-000949-00-01-12 | M11: HHT_VX1_ESPHevX | O11: 2
A12: 206370_BYD_ESP9.3_New_Hybrid_MS15.1_BSS18 | B12: 206370_BYD_ESP9.3_New_Hybrid_MS15.1 | C12: Nguyen Tai Hau | D12: 49.38 | F12: =VLOOKUP(B12,$M$3:$M$132,1,0) -> 206370_BYD_ESP9.3_New_Hybrid_MS15.1 | H12: Do Phu Loc | I12: External | J12: COEM-ESP-UT | K12: M | L12: BM-00053759_004 | M12: BYD_Carbon_Mainstream | O12: 14
A13: BJEV_N60_2WD_4WD | B13: BJEV_N60_2WD_4WD | C13: Nguyen Tai Hau | D13: 4.29 | F13: =VLOOKUP(B13,$M$3:$M$132,1,0) -> #N/A | H13: Do Phu Loc | I13: External | J13: COEM-iBooster-UT | K13: N | L13: B30_9DCT_IB2: MCR BM-00022611_004, BB80722 A30_DHT_IB2: MCR BM-00049368_003, BB81556 | M13: AB30IB2 | O13: 1
A14: EC_245950_NIO_ESX_ESPHevX_DTC_BSS01_SP01 | B14: EC_245950_NIO_ESX_ESPHevX_DTC | C14: Nguyen Tai Hau | D14: 4.86 | F14: =VLOOKUP(B14,$M$3:$M$132,1,0) -> EC_245950_NIO_ESX_ESPHevX_DTC | H14: Do Phu Loc | I14: External | J14: COEM-ESP-UT | K14: N | L14: BM-00031018_003 | M14: 216916_FAW_E115_L3_ESPhev_APB(CBi) | O14: 4
A15: GWM_B30_CP | B15: GWM_B30_CP | C15: Nguyen Tai Hau | D15: 21.07 | F15: =VLOOKUP(B15,$M$3:$M$132,1,0) -> GWM_B30_CP | H15: Do Phu Loc | I15: External | J15: COEM-ESP-UT | K15: M | L15: BM-00040400_003 | M15: BYD_IPB_SW_Mainstream | O15: 12
A16: GEELY_FE-3AH_CB_CSIS241976_BSS03 | B16: GEELY_FE-3AH_CB_CSIS241976 | C16: Nguyen Tai Hau | D16: 7.24 | F16: =VLOOKUP(B16,$M$3:$M$132,1,0) -> GEELY_FE-3AH_CB_CSIS241976 | H16: Do Phu Loc | I16: External | J16: COEM-ESP-UT | K16: N | L16: BM-00011763_003 | M16: GWM_B30_HP | O16: 2
A17: SAIC ZS12MCE withDA ESP9.3 BSS03SP01 | B17: SAIC ZS12MCE withDA ESP9.3 | C17: Nguyen Tai Hau | D17: 2.96 | F17: =VLOOKUP(B17,$M$3:$M$132,1,0) -> SAIC ZS12MCE withDA ESP9.3 | H17: Do Phu Loc | I17: External | J17: COEM-ESP-UT | K17: M | L17: BM-00044592_003 | M17: GAC_Carbon_Stream_ESPCP | O17: 20
A18: MC_239446_Geely_FE6AB_ESP9.3HD_BB81527_BL04 | B18: MC_239446_Geely_FE6AB_ESP9.3HD_BB81527 | C18: Nguyen Tai Hau | D18: 1.52 | F18: =VLOOKUP(B18,$M$3:$M$132,1,0) -> MC_239446_Geely_FE6AB_ESP9.3HD_BB81527 | H18: Do Phu Loc | I18: External | J18: COEM-ESP-UT | K18: E | L18: BM-00041598_006 | M18: MC_225750_Geely_KC2A_ESP9.3HB_BB80336 | O18: 6
A19: 217437_FAW_C229_BL43 | B19: 217437_FAW_C229 | C19: Nguyen Tai Hau | D19: 11.51 | F19: =VLOOKUP(B19,$M$3:$M$132,1,0) -> 217437_FAW_C229 | H19: Do Phu Loc | I19: External | J19: COEM-ESP-UT | K19: N | L19: BM-00031018_003 | M19: FAW_E115_ESPhev | O19: 3
A20: CNMS_226528_IB2_RPA | B20: CNMS_226528_IB2_RPA | C20: Nguyen Tai Hau | D20: 1.23 | F20: =VLOOKUP(B20,$M$3:$M$132,1,0) -> CNMS_226528_IB2_RPA | H20: Do Phu Loc | I20: External | J20: COEM-ESP-UT | K20: M | L20: BM-00052994_003 | M20: 242899_GAC_A39_ESP9.3CPHD_RC4 | O20: 3.5
A21: GWM_AB30_CP | B21: GWM_AB30_CP | C21: Nguyen Tai Hau | D21: 15.59 | F21: =VLOOKUP(B21,$M$3:$M$132,1,0) -> GWM_AB30_CP | H21: Do Phu Loc | I21: External | J21: COEM-ESP-UT | K21: N | L21: BM-00044444_004 | M21: FAW_E111_ESPhev | O21: 8.5
A22: GAC_Common_Task_Record_Sprint07 | B22: GAC_Common_Task_Record_Sprint07 | C22: Nguyen Tai Hau | D22: 4.17 | F22: =VLOOKUP(B22,$M$3:$M$132,1,0) -> GAC_Common_Task_Record_Sprint07 | H22: Do Phu Loc | I22: External | J22: COEM-ESP-UT | K22: N | L22: BM-00011083_007 | M22: 235149_FAW_HS7_RC | O22: 4.5
A23: SAIC_ZS11E_MCE_withDA_ESP9.3_241859_BSS01 | B23: SAIC_ZS11E_MCE_withDA_ESP9.3_241859 | C23: Nguyen Tai Hau | D23: 7.37 | F23: =VLOOKUP(B23,$M$3:$M$132,1,0) -> SAIC_ZS11E_MCE_withDA_ESP9.3_241859 | H23: Do Phu Loc | I23: External | J23: COEM-ESP-UT | K23: N | L23: BM-00011763_003 | M23: GWM_B30HP ESP | O23: 4
A24: HAIMA_238525_VF00_ESP_RC2_BSS01.1_BSS02_Workitems_closure | B24: HAIMA_238525_VF00_ESP_RC2 | C24: Nguyen Tai Hau | D24: 0.53 | F24: =VLOOKUP(B24,$M$3:$M$132,1,0) -> HAIMA_238525_VF00_ESP_RC2 | H24: Do Phu Loc | I24: External | J24: 2WP-UT | L24: BM-00034660_005 | M24: Suzuki_XE431RC ABS10.3ME | O24: 24
A25: MC_223517_Geely_KC2A_ESP9.3CP_BB80335_BL04SP03 | B25: MC_223517_Geely_KC2A_ESP9.3CP_BB80335 | C25: Nguyen Tai Hau | D25: 44 | F25: =VLOOKUP(B25,$M$3:$M$132,1,0) -> MC_223517_Geely_KC2A_ESP9.3CP_BB80335 | H25: Do Phu Loc | I25: External | J25: COEM-iBooster-UT | K25: N | L25: B30_9DCT_IB2: MCR BM-00022611_004, BB80722 A30_DHT_IB2: MCR BM-00049368_003, BB81556 | M25: AB30IB2 | O25: 1
A26: 206370_BYD_ESP9.3_New_Hybrid_MS15.1_BSS18 | B26: 206370_BYD_ESP9.3_New_Hybrid_MS15.1 | C26: Nguyen Duy Bang | D26: 17.72 | F26: =VLOOKUP(B26,$M$3:$M$132,1,0) -> 206370_BYD_ESP9.3_New_Hybrid_MS15.1 | H26: Do Phu Loc | I26: External | J26: COEM-CNMS-UT | M26: CNMS_226528_IB2_RPA | O26: 4
A27: MC_239507_SGMW_CN210S_PHEV_ESP9.3CPi_BSS03_SP1 | B27: MC_239507_SGMW_CN210S_PHEV_ESP9.3CPi | C27: Nguyen Duy Bang | D27: 10.93 | F27: =VLOOKUP(B27,$M$3:$M$132,1,0) -> MC_239507_SGMW_CN210S_PHEV_ESP9.3CPi | H27: Do Phu Loc | I27: External | J27: COEM-CNMS-UT | M27: CNMS_226315_HevX_RPA | O27: 4
A28: BAIC_C62X_RC_APA_BL01 | B28: BAIC_C62X_RC_APA | C28: Nguyen Duy Bang | D28: 5.45 | F28: =VLOOKUP(B28,$M$3:$M$132,1,0) -> BAIC_C62X_RC_APA | H28: Do Phu Loc | I28: External | J28: 2WP-UT | L28: BM-00034660_005 | M28: XE431RC ABS10.3ME | O28: 22
A29: DFN_ESP_Gen9.3_534_238307_BS03SP03 | B29: DFN_ESP_Gen9.3_534_238307 | C29: Nguyen Duy Bang | D29: 9.75 | F29: =VLOOKUP(B29,$M$3:$M$132,1,0) -> DFN_ESP_Gen9.3_534_238307 | H29: Luu Cong Dac | I29: External | J29: COEM-ESP-UT | K29: N | L29: BM-00045327_003 | M29: GWM_B30_CP | O29: 2.1
A30: RC_242264_SOKON_S513EVR_ESP9.3 | B30: RC_242264_SOKON_S513EVR_ESP9.3 | C30: Nguyen Duy Bang | D30: 1.9 | F30: =VLOOKUP(B30,$M$3:$M$132,1,0) -> RC_242264_SOKON_S513EVR_ESP9.3 | H30: Luu Cong Dac | I30: External | J30: BEG-UT | L30: RG-000949-00-01-12 | M30: HHT_VX1_ESPHevX | O30: 3.7
A31: MC_237270_GAC_A55CP_Carbon_ESP_BL02 | B31: MC_237270_GAC_A55CP_Carbon_ESP | C31: Nguyen Duy Bang | D31: 4.19 | F31: =VLOOKUP(B31,$M$3:$M$132,1,0) -> MC_237270_GAC_A55CP_Carbon_ESP | H31: Luu Cong Dac | I31: External | J31: BEG-UT | L31: RG-000952-00-08-20-08 | M31: HHT_VX1_IBooster_Gen2 | O31: 2.1
A32: HHT_VX1_IBooster_Gen2_BL2 | B32: HHT_VX1_IBooster_Gen2 | C32: Nguyen Duy Bang | D32: 20.1 | F32: =VLOOKUP(B32,$M$3:$M$132,1,0) -> HHT_VX1_IBooster_Gen2 | H32: Luu Cong Dac | I32: External | J32: COEM-ESP-UT | K32: W | L32: BM-00045267_004 | M32: EC_245950_NIO_ESX_ESPHevX_DTC | O32: 8.1
A33: EC_245950_NIO_ESX_ESPHevX_DTC_BSS01_SP01 | B33: EC_245950_NIO_ESX_ESPHevX_DTC | C33: Nguyen Duy Bang | D33: 18.55 | F33: =VLOOKUP(B33,$M$3:$M$132,1,0) -> EC_245950_NIO_ESX_ESPHevX_DTC | H33: Luu Cong Dac | I33: External | J33: COEM-ESP-UT | K33: M | L33: BM-00053759_004 | M33: BYD_Carbon_Mainstream | O33: 1
A34: Adapt_236246_SMART_BBM_Ibooster_E2_SP3 | B34: Adapt_236246_SMART_BBM_Ibooster_E2_SP3 | C34: Nguyen Duy Bang | D34: 25.49 | F34: =VLOOKUP(B34,$M$3:$M$132,1,0) -> Adapt_236246_SMART_BBM_Ibooster_E2_SP3 | H34: Luu Cong Dac | I34: External | J34: COEM-ESP-UT | K34: W | L34: BM-00033117_003 | M34: 218053_CA_CD569_ESP9.3CP | O34: 1
A35: GWM_B30_HP | B35: GWM_B30_HP | C35: Nguyen Duy Bang | D35: 33.89 | F35: =VLOOKUP(B35,$M$3:$M$132,1,0) -> GWM_B30_HP | H35: Luu Cong Dac | I35: External | J35: COEM-iBooster-UT | K35: N | L35: BM-00041400_003 | M35: BAIC_C62XP_IB2 | O35: 4.1
A36: BYD_IPB_SW_Mainstream_BL05_Defect | B36: BYD_IPB_SW_Mainstream | C36: Nguyen Duy Bang | D36: 14.27 | F36: =VLOOKUP(B36,$M$3:$M$132,1,0) -> BYD_IPB_SW_Mainstream | H36: Luu Cong Dac | I36: External | J36: COEM-ESP-UT | K36: M | L36: BM-00040400_003 | M36: BYD_IPB_SW_Mainstream | O36: 9.5
A37: 231839_DearCC_IC321_ESP9.3_BSS02_CAN_MATRIX_VARTABLE | B37: 231839_DearCC_IC321_ESP9.3 | C37: Nguyen Duy Bang | D37: 3.2 | F37: =VLOOKUP(B37,$M$3:$M$132,1,0) -> 231839_DearCC_IC321_ESP9.3 | H37: Luu Cong Dac | I37: External | J37: COEM-ESP-UT | K37: M | L37: BM-00037542_002 | M37: GAC_220680_Carbon_A18_ESPHevx_FPA/RPA | O37: 2
A38: HHT_VX1_IBooster_Gen2_BL2 | B38: HHT_VX1_IBooster_Gen2 | C38: Luu Cong Dac | D38: 3.31 | F38: =VLOOKUP(B38,$M$3:$M$132,1,0) -> HHT_VX1_IBooster_Gen2 | H38: Luu Cong Dac | I38: External | J38: COEM-ESP-UT | K38: M | M38: KX63_FL_ACC_232961 | O38: 6.2
A39: EC_245950_NIO_ESX_ESPHevX_DTC_BSS01_SP01 | B39: EC_245950_NIO_ESX_ESPHevX_DTC | C39: Luu Cong Dac | D39: 10.62 | F39: =VLOOKUP(B39,$M$3:$M$132,1,0) -> EC_245950_NIO_ESX_ESPHevX_DTC | H39: Luu Cong Dac | I39: External | J39: COEM-ESP-UT | K39: M | L39: BM-00049327_004 BB81260 BM-00047518_004 BB81315 | M39: 233324_JAC_P843_ESP9.3 | O39: 5
A40: HHT_VX1_ESPHevX_BL2 | B40: HHT_VX1_ESPHevX | C40: Luu Cong Dac | D40: 5.6 | F40: =VLOOKUP(B40,$M$3:$M$132,1,0) -> HHT_VX1_ESPHevX | H40: Ly Chung | I40: External | J40: BEG-UT | L40: RG-000949-00-01-12 | M40: HHT_VX1_ESPHevX | O40: 3
A41: GWM_B30_CP | B41: GWM_B30_CP | C41: Luu Cong Dac | D41: 0.91 | F41: =VLOOKUP(B41,$M$3:$M$132,1,0) -> GWM_B30_CP | H41: Ly Chung | I41: External | J41: COEM-ESP-UT | K41: M | L41: BM-00053759_004 | M41: BYD_Carbon_Mainstream | O41: 10.6
...
